/*
*** MADE BY MITHION'S .SCHEMATIC TO JAVA CONVERTING TOOL v1.6 ***
*/

package com.sudwood.mysticadditions.worldgen;
import java.util.Random;

import net.minecraft.block.Block;
import net.minecraft.item.ItemStack;
import net.minecraft.tileentity.TileEntityChest;
import net.minecraft.tileentity.TileEntityMobSpawner;
import net.minecraft.world.World;
import net.minecraft.world.gen.feature.WorldGenerator;

import com.sudwood.mysticadditions.blocks.MysticModBlocks;
import com.sudwood.mysticadditions.items.MysticModItems;

public class WorldGenWarpedWaterShrine extends WorldGenerator
{
	protected int[] GetValidSpawnBlocks() {
		return new int[] {
			MysticModBlocks.inertGrass.blockID
		};
	}

	public boolean LocationIsValidSpawn(World world, int i, int j, int k){
		if(!world.isRemote)
		{
		int distanceToAir = 0;
		int checkID = world.getBlockId(i, j, k);

		while (checkID != 0){
			distanceToAir++;
			checkID = world.getBlockId(i, j + distanceToAir, k);
		}

		if (distanceToAir > 3){
			return false;
		}
		j += distanceToAir - 1;

		int blockID = world.getBlockId(i, j, k);
		int blockIDAbove = world.getBlockId(i, j+1, k);
		int blockIDBelow = world.getBlockId(i, j-1, k);
		for (int x : GetValidSpawnBlocks()){
			if (blockIDAbove != 0){
				return false;
			}
			if (blockID == x){
				return true;
			}else if (blockID == Block.snow.blockID && blockIDBelow == x){
				return true;
			}
		}
		}
		return false;
	}

	public WorldGenWarpedWaterShrine() { }

	public boolean generate(World world, Random rand, int i, int j, int k) {
		//check that each corner is one of the valid spawn blocks
		if(world.getBlockId(i, j, k)!=MysticModBlocks.inertGrass.blockID)
		{
			return false;
		}

		world.setBlock(i + 0, j + 0, k + 0, Block.stoneSingleSlab.blockID, 2,2);
		world.setBlock(i + 0, j + 0, k + 1, Block.stoneSingleSlab.blockID, 2,2);
		world.setBlock(i + 0, j + 0, k + 2, Block.stoneSingleSlab.blockID, 2,2);
		world.setBlock(i + 0, j + 0, k + 3, Block.stoneSingleSlab.blockID, 2,2);
		world.setBlock(i + 0, j + 0, k + 4, Block.stoneSingleSlab.blockID, 2,2);
		world.setBlock(i + 0, j + 0, k + 5, Block.stoneSingleSlab.blockID, 2,2);
		world.setBlock(i + 0, j + 0, k + 6, Block.stoneSingleSlab.blockID, 2,2);
		world.setBlock(i + 0, j + 0, k + 7, Block.stoneSingleSlab.blockID, 2,2);
		world.setBlock(i + 0, j + 0, k + 8, Block.stoneSingleSlab.blockID, 2,2);
		world.setBlock(i + 0, j + 0, k + 9, Block.stoneSingleSlab.blockID, 2,2);
		world.setBlock(i + 0, j + 0, k + 10, Block.stoneSingleSlab.blockID, 2,2);
		world.setBlock(i + 0, j + 0, k + 11, Block.stoneSingleSlab.blockID, 2,2);
		world.setBlock(i + 0, j + 0, k + 12, Block.stoneSingleSlab.blockID, 2,2);
		world.setBlock(i + 0, j + 0, k + 13, Block.stoneSingleSlab.blockID, 2,2);
		world.setBlock(i + 0, j + 0, k + 14, Block.stoneSingleSlab.blockID, 2,2);
		world.setBlock(i + 0, j + 0, k + 15, Block.stoneSingleSlab.blockID, 2,2);
		world.setBlock(i + 0, j + 0, k + 16, Block.stoneSingleSlab.blockID, 2,2);
		world.setBlock(i + 0, j + 0, k + 17, Block.stoneSingleSlab.blockID, 2,2);
		world.setBlock(i + 0, j + 18, k + 0, MysticModBlocks.mysticBricks.blockID);
		world.setBlock(i + 0, j + 18, k + 1, MysticModBlocks.mysticBricks.blockID);
		world.setBlock(i + 0, j + 18, k + 2, MysticModBlocks.mysticBricks.blockID);
		world.setBlock(i + 0, j + 18, k + 3, MysticModBlocks.mysticBricks.blockID);
		world.setBlock(i + 0, j + 18, k + 4, MysticModBlocks.mysticBricks.blockID);
		world.setBlock(i + 0, j + 18, k + 5, MysticModBlocks.mysticBricks.blockID);
		world.setBlock(i + 0, j + 18, k + 6, MysticModBlocks.mysticBricks.blockID);
		world.setBlock(i + 0, j + 18, k + 7, MysticModBlocks.mysticBricks.blockID);
		world.setBlock(i + 0, j + 18, k + 8, MysticModBlocks.mysticBricks.blockID);
		world.setBlock(i + 0, j + 18, k + 9, MysticModBlocks.mysticBricks.blockID);
		world.setBlock(i + 0, j + 18, k + 10, MysticModBlocks.mysticBricks.blockID);
		world.setBlock(i + 0, j + 18, k + 11, MysticModBlocks.mysticBricks.blockID);
		world.setBlock(i + 0, j + 18, k + 12, MysticModBlocks.mysticBricks.blockID);
		world.setBlock(i + 0, j + 18, k + 13, MysticModBlocks.mysticBricks.blockID);
		world.setBlock(i + 0, j + 18, k + 14, MysticModBlocks.mysticBricks.blockID);
		world.setBlock(i + 0, j + 18, k + 15, MysticModBlocks.mysticBricks.blockID);
		world.setBlock(i + 0, j + 18, k + 16, MysticModBlocks.mysticBricks.blockID);
		world.setBlock(i + 0, j + 18, k + 17, MysticModBlocks.mysticBricks.blockID);
		world.setBlock(i + 1, j + 0, k + 0, Block.stoneSingleSlab.blockID, 2,2);
		world.setBlock(i + 1, j + 0, k + 17, Block.stoneSingleSlab.blockID, 2,2);
		world.setBlock(i + 1, j + 18, k + 0, MysticModBlocks.mysticBricks.blockID);
		world.setBlock(i + 1, j + 18, k + 17, MysticModBlocks.mysticBricks.blockID);
		world.setBlock(i + 1, j + 19, k + 1, Block.stoneSingleSlab.blockID, 2,2);
		world.setBlock(i + 1, j + 19, k + 2, Block.stoneSingleSlab.blockID, 2,2);
		world.setBlock(i + 1, j + 19, k + 3, Block.stoneSingleSlab.blockID, 2,2);
		world.setBlock(i + 1, j + 19, k + 4, Block.stoneSingleSlab.blockID, 2,2);
		world.setBlock(i + 1, j + 19, k + 5, Block.stoneSingleSlab.blockID, 2,2);
		world.setBlock(i + 1, j + 19, k + 6, Block.stoneSingleSlab.blockID, 2,2);
		world.setBlock(i + 1, j + 19, k + 7, Block.stoneSingleSlab.blockID, 2,2);
		world.setBlock(i + 1, j + 19, k + 8, Block.stoneSingleSlab.blockID, 2,2);
		world.setBlock(i + 1, j + 19, k + 9, Block.stoneSingleSlab.blockID, 2,2);
		world.setBlock(i + 1, j + 19, k + 10, Block.stoneSingleSlab.blockID, 2,2);
		world.setBlock(i + 1, j + 19, k + 11, Block.stoneSingleSlab.blockID, 2,2);
		world.setBlock(i + 1, j + 19, k + 12, Block.stoneSingleSlab.blockID, 2,2);
		world.setBlock(i + 1, j + 19, k + 13, Block.stoneSingleSlab.blockID, 2,2);
		world.setBlock(i + 1, j + 19, k + 14, Block.stoneSingleSlab.blockID, 2,2);
		world.setBlock(i + 1, j + 19, k + 15, Block.stoneSingleSlab.blockID, 2,2);
		world.setBlock(i + 1, j + 19, k + 16, Block.stoneSingleSlab.blockID, 2,2);
		world.setBlock(i + 2, j + 0, k + 0, Block.stoneSingleSlab.blockID, 2,2);
		world.setBlock(i + 2, j + 0, k + 2, Block.stoneSingleSlab.blockID, 2,2);
		world.setBlock(i + 2, j + 0, k + 3, Block.stoneSingleSlab.blockID, 2,2);
		world.setBlock(i + 2, j + 0, k + 4, Block.stoneSingleSlab.blockID, 2,2);
		world.setBlock(i + 2, j + 0, k + 5, Block.stoneSingleSlab.blockID, 2,2);
		world.setBlock(i + 2, j + 0, k + 6, Block.stoneSingleSlab.blockID, 2,2);
		world.setBlock(i + 2, j + 0, k + 7, Block.stoneSingleSlab.blockID, 2,2);
		world.setBlock(i + 2, j + 0, k + 8, Block.stoneSingleSlab.blockID, 2,2);
		world.setBlock(i + 2, j + 0, k + 9, Block.stoneSingleSlab.blockID, 2,2);
		world.setBlock(i + 2, j + 0, k + 10, Block.stoneSingleSlab.blockID, 2,2);
		world.setBlock(i + 2, j + 0, k + 11, Block.stoneSingleSlab.blockID, 2,2);
		world.setBlock(i + 2, j + 0, k + 12, Block.stoneSingleSlab.blockID, 2,2);
		world.setBlock(i + 2, j + 0, k + 13, Block.stoneSingleSlab.blockID, 2,2);
		world.setBlock(i + 2, j + 0, k + 14, Block.stoneSingleSlab.blockID, 2,2);
		world.setBlock(i + 2, j + 0, k + 15, Block.stoneSingleSlab.blockID, 2,2);
		world.setBlock(i + 2, j + 0, k + 17, Block.stoneSingleSlab.blockID, 2,2);
		world.setBlock(i + 2, j + 1, k + 2, MysticModBlocks.Elevator.blockID);
		world.setBlock(i + 2, j + 1, k + 3, MysticModBlocks.Elevator.blockID);
		world.setBlock(i + 2, j + 1, k + 4, MysticModBlocks.Elevator.blockID);
		world.setBlock(i + 2, j + 1, k + 5, MysticModBlocks.Elevator.blockID);
		world.setBlock(i + 2, j + 1, k + 6, MysticModBlocks.Elevator.blockID);
		world.setBlock(i + 2, j + 1, k + 7, MysticModBlocks.Elevator.blockID);
		world.setBlock(i + 2, j + 1, k + 8, MysticModBlocks.Elevator.blockID);
		world.setBlock(i + 2, j + 1, k + 9, MysticModBlocks.Elevator.blockID);
		world.setBlock(i + 2, j + 1, k + 10, MysticModBlocks.Elevator.blockID);
		world.setBlock(i + 2, j + 1, k + 11, MysticModBlocks.Elevator.blockID);
		world.setBlock(i + 2, j + 1, k + 12, MysticModBlocks.Elevator.blockID);
		world.setBlock(i + 2, j + 1, k + 13, MysticModBlocks.Elevator.blockID);
		world.setBlock(i + 2, j + 1, k + 14, MysticModBlocks.Elevator.blockID);
		world.setBlock(i + 2, j + 1, k + 15, MysticModBlocks.Elevator.blockID);
		world.setBlock(i + 2, j + 2, k + 2, MysticModBlocks.Dropper.blockID);
		world.setBlock(i + 2, j + 2, k + 3, MysticModBlocks.Dropper.blockID);
		world.setBlock(i + 2, j + 2, k + 4, MysticModBlocks.Dropper.blockID);
		world.setBlock(i + 2, j + 2, k + 5, MysticModBlocks.Dropper.blockID);
		world.setBlock(i + 2, j + 2, k + 6, MysticModBlocks.Dropper.blockID);
		world.setBlock(i + 2, j + 2, k + 7, MysticModBlocks.Dropper.blockID);
		world.setBlock(i + 2, j + 2, k + 8, MysticModBlocks.Dropper.blockID);
		world.setBlock(i + 2, j + 2, k + 9, MysticModBlocks.Dropper.blockID);
		world.setBlock(i + 2, j + 2, k + 10, MysticModBlocks.Dropper.blockID);
		world.setBlock(i + 2, j + 2, k + 11, MysticModBlocks.Dropper.blockID);
		world.setBlock(i + 2, j + 2, k + 12, MysticModBlocks.Dropper.blockID);
		world.setBlock(i + 2, j + 2, k + 13, MysticModBlocks.Dropper.blockID);
		world.setBlock(i + 2, j + 2, k + 14, MysticModBlocks.Dropper.blockID);
		world.setBlock(i + 2, j + 2, k + 15, MysticModBlocks.Dropper.blockID);
		world.setBlock(i + 2, j + 18, k + 0, MysticModBlocks.mysticBricks.blockID);
		world.setBlock(i + 2, j + 18, k + 2, MysticModBlocks.mysticBricks.blockID);
		world.setBlock(i + 2, j + 18, k + 3, MysticModBlocks.mysticBricks.blockID);
		world.setBlock(i + 2, j + 18, k + 4, MysticModBlocks.mysticBricks.blockID);
		world.setBlock(i + 2, j + 18, k + 5, MysticModBlocks.mysticBricks.blockID);
		world.setBlock(i + 2, j + 18, k + 6, MysticModBlocks.mysticBricks.blockID);
		world.setBlock(i + 2, j + 18, k + 7, MysticModBlocks.mysticBricks.blockID);
		world.setBlock(i + 2, j + 18, k + 8, MysticModBlocks.mysticBricks.blockID);
		world.setBlock(i + 2, j + 18, k + 9, MysticModBlocks.mysticBricks.blockID);
		world.setBlock(i + 2, j + 18, k + 10, MysticModBlocks.mysticBricks.blockID);
		world.setBlock(i + 2, j + 18, k + 11, MysticModBlocks.mysticBricks.blockID);
		world.setBlock(i + 2, j + 18, k + 12, MysticModBlocks.mysticBricks.blockID);
		world.setBlock(i + 2, j + 18, k + 13, MysticModBlocks.mysticBricks.blockID);
		world.setBlock(i + 2, j + 18, k + 14, MysticModBlocks.mysticBricks.blockID);
		world.setBlock(i + 2, j + 18, k + 15, MysticModBlocks.mysticBricks.blockID);
		world.setBlock(i + 2, j + 18, k + 17, MysticModBlocks.mysticBricks.blockID);
		world.setBlock(i + 2, j + 19, k + 1, Block.stoneSingleSlab.blockID, 2,2);
		world.setBlock(i + 2, j + 19, k + 16, Block.stoneSingleSlab.blockID, 2,2);
		world.setBlock(i + 3, j + 0, k + 0, Block.stoneSingleSlab.blockID, 2,2);
		world.setBlock(i + 3, j + 0, k + 2, Block.stoneSingleSlab.blockID, 2,2);
		world.setBlock(i + 3, j + 0, k + 3, MysticModBlocks.Elevator.blockID);
		world.setBlock(i + 3, j + 0, k + 4, MysticModBlocks.Elevator.blockID);
		world.setBlock(i + 3, j + 0, k + 5, MysticModBlocks.Elevator.blockID);
		world.setBlock(i + 3, j + 0, k + 6, MysticModBlocks.Elevator.blockID);
		world.setBlock(i + 3, j + 0, k + 7, MysticModBlocks.Elevator.blockID);
		world.setBlock(i + 3, j + 0, k + 8, MysticModBlocks.Elevator.blockID);
		world.setBlock(i + 3, j + 0, k + 9, MysticModBlocks.Elevator.blockID);
		world.setBlock(i + 3, j + 0, k + 10, MysticModBlocks.Elevator.blockID);
		world.setBlock(i + 3, j + 0, k + 11, MysticModBlocks.Elevator.blockID);
		world.setBlock(i + 3, j + 0, k + 12, MysticModBlocks.Elevator.blockID);
		world.setBlock(i + 3, j + 0, k + 13, MysticModBlocks.Elevator.blockID);
		world.setBlock(i + 3, j + 0, k + 14, MysticModBlocks.Elevator.blockID);
		world.setBlock(i + 3, j + 0, k + 15, Block.stoneSingleSlab.blockID, 2,2);
		world.setBlock(i + 3, j + 0, k + 17, Block.stoneSingleSlab.blockID, 2,2);
		world.setBlock(i + 3, j + 1, k + 2, MysticModBlocks.Elevator.blockID);
		world.setBlock(i + 3, j + 1, k + 3, Block.waterStill.blockID);
		world.setBlock(i + 3, j + 1, k + 4, Block.waterStill.blockID);
		world.setBlock(i + 3, j + 1, k + 5, Block.waterStill.blockID);
		world.setBlock(i + 3, j + 1, k + 6, Block.waterStill.blockID);
		world.setBlock(i + 3, j + 1, k + 7, Block.waterStill.blockID);
		world.setBlock(i + 3, j + 1, k + 8, Block.waterStill.blockID);
		world.setBlock(i + 3, j + 1, k + 9, Block.waterStill.blockID);
		world.setBlock(i + 3, j + 1, k + 10, Block.waterStill.blockID);
		world.setBlock(i + 3, j + 1, k + 11, Block.waterStill.blockID);
		world.setBlock(i + 3, j + 1, k + 12, Block.waterStill.blockID);
		world.setBlock(i + 3, j + 1, k + 13, Block.waterStill.blockID);
		world.setBlock(i + 3, j + 1, k + 14, Block.waterStill.blockID);
		world.setBlock(i + 3, j + 1, k + 15, MysticModBlocks.Elevator.blockID);
		world.setBlock(i + 3, j + 2, k + 2, MysticModBlocks.Dropper.blockID);
		world.setBlock(i + 3, j + 2, k + 3, Block.waterStill.blockID);
		world.setBlock(i + 3, j + 2, k + 4, Block.waterStill.blockID);
		world.setBlock(i + 3, j + 2, k + 5, Block.waterStill.blockID);
		world.setBlock(i + 3, j + 2, k + 6, Block.waterStill.blockID);
		world.setBlock(i + 3, j + 2, k + 7, Block.waterStill.blockID);
		world.setBlock(i + 3, j + 2, k + 8, Block.waterStill.blockID);
		world.setBlock(i + 3, j + 2, k + 9, Block.waterStill.blockID);
		world.setBlock(i + 3, j + 2, k + 10, Block.waterStill.blockID);
		world.setBlock(i + 3, j + 2, k + 11, Block.waterStill.blockID);
		world.setBlock(i + 3, j + 2, k + 12, Block.waterStill.blockID);
		world.setBlock(i + 3, j + 2, k + 13, Block.waterStill.blockID);
		world.setBlock(i + 3, j + 2, k + 14, Block.waterStill.blockID);
		world.setBlock(i + 3, j + 2, k + 15, MysticModBlocks.Dropper.blockID);
		world.setBlock(i + 3, j + 3, k + 3, MysticModBlocks.Dropper.blockID);
		world.setBlock(i + 3, j + 3, k + 4, MysticModBlocks.Dropper.blockID);
		world.setBlock(i + 3, j + 3, k + 5, MysticModBlocks.Dropper.blockID);
		world.setBlock(i + 3, j + 3, k + 6, MysticModBlocks.Dropper.blockID);
		world.setBlock(i + 3, j + 3, k + 7, MysticModBlocks.Dropper.blockID);
		world.setBlock(i + 3, j + 3, k + 8, MysticModBlocks.Dropper.blockID);
		world.setBlock(i + 3, j + 3, k + 9, MysticModBlocks.Dropper.blockID);
		world.setBlock(i + 3, j + 3, k + 10, MysticModBlocks.Dropper.blockID);
		world.setBlock(i + 3, j + 3, k + 11, MysticModBlocks.Dropper.blockID);
		world.setBlock(i + 3, j + 3, k + 12, MysticModBlocks.Dropper.blockID);
		world.setBlock(i + 3, j + 3, k + 13, MysticModBlocks.Dropper.blockID);
		world.setBlock(i + 3, j + 3, k + 14, MysticModBlocks.Dropper.blockID);
		world.setBlock(i + 3, j + 18, k + 0, MysticModBlocks.mysticBricks.blockID);
		world.setBlock(i + 3, j + 18, k + 2, MysticModBlocks.mysticBricks.blockID);
		world.setBlock(i + 3, j + 18, k + 15, MysticModBlocks.mysticBricks.blockID);
		world.setBlock(i + 3, j + 18, k + 17, MysticModBlocks.mysticBricks.blockID);
		world.setBlock(i + 3, j + 19, k + 1, Block.stoneSingleSlab.blockID, 2,2);
		world.setBlock(i + 3, j + 19, k + 3, Block.stoneSingleSlab.blockID, 2,2);
		world.setBlock(i + 3, j + 19, k + 4, Block.stoneSingleSlab.blockID, 2,2);
		world.setBlock(i + 3, j + 19, k + 5, Block.stoneSingleSlab.blockID, 2,2);
		world.setBlock(i + 3, j + 19, k + 6, Block.stoneSingleSlab.blockID, 2,2);
		world.setBlock(i + 3, j + 19, k + 7, Block.stoneSingleSlab.blockID, 2,2);
		world.setBlock(i + 3, j + 19, k + 8, Block.stoneSingleSlab.blockID, 2,2);
		world.setBlock(i + 3, j + 19, k + 9, Block.stoneSingleSlab.blockID, 2,2);
		world.setBlock(i + 3, j + 19, k + 10, Block.stoneSingleSlab.blockID, 2,2);
		world.setBlock(i + 3, j + 19, k + 11, Block.stoneSingleSlab.blockID, 2,2);
		world.setBlock(i + 3, j + 19, k + 12, Block.stoneSingleSlab.blockID, 2,2);
		world.setBlock(i + 3, j + 19, k + 13, Block.stoneSingleSlab.blockID, 2,2);
		world.setBlock(i + 3, j + 19, k + 14, Block.stoneSingleSlab.blockID, 2,2);
		world.setBlock(i + 3, j + 19, k + 16, Block.stoneSingleSlab.blockID, 2,2);
		world.setBlock(i + 4, j + 0, k + 0, Block.stoneSingleSlab.blockID, 2,2);
		world.setBlock(i + 4, j + 0, k + 2, Block.stoneSingleSlab.blockID, 2,2);
		world.setBlock(i + 4, j + 0, k + 3, MysticModBlocks.Elevator.blockID);
		world.setBlock(i + 4, j + 0, k + 4, MysticModBlocks.Elevator.blockID);
		world.setBlock(i + 4, j + 0, k + 5, MysticModBlocks.Elevator.blockID);
		world.setBlock(i + 4, j + 0, k + 6, MysticModBlocks.Elevator.blockID);
		world.setBlock(i + 4, j + 0, k + 7, MysticModBlocks.Elevator.blockID);
		world.setBlock(i + 4, j + 0, k + 8, MysticModBlocks.Elevator.blockID);
		world.setBlock(i + 4, j + 0, k + 9, MysticModBlocks.Elevator.blockID);
		world.setBlock(i + 4, j + 0, k + 10, MysticModBlocks.Elevator.blockID);
		world.setBlock(i + 4, j + 0, k + 11, MysticModBlocks.Elevator.blockID);
		world.setBlock(i + 4, j + 0, k + 12, MysticModBlocks.Elevator.blockID);
		world.setBlock(i + 4, j + 0, k + 13, MysticModBlocks.Elevator.blockID);
		world.setBlock(i + 4, j + 0, k + 14, MysticModBlocks.Elevator.blockID);
		world.setBlock(i + 4, j + 0, k + 15, Block.stoneSingleSlab.blockID, 2,2);
		world.setBlock(i + 4, j + 0, k + 17, Block.stoneSingleSlab.blockID, 2,2);
		world.setBlock(i + 4, j + 1, k + 2, MysticModBlocks.Elevator.blockID);
		world.setBlock(i + 4, j + 1, k + 3, Block.waterStill.blockID);
		world.setBlock(i + 4, j + 1, k + 4, Block.waterStill.blockID);
		world.setBlock(i + 4, j + 1, k + 5, Block.waterStill.blockID);
		world.setBlock(i + 4, j + 1, k + 6, Block.waterStill.blockID);
		world.setBlock(i + 4, j + 1, k + 7, Block.waterStill.blockID);
		world.setBlock(i + 4, j + 1, k + 8, Block.waterStill.blockID);
		world.setBlock(i + 4, j + 1, k + 9, Block.waterStill.blockID);
		world.setBlock(i + 4, j + 1, k + 10, Block.waterStill.blockID);
		world.setBlock(i + 4, j + 1, k + 11, Block.waterStill.blockID);
		world.setBlock(i + 4, j + 1, k + 12, Block.waterStill.blockID);
		world.setBlock(i + 4, j + 1, k + 13, Block.waterStill.blockID);
		world.setBlock(i + 4, j + 1, k + 14, Block.waterStill.blockID);
		world.setBlock(i + 4, j + 1, k + 15, MysticModBlocks.Elevator.blockID);
		world.setBlock(i + 4, j + 2, k + 2, MysticModBlocks.Dropper.blockID);
		world.setBlock(i + 4, j + 2, k + 3, Block.waterStill.blockID);
		world.setBlock(i + 4, j + 2, k + 4, Block.waterStill.blockID);
		world.setBlock(i + 4, j + 2, k + 5, Block.waterStill.blockID);
		world.setBlock(i + 4, j + 2, k + 6, Block.waterStill.blockID);
		world.setBlock(i + 4, j + 2, k + 7, Block.waterStill.blockID);
		world.setBlock(i + 4, j + 2, k + 8, Block.waterStill.blockID);
		world.setBlock(i + 4, j + 2, k + 9, Block.waterStill.blockID);
		world.setBlock(i + 4, j + 2, k + 10, Block.waterStill.blockID);
		world.setBlock(i + 4, j + 2, k + 11, Block.waterStill.blockID);
		world.setBlock(i + 4, j + 2, k + 12, Block.waterStill.blockID);
		world.setBlock(i + 4, j + 2, k + 13, Block.waterStill.blockID);
		world.setBlock(i + 4, j + 2, k + 14, Block.waterStill.blockID);
		world.setBlock(i + 4, j + 2, k + 15, MysticModBlocks.Dropper.blockID);
		world.setBlock(i + 4, j + 3, k + 3, MysticModBlocks.Dropper.blockID);
		world.setBlock(i + 4, j + 3, k + 4, MysticModBlocks.Dropper.blockID);
		world.setBlock(i + 4, j + 3, k + 5, MysticModBlocks.Dropper.blockID);
		world.setBlock(i + 4, j + 3, k + 6, MysticModBlocks.Dropper.blockID);
		world.setBlock(i + 4, j + 3, k + 7, MysticModBlocks.Dropper.blockID);
		world.setBlock(i + 4, j + 3, k + 8, MysticModBlocks.Dropper.blockID);
		world.setBlock(i + 4, j + 3, k + 9, MysticModBlocks.Dropper.blockID);
		world.setBlock(i + 4, j + 3, k + 10, MysticModBlocks.Dropper.blockID);
		world.setBlock(i + 4, j + 3, k + 11, MysticModBlocks.Dropper.blockID);
		world.setBlock(i + 4, j + 3, k + 12, MysticModBlocks.Dropper.blockID);
		world.setBlock(i + 4, j + 3, k + 13, MysticModBlocks.Dropper.blockID);
		world.setBlock(i + 4, j + 3, k + 14, MysticModBlocks.Dropper.blockID);
		world.setBlock(i + 4, j + 18, k + 0, MysticModBlocks.mysticBricks.blockID);
		world.setBlock(i + 4, j + 18, k + 2, MysticModBlocks.mysticBricks.blockID);
		world.setBlock(i + 4, j + 18, k + 15, MysticModBlocks.mysticBricks.blockID);
		world.setBlock(i + 4, j + 18, k + 17, MysticModBlocks.mysticBricks.blockID);
		world.setBlock(i + 4, j + 19, k + 1, Block.stoneSingleSlab.blockID, 2,2);
		world.setBlock(i + 4, j + 19, k + 3, Block.stoneSingleSlab.blockID, 2,2);
		world.setBlock(i + 4, j + 19, k + 4, Block.stoneSingleSlab.blockID, 2,2);
		world.setBlock(i + 4, j + 19, k + 5, Block.stoneSingleSlab.blockID, 2,2);
		world.setBlock(i + 4, j + 19, k + 6, Block.stoneSingleSlab.blockID, 2,2);
		world.setBlock(i + 4, j + 19, k + 7, Block.stoneSingleSlab.blockID, 2,2);
		world.setBlock(i + 4, j + 19, k + 8, Block.stoneSingleSlab.blockID, 2,2);
		world.setBlock(i + 4, j + 19, k + 9, Block.stoneSingleSlab.blockID, 2,2);
		world.setBlock(i + 4, j + 19, k + 10, Block.stoneSingleSlab.blockID, 2,2);
		world.setBlock(i + 4, j + 19, k + 11, Block.stoneSingleSlab.blockID, 2,2);
		world.setBlock(i + 4, j + 19, k + 12, Block.stoneSingleSlab.blockID, 2,2);
		world.setBlock(i + 4, j + 19, k + 13, Block.stoneSingleSlab.blockID, 2,2);
		world.setBlock(i + 4, j + 19, k + 14, Block.stoneSingleSlab.blockID, 2,2);
		world.setBlock(i + 4, j + 19, k + 16, Block.stoneSingleSlab.blockID, 2,2);
		world.setBlock(i + 4, j + 20, k + 4, Block.stoneSingleSlab.blockID, 2,2);
		world.setBlock(i + 4, j + 20, k + 5, Block.stoneSingleSlab.blockID, 2,2);
		world.setBlock(i + 4, j + 20, k + 6, Block.stoneSingleSlab.blockID, 2,2);
		world.setBlock(i + 4, j + 20, k + 7, Block.stoneSingleSlab.blockID, 2,2);
		world.setBlock(i + 4, j + 20, k + 8, Block.stoneSingleSlab.blockID, 2,2);
		world.setBlock(i + 4, j + 20, k + 9, Block.stoneSingleSlab.blockID, 2,2);
		world.setBlock(i + 4, j + 20, k + 10, Block.stoneSingleSlab.blockID, 2,2);
		world.setBlock(i + 4, j + 20, k + 11, Block.stoneSingleSlab.blockID, 2,2);
		world.setBlock(i + 4, j + 20, k + 12, Block.stoneSingleSlab.blockID, 2,2);
		world.setBlock(i + 4, j + 20, k + 13, Block.stoneSingleSlab.blockID, 2,2);
		world.setBlock(i + 5, j + 0, k + 0, Block.stoneSingleSlab.blockID, 2,2);
		world.setBlock(i + 5, j + 0, k + 2, Block.stoneSingleSlab.blockID, 2,2);
		world.setBlock(i + 5, j + 0, k + 3, MysticModBlocks.Elevator.blockID);
		world.setBlock(i + 5, j + 0, k + 4, MysticModBlocks.Elevator.blockID);
		world.setBlock(i + 5, j + 0, k + 13, MysticModBlocks.Elevator.blockID);
		world.setBlock(i + 5, j + 0, k + 14, MysticModBlocks.Elevator.blockID);
		world.setBlock(i + 5, j + 0, k + 15, Block.stoneSingleSlab.blockID, 2,2);
		world.setBlock(i + 5, j + 0, k + 17, Block.stoneSingleSlab.blockID, 2,2);
		world.setBlock(i + 5, j + 1, k + 2, MysticModBlocks.Elevator.blockID);
		world.setBlock(i + 5, j + 1, k + 3, Block.waterStill.blockID);
		world.setBlock(i + 5, j + 1, k + 4, Block.waterStill.blockID);
		world.setBlock(i + 5, j + 1, k + 5, MysticModBlocks.Elevator.blockID);
		world.setBlock(i + 5, j + 1, k + 6, MysticModBlocks.Elevator.blockID);
		world.setBlock(i + 5, j + 1, k + 7, MysticModBlocks.Elevator.blockID);
		world.setBlock(i + 5, j + 1, k + 8, MysticModBlocks.Elevator.blockID);
		world.setBlock(i + 5, j + 1, k + 9, MysticModBlocks.Elevator.blockID);
		world.setBlock(i + 5, j + 1, k + 10, MysticModBlocks.Elevator.blockID);
		world.setBlock(i + 5, j + 1, k + 11, MysticModBlocks.Elevator.blockID);
		world.setBlock(i + 5, j + 1, k + 12, MysticModBlocks.Elevator.blockID);
		world.setBlock(i + 5, j + 1, k + 13, Block.waterStill.blockID);
		world.setBlock(i + 5, j + 1, k + 14, Block.waterStill.blockID);
		world.setBlock(i + 5, j + 1, k + 15, MysticModBlocks.Elevator.blockID);
		world.setBlock(i + 5, j + 2, k + 2, MysticModBlocks.Dropper.blockID);
		world.setBlock(i + 5, j + 2, k + 3, Block.waterStill.blockID);
		world.setBlock(i + 5, j + 2, k + 4, Block.waterStill.blockID);
		world.setBlock(i + 5, j + 2, k + 5, MysticModBlocks.Dropper.blockID);
		world.setBlock(i + 5, j + 2, k + 6, MysticModBlocks.Dropper.blockID);
		world.setBlock(i + 5, j + 2, k + 7, MysticModBlocks.Dropper.blockID);
		world.setBlock(i + 5, j + 2, k + 8, MysticModBlocks.Dropper.blockID);
		world.setBlock(i + 5, j + 2, k + 9, MysticModBlocks.Dropper.blockID);
		world.setBlock(i + 5, j + 2, k + 10, MysticModBlocks.Dropper.blockID);
		world.setBlock(i + 5, j + 2, k + 11, MysticModBlocks.Dropper.blockID);
		world.setBlock(i + 5, j + 2, k + 12, MysticModBlocks.Dropper.blockID);
		world.setBlock(i + 5, j + 2, k + 13, Block.waterStill.blockID);
		world.setBlock(i + 5, j + 2, k + 14, Block.waterStill.blockID);
		world.setBlock(i + 5, j + 2, k + 15, MysticModBlocks.Dropper.blockID);
		world.setBlock(i + 5, j + 3, k + 3, MysticModBlocks.Dropper.blockID);
		world.setBlock(i + 5, j + 3, k + 4, MysticModBlocks.Dropper.blockID);
		world.setBlock(i + 5, j + 3, k + 13, MysticModBlocks.Dropper.blockID);
		world.setBlock(i + 5, j + 3, k + 14, MysticModBlocks.Dropper.blockID);
		world.setBlock(i + 5, j + 18, k + 0, MysticModBlocks.mysticBricks.blockID);
		world.setBlock(i + 5, j + 18, k + 2, MysticModBlocks.mysticBricks.blockID);
		world.setBlock(i + 5, j + 18, k + 15, MysticModBlocks.mysticBricks.blockID);
		world.setBlock(i + 5, j + 18, k + 17, MysticModBlocks.mysticBricks.blockID);
		world.setBlock(i + 5, j + 19, k + 1, Block.stoneSingleSlab.blockID, 2,2);
		world.setBlock(i + 5, j + 19, k + 3, Block.stoneSingleSlab.blockID, 2,2);
		world.setBlock(i + 5, j + 19, k + 4, Block.stoneSingleSlab.blockID, 2,2);
		world.setBlock(i + 5, j + 19, k + 5, MysticModBlocks.mysticGlass.blockID);
		world.setBlock(i + 5, j + 19, k + 6, MysticModBlocks.mysticGlass.blockID);
		world.setBlock(i + 5, j + 19, k + 7, MysticModBlocks.mysticGlass.blockID);
		world.setBlock(i + 5, j + 19, k + 8, MysticModBlocks.mysticGlass.blockID);
		world.setBlock(i + 5, j + 19, k + 9, MysticModBlocks.mysticGlass.blockID);
		world.setBlock(i + 5, j + 19, k + 10, MysticModBlocks.mysticGlass.blockID);
		world.setBlock(i + 5, j + 19, k + 11, MysticModBlocks.mysticGlass.blockID);
		world.setBlock(i + 5, j + 19, k + 12, MysticModBlocks.mysticGlass.blockID);
		world.setBlock(i + 5, j + 19, k + 13, Block.stoneSingleSlab.blockID, 2,2);
		world.setBlock(i + 5, j + 19, k + 14, Block.stoneSingleSlab.blockID, 2,2);
		world.setBlock(i + 5, j + 19, k + 16, Block.stoneSingleSlab.blockID, 2,2);
		world.setBlock(i + 5, j + 20, k + 4, Block.stoneSingleSlab.blockID, 2,2);
		world.setBlock(i + 5, j + 20, k + 13, Block.stoneSingleSlab.blockID, 2,2);
		world.setBlock(i + 6, j + 0, k + 0, Block.stoneSingleSlab.blockID, 2,2);
		world.setBlock(i + 6, j + 0, k + 2, Block.stoneSingleSlab.blockID, 2,2);
		world.setBlock(i + 6, j + 0, k + 3, MysticModBlocks.Elevator.blockID);
		world.setBlock(i + 6, j + 0, k + 4, MysticModBlocks.Elevator.blockID);
		world.setBlock(i + 6, j + 0, k + 13, MysticModBlocks.Elevator.blockID);
		world.setBlock(i + 6, j + 0, k + 14, MysticModBlocks.Elevator.blockID);
		world.setBlock(i + 6, j + 0, k + 15, Block.stoneSingleSlab.blockID, 2,2);
		world.setBlock(i + 6, j + 0, k + 17, Block.stoneSingleSlab.blockID, 2,2);
		world.setBlock(i + 6, j + 1, k + 2, MysticModBlocks.Elevator.blockID);
		world.setBlock(i + 6, j + 1, k + 3, Block.waterStill.blockID);
		world.setBlock(i + 6, j + 1, k + 4, Block.waterStill.blockID);
		world.setBlock(i + 6, j + 1, k + 5, MysticModBlocks.Elevator.blockID);
		world.setBlock(i + 6, j + 1, k + 12, MysticModBlocks.Elevator.blockID);
		world.setBlock(i + 6, j + 1, k + 13, Block.waterStill.blockID);
		world.setBlock(i + 6, j + 1, k + 14, Block.waterStill.blockID);
		world.setBlock(i + 6, j + 1, k + 15, MysticModBlocks.Elevator.blockID);
		world.setBlock(i + 6, j + 2, k + 2, MysticModBlocks.Dropper.blockID);
		world.setBlock(i + 6, j + 2, k + 3, Block.waterStill.blockID);
		world.setBlock(i + 6, j + 2, k + 4, Block.waterStill.blockID);
		world.setBlock(i + 6, j + 2, k + 5, MysticModBlocks.Dropper.blockID);
		world.setBlock(i + 6, j + 2, k + 12, MysticModBlocks.Dropper.blockID);
		world.setBlock(i + 6, j + 2, k + 13, Block.waterStill.blockID);
		world.setBlock(i + 6, j + 2, k + 14, Block.waterStill.blockID);
		world.setBlock(i + 6, j + 2, k + 15, MysticModBlocks.Dropper.blockID);
		world.setBlock(i + 6, j + 3, k + 3, MysticModBlocks.Dropper.blockID);
		world.setBlock(i + 6, j + 3, k + 4, MysticModBlocks.Dropper.blockID);
		world.setBlock(i + 6, j + 3, k + 13, MysticModBlocks.Dropper.blockID);
		world.setBlock(i + 6, j + 3, k + 14, MysticModBlocks.Dropper.blockID);
		world.setBlock(i + 6, j + 18, k + 0, MysticModBlocks.mysticBricks.blockID);
		world.setBlock(i + 6, j + 18, k + 2, MysticModBlocks.mysticBricks.blockID);
		world.setBlock(i + 6, j + 18, k + 15, MysticModBlocks.mysticBricks.blockID);
		world.setBlock(i + 6, j + 18, k + 17, MysticModBlocks.mysticBricks.blockID);
		world.setBlock(i + 6, j + 19, k + 1, Block.stoneSingleSlab.blockID, 2,2);
		world.setBlock(i + 6, j + 19, k + 3, Block.stoneSingleSlab.blockID, 2,2);
		world.setBlock(i + 6, j + 19, k + 4, Block.stoneSingleSlab.blockID, 2,2);
		world.setBlock(i + 6, j + 19, k + 5, MysticModBlocks.mysticGlass.blockID);
		world.setBlock(i + 6, j + 19, k + 6, MysticModBlocks.mysticGlass.blockID);
		world.setBlock(i + 6, j + 19, k + 7, MysticModBlocks.mysticGlass.blockID);
		world.setBlock(i + 6, j + 19, k + 8, MysticModBlocks.mysticGlass.blockID);
		world.setBlock(i + 6, j + 19, k + 9, MysticModBlocks.mysticGlass.blockID);
		world.setBlock(i + 6, j + 19, k + 10, MysticModBlocks.mysticGlass.blockID);
		world.setBlock(i + 6, j + 19, k + 11, MysticModBlocks.mysticGlass.blockID);
		world.setBlock(i + 6, j + 19, k + 12, MysticModBlocks.mysticGlass.blockID);
		world.setBlock(i + 6, j + 19, k + 13, Block.stoneSingleSlab.blockID, 2,2);
		world.setBlock(i + 6, j + 19, k + 14, Block.stoneSingleSlab.blockID, 2,2);
		world.setBlock(i + 6, j + 19, k + 16, Block.stoneSingleSlab.blockID, 2,2);
		world.setBlock(i + 6, j + 20, k + 4, Block.stoneSingleSlab.blockID, 2,2);
		world.setBlock(i + 6, j + 20, k + 13, Block.stoneSingleSlab.blockID, 2,2);
		world.setBlock(i + 7, j + 0, k + 0, Block.stoneSingleSlab.blockID, 2,2);
		world.setBlock(i + 7, j + 0, k + 2, Block.stoneSingleSlab.blockID, 2,2);
		world.setBlock(i + 7, j + 0, k + 3, MysticModBlocks.Elevator.blockID);
		world.setBlock(i + 7, j + 0, k + 4, MysticModBlocks.Elevator.blockID);
		world.setBlock(i + 7, j + 0, k + 7, Block.stoneSingleSlab.blockID, 2,2);
		world.setBlock(i + 7, j + 0, k + 8, Block.stoneSingleSlab.blockID, 2,2);
		world.setBlock(i + 7, j + 0, k + 9, Block.stoneSingleSlab.blockID, 2,2);
		world.setBlock(i + 7, j + 0, k + 10, Block.stoneSingleSlab.blockID, 2,2);
		world.setBlock(i + 7, j + 0, k + 13, MysticModBlocks.Elevator.blockID);
		world.setBlock(i + 7, j + 0, k + 14, MysticModBlocks.Elevator.blockID);
		world.setBlock(i + 7, j + 0, k + 15, Block.stoneSingleSlab.blockID, 2,2);
		world.setBlock(i + 7, j + 0, k + 17, Block.stoneSingleSlab.blockID, 2,2);
		world.setBlock(i + 7, j + 1, k + 2, MysticModBlocks.Elevator.blockID);
		world.setBlock(i + 7, j + 1, k + 3, Block.waterStill.blockID);
		world.setBlock(i + 7, j + 1, k + 4, Block.waterStill.blockID);
		world.setBlock(i + 7, j + 1, k + 5, MysticModBlocks.Elevator.blockID);
		world.setBlock(i + 7, j + 1, k + 12, MysticModBlocks.Elevator.blockID);
		world.setBlock(i + 7, j + 1, k + 13, Block.waterStill.blockID);
		world.setBlock(i + 7, j + 1, k + 14, Block.waterStill.blockID);
		world.setBlock(i + 7, j + 1, k + 15, MysticModBlocks.Elevator.blockID);
		world.setBlock(i + 7, j + 2, k + 2, MysticModBlocks.Dropper.blockID);
		world.setBlock(i + 7, j + 2, k + 3, Block.waterStill.blockID);
		world.setBlock(i + 7, j + 2, k + 4, Block.waterStill.blockID);
		world.setBlock(i + 7, j + 2, k + 5, MysticModBlocks.Dropper.blockID);
		world.setBlock(i + 7, j + 2, k + 12, MysticModBlocks.Dropper.blockID);
		world.setBlock(i + 7, j + 2, k + 13, Block.waterStill.blockID);
		world.setBlock(i + 7, j + 2, k + 14, Block.waterStill.blockID);
		world.setBlock(i + 7, j + 2, k + 15, MysticModBlocks.Dropper.blockID);
		world.setBlock(i + 7, j + 3, k + 3, MysticModBlocks.Dropper.blockID);
		world.setBlock(i + 7, j + 3, k + 4, MysticModBlocks.Dropper.blockID);
		world.setBlock(i + 7, j + 3, k + 13, MysticModBlocks.Dropper.blockID);
		world.setBlock(i + 7, j + 3, k + 14, MysticModBlocks.Dropper.blockID);
		world.setBlock(i + 7, j + 18, k + 0, MysticModBlocks.mysticBricks.blockID);
		world.setBlock(i + 7, j + 18, k + 2, MysticModBlocks.mysticBricks.blockID);
		world.setBlock(i + 7, j + 18, k + 15, MysticModBlocks.mysticBricks.blockID);
		world.setBlock(i + 7, j + 18, k + 17, MysticModBlocks.mysticBricks.blockID);
		world.setBlock(i + 7, j + 19, k + 1, Block.stoneSingleSlab.blockID, 2,2);
		world.setBlock(i + 7, j + 19, k + 3, Block.stoneSingleSlab.blockID, 2,2);
		world.setBlock(i + 7, j + 19, k + 4, Block.stoneSingleSlab.blockID, 2,2);
		world.setBlock(i + 7, j + 19, k + 5, MysticModBlocks.mysticGlass.blockID);
		world.setBlock(i + 7, j + 19, k + 6, MysticModBlocks.mysticGlass.blockID);
		world.setBlock(i + 7, j + 19, k + 7, MysticModBlocks.mysticGlass.blockID);
		world.setBlock(i + 7, j + 19, k + 8, MysticModBlocks.mysticGlass.blockID);
		world.setBlock(i + 7, j + 19, k + 9, MysticModBlocks.mysticGlass.blockID);
		world.setBlock(i + 7, j + 19, k + 10, MysticModBlocks.mysticGlass.blockID);
		world.setBlock(i + 7, j + 19, k + 11, MysticModBlocks.mysticGlass.blockID);
		world.setBlock(i + 7, j + 19, k + 12, MysticModBlocks.mysticGlass.blockID);
		world.setBlock(i + 7, j + 19, k + 13, Block.stoneSingleSlab.blockID, 2,2);
		world.setBlock(i + 7, j + 19, k + 14, Block.stoneSingleSlab.blockID, 2,2);
		world.setBlock(i + 7, j + 19, k + 16, Block.stoneSingleSlab.blockID, 2,2);
		world.setBlock(i + 7, j + 20, k + 4, Block.stoneSingleSlab.blockID, 2,2);
		world.setBlock(i + 7, j + 20, k + 13, Block.stoneSingleSlab.blockID, 2,2);
		world.setBlock(i + 8, j + 0, k + 0, Block.stoneSingleSlab.blockID, 2,2);
		world.setBlock(i + 8, j + 0, k + 2, Block.stoneSingleSlab.blockID, 2,2);
		world.setBlock(i + 8, j + 0, k + 3, MysticModBlocks.Elevator.blockID);
		world.setBlock(i + 8, j + 0, k + 4, MysticModBlocks.Elevator.blockID);
		world.setBlock(i + 8, j + 0, k + 7, Block.stoneSingleSlab.blockID, 2,2);
		world.setBlock(i + 8, j + 0, k + 8, Block.mobSpawner.blockID);
		TileEntityMobSpawner tile2 = (TileEntityMobSpawner) world.getBlockTileEntity(i+8, j+0, k+8);
		tile2.getSpawnerLogic().setMobID("MysticAdditions.WaterMiniBoss");
		world.setBlock(i + 8, j + 0, k + 9, Block.stoneSingleSlab.blockID, 2,2);
		world.setBlock(i + 8, j + 0, k + 10, Block.stoneSingleSlab.blockID, 2,2);
		world.setBlock(i + 8, j + 0, k + 13, MysticModBlocks.Elevator.blockID);
		world.setBlock(i + 8, j + 0, k + 14, MysticModBlocks.Elevator.blockID);
		world.setBlock(i + 8, j + 0, k + 15, Block.stoneSingleSlab.blockID, 2,2);
		world.setBlock(i + 8, j + 0, k + 17, Block.stoneSingleSlab.blockID, 2,2);
		world.setBlock(i + 8, j + 1, k + 2, MysticModBlocks.Elevator.blockID);
		world.setBlock(i + 8, j + 1, k + 3, Block.waterStill.blockID);
		world.setBlock(i + 8, j + 1, k + 4, Block.waterStill.blockID);
		world.setBlock(i + 8, j + 1, k + 5, MysticModBlocks.Elevator.blockID);
		world.setBlock(i + 8, j + 1, k + 12, MysticModBlocks.Elevator.blockID);
		world.setBlock(i + 8, j + 1, k + 13, Block.waterStill.blockID);
		world.setBlock(i + 8, j + 1, k + 14, Block.waterStill.blockID);
		world.setBlock(i + 8, j + 1, k + 15, MysticModBlocks.Elevator.blockID);
		world.setBlock(i + 8, j + 2, k + 2, MysticModBlocks.Dropper.blockID);
		world.setBlock(i + 8, j + 2, k + 3, Block.waterStill.blockID);
		world.setBlock(i + 8, j + 2, k + 4, Block.waterStill.blockID);
		world.setBlock(i + 8, j + 2, k + 5, MysticModBlocks.Dropper.blockID);
		world.setBlock(i + 8, j + 2, k + 12, MysticModBlocks.Dropper.blockID);
		world.setBlock(i + 8, j + 2, k + 13, Block.waterStill.blockID);
		world.setBlock(i + 8, j + 2, k + 14, Block.waterStill.blockID);
		world.setBlock(i + 8, j + 2, k + 15, MysticModBlocks.Dropper.blockID);
		world.setBlock(i + 8, j + 3, k + 3, MysticModBlocks.Dropper.blockID);
		world.setBlock(i + 8, j + 3, k + 4, MysticModBlocks.Dropper.blockID);
		world.setBlock(i + 8, j + 3, k + 13, MysticModBlocks.Dropper.blockID);
		world.setBlock(i + 8, j + 3, k + 14, MysticModBlocks.Dropper.blockID);
		world.setBlock(i + 8, j + 18, k + 0, MysticModBlocks.mysticBricks.blockID);
		world.setBlock(i + 8, j + 18, k + 2, MysticModBlocks.mysticBricks.blockID);
		world.setBlock(i + 8, j + 18, k + 15, MysticModBlocks.mysticBricks.blockID);
		world.setBlock(i + 8, j + 18, k + 17, MysticModBlocks.mysticBricks.blockID);
		world.setBlock(i + 8, j + 19, k + 1, Block.stoneSingleSlab.blockID, 2,2);
		world.setBlock(i + 8, j + 19, k + 3, Block.stoneSingleSlab.blockID, 2,2);
		world.setBlock(i + 8, j + 19, k + 4, Block.stoneSingleSlab.blockID, 2,2);
		world.setBlock(i + 8, j + 19, k + 5, MysticModBlocks.mysticGlass.blockID);
		world.setBlock(i + 8, j + 19, k + 6, MysticModBlocks.mysticGlass.blockID);
		world.setBlock(i + 8, j + 19, k + 7, MysticModBlocks.mysticGlass.blockID);
		world.setBlock(i + 8, j + 19, k + 8, MysticModBlocks.mysticGlass.blockID);
		world.setBlock(i + 8, j + 19, k + 9, MysticModBlocks.mysticGlass.blockID);
		world.setBlock(i + 8, j + 19, k + 10, MysticModBlocks.mysticGlass.blockID);
		world.setBlock(i + 8, j + 19, k + 11, MysticModBlocks.mysticGlass.blockID);
		world.setBlock(i + 8, j + 19, k + 12, MysticModBlocks.mysticGlass.blockID);
		world.setBlock(i + 8, j + 19, k + 13, Block.stoneSingleSlab.blockID, 2,2);
		world.setBlock(i + 8, j + 19, k + 14, Block.stoneSingleSlab.blockID, 2,2);
		world.setBlock(i + 8, j + 19, k + 16, Block.stoneSingleSlab.blockID, 2,2);
		world.setBlock(i + 8, j + 20, k + 4, Block.stoneSingleSlab.blockID, 2,2);
		world.setBlock(i + 8, j + 20, k + 13, Block.stoneSingleSlab.blockID, 2,2);
		world.setBlock(i + 9, j + 0, k + 0, Block.stoneSingleSlab.blockID, 2,2);
		world.setBlock(i + 9, j + 0, k + 2, Block.stoneSingleSlab.blockID, 2,2);
		world.setBlock(i + 9, j + 0, k + 3, MysticModBlocks.Elevator.blockID);
		world.setBlock(i + 9, j + 0, k + 4, MysticModBlocks.Elevator.blockID);
		world.setBlock(i + 9, j + 0, k + 7, Block.stoneSingleSlab.blockID, 2,2);
		world.setBlock(i + 9, j + 0, k + 8, Block.stoneSingleSlab.blockID, 2,2);
		world.setBlock(i + 9, j + 0, k + 9, Block.chest.blockID);
		TileEntityChest tile = (TileEntityChest) world.getBlockTileEntity(i+9, j+0, k+9);
		tile.setInventorySlotContents(0, new ItemStack(MysticModItems.waterToken, 1));
		world.setBlock(i + 9, j + 0, k + 10, Block.stoneSingleSlab.blockID, 2,2);
		world.setBlock(i + 9, j + 0, k + 13, MysticModBlocks.Elevator.blockID);
		world.setBlock(i + 9, j + 0, k + 14, MysticModBlocks.Elevator.blockID);
		world.setBlock(i + 9, j + 0, k + 15, Block.stoneSingleSlab.blockID, 2,2);
		world.setBlock(i + 9, j + 0, k + 17, Block.stoneSingleSlab.blockID, 2,2);
		world.setBlock(i + 9, j + 1, k + 2, MysticModBlocks.Elevator.blockID);
		world.setBlock(i + 9, j + 1, k + 3, Block.waterStill.blockID);
		world.setBlock(i + 9, j + 1, k + 4, Block.waterStill.blockID);
		world.setBlock(i + 9, j + 1, k + 5, MysticModBlocks.Elevator.blockID);
		world.setBlock(i + 9, j + 1, k + 12, MysticModBlocks.Elevator.blockID);
		world.setBlock(i + 9, j + 1, k + 13, Block.waterStill.blockID);
		world.setBlock(i + 9, j + 1, k + 14, Block.waterStill.blockID);
		world.setBlock(i + 9, j + 1, k + 15, MysticModBlocks.Elevator.blockID);
		world.setBlock(i + 9, j + 2, k + 2, MysticModBlocks.Dropper.blockID);
		world.setBlock(i + 9, j + 2, k + 3, Block.waterStill.blockID);
		world.setBlock(i + 9, j + 2, k + 4, Block.waterStill.blockID);
		world.setBlock(i + 9, j + 2, k + 5, MysticModBlocks.Dropper.blockID);
		world.setBlock(i + 9, j + 2, k + 12, MysticModBlocks.Dropper.blockID);
		world.setBlock(i + 9, j + 2, k + 13, Block.waterStill.blockID);
		world.setBlock(i + 9, j + 2, k + 14, Block.waterStill.blockID);
		world.setBlock(i + 9, j + 2, k + 15, MysticModBlocks.Dropper.blockID);
		world.setBlock(i + 9, j + 3, k + 3, MysticModBlocks.Dropper.blockID);
		world.setBlock(i + 9, j + 3, k + 4, MysticModBlocks.Dropper.blockID);
		world.setBlock(i + 9, j + 3, k + 13, MysticModBlocks.Dropper.blockID);
		world.setBlock(i + 9, j + 3, k + 14, MysticModBlocks.Dropper.blockID);
		world.setBlock(i + 9, j + 18, k + 0, MysticModBlocks.mysticBricks.blockID);
		world.setBlock(i + 9, j + 18, k + 2, MysticModBlocks.mysticBricks.blockID);
		world.setBlock(i + 9, j + 18, k + 15, MysticModBlocks.mysticBricks.blockID);
		world.setBlock(i + 9, j + 18, k + 17, MysticModBlocks.mysticBricks.blockID);
		world.setBlock(i + 9, j + 19, k + 1, Block.stoneSingleSlab.blockID, 2,2);
		world.setBlock(i + 9, j + 19, k + 3, Block.stoneSingleSlab.blockID, 2,2);
		world.setBlock(i + 9, j + 19, k + 4, Block.stoneSingleSlab.blockID, 2,2);
		world.setBlock(i + 9, j + 19, k + 5, MysticModBlocks.mysticGlass.blockID);
		world.setBlock(i + 9, j + 19, k + 6, MysticModBlocks.mysticGlass.blockID);
		world.setBlock(i + 9, j + 19, k + 7, MysticModBlocks.mysticGlass.blockID);
		world.setBlock(i + 9, j + 19, k + 8, MysticModBlocks.mysticGlass.blockID);
		world.setBlock(i + 9, j + 19, k + 9, MysticModBlocks.mysticGlass.blockID);
		world.setBlock(i + 9, j + 19, k + 10, MysticModBlocks.mysticGlass.blockID);
		world.setBlock(i + 9, j + 19, k + 11, MysticModBlocks.mysticGlass.blockID);
		world.setBlock(i + 9, j + 19, k + 12, MysticModBlocks.mysticGlass.blockID);
		world.setBlock(i + 9, j + 19, k + 13, Block.stoneSingleSlab.blockID, 2,2);
		world.setBlock(i + 9, j + 19, k + 14, Block.stoneSingleSlab.blockID, 2,2);
		world.setBlock(i + 9, j + 19, k + 16, Block.stoneSingleSlab.blockID, 2,2);
		world.setBlock(i + 9, j + 20, k + 4, Block.stoneSingleSlab.blockID, 2,2);
		world.setBlock(i + 9, j + 20, k + 13, Block.stoneSingleSlab.blockID, 2,2);
		world.setBlock(i + 10, j + 0, k + 0, Block.stoneSingleSlab.blockID, 2,2);
		world.setBlock(i + 10, j + 0, k + 2, Block.stoneSingleSlab.blockID, 2,2);
		world.setBlock(i + 10, j + 0, k + 3, MysticModBlocks.Elevator.blockID);
		world.setBlock(i + 10, j + 0, k + 4, MysticModBlocks.Elevator.blockID);
		world.setBlock(i + 10, j + 0, k + 7, Block.stoneSingleSlab.blockID, 2,2);
		world.setBlock(i + 10, j + 0, k + 8, Block.stoneSingleSlab.blockID, 2,2);
		world.setBlock(i + 10, j + 0, k + 9, Block.stoneSingleSlab.blockID, 2,2);
		world.setBlock(i + 10, j + 0, k + 10, Block.stoneSingleSlab.blockID, 2,2);
		world.setBlock(i + 10, j + 0, k + 13, MysticModBlocks.Elevator.blockID);
		world.setBlock(i + 10, j + 0, k + 14, MysticModBlocks.Elevator.blockID);
		world.setBlock(i + 10, j + 0, k + 15, Block.stoneSingleSlab.blockID, 2,2);
		world.setBlock(i + 10, j + 0, k + 17, Block.stoneSingleSlab.blockID, 2,2);
		world.setBlock(i + 10, j + 1, k + 2, MysticModBlocks.Elevator.blockID);
		world.setBlock(i + 10, j + 1, k + 3, Block.waterStill.blockID);
		world.setBlock(i + 10, j + 1, k + 4, Block.waterStill.blockID);
		world.setBlock(i + 10, j + 1, k + 5, MysticModBlocks.Elevator.blockID);
		world.setBlock(i + 10, j + 1, k + 12, MysticModBlocks.Elevator.blockID);
		world.setBlock(i + 10, j + 1, k + 13, Block.waterStill.blockID);
		world.setBlock(i + 10, j + 1, k + 14, Block.waterStill.blockID);
		world.setBlock(i + 10, j + 1, k + 15, MysticModBlocks.Elevator.blockID);
		world.setBlock(i + 10, j + 2, k + 2, MysticModBlocks.Dropper.blockID);
		world.setBlock(i + 10, j + 2, k + 3, Block.waterStill.blockID);
		world.setBlock(i + 10, j + 2, k + 4, Block.waterStill.blockID);
		world.setBlock(i + 10, j + 2, k + 5, MysticModBlocks.Dropper.blockID);
		world.setBlock(i + 10, j + 2, k + 12, MysticModBlocks.Dropper.blockID);
		world.setBlock(i + 10, j + 2, k + 13, Block.waterStill.blockID);
		world.setBlock(i + 10, j + 2, k + 14, Block.waterStill.blockID);
		world.setBlock(i + 10, j + 2, k + 15, MysticModBlocks.Dropper.blockID);
		world.setBlock(i + 10, j + 3, k + 3, MysticModBlocks.Dropper.blockID);
		world.setBlock(i + 10, j + 3, k + 4, MysticModBlocks.Dropper.blockID);
		world.setBlock(i + 10, j + 3, k + 13, MysticModBlocks.Dropper.blockID);
		world.setBlock(i + 10, j + 3, k + 14, MysticModBlocks.Dropper.blockID);
		world.setBlock(i + 10, j + 18, k + 0, MysticModBlocks.mysticBricks.blockID);
		world.setBlock(i + 10, j + 18, k + 2, MysticModBlocks.mysticBricks.blockID);
		world.setBlock(i + 10, j + 18, k + 15, MysticModBlocks.mysticBricks.blockID);
		world.setBlock(i + 10, j + 18, k + 17, MysticModBlocks.mysticBricks.blockID);
		world.setBlock(i + 10, j + 19, k + 1, Block.stoneSingleSlab.blockID, 2,2);
		world.setBlock(i + 10, j + 19, k + 3, Block.stoneSingleSlab.blockID, 2,2);
		world.setBlock(i + 10, j + 19, k + 4, Block.stoneSingleSlab.blockID, 2,2);
		world.setBlock(i + 10, j + 19, k + 5, MysticModBlocks.mysticGlass.blockID);
		world.setBlock(i + 10, j + 19, k + 6, MysticModBlocks.mysticGlass.blockID);
		world.setBlock(i + 10, j + 19, k + 7, MysticModBlocks.mysticGlass.blockID);
		world.setBlock(i + 10, j + 19, k + 8, MysticModBlocks.mysticGlass.blockID);
		world.setBlock(i + 10, j + 19, k + 9, MysticModBlocks.mysticGlass.blockID);
		world.setBlock(i + 10, j + 19, k + 10, MysticModBlocks.mysticGlass.blockID);
		world.setBlock(i + 10, j + 19, k + 11, MysticModBlocks.mysticGlass.blockID);
		world.setBlock(i + 10, j + 19, k + 12, MysticModBlocks.mysticGlass.blockID);
		world.setBlock(i + 10, j + 19, k + 13, Block.stoneSingleSlab.blockID, 2,2);
		world.setBlock(i + 10, j + 19, k + 14, Block.stoneSingleSlab.blockID, 2,2);
		world.setBlock(i + 10, j + 19, k + 16, Block.stoneSingleSlab.blockID, 2,2);
		world.setBlock(i + 10, j + 20, k + 4, Block.stoneSingleSlab.blockID, 2,2);
		world.setBlock(i + 10, j + 20, k + 13, Block.stoneSingleSlab.blockID, 2,2);
		world.setBlock(i + 11, j + 0, k + 0, Block.stoneSingleSlab.blockID, 2,2);
		world.setBlock(i + 11, j + 0, k + 2, Block.stoneSingleSlab.blockID, 2,2);
		world.setBlock(i + 11, j + 0, k + 3, MysticModBlocks.Elevator.blockID);
		world.setBlock(i + 11, j + 0, k + 4, MysticModBlocks.Elevator.blockID);
		world.setBlock(i + 11, j + 0, k + 13, MysticModBlocks.Elevator.blockID);
		world.setBlock(i + 11, j + 0, k + 14, MysticModBlocks.Elevator.blockID);
		world.setBlock(i + 11, j + 0, k + 15, Block.stoneSingleSlab.blockID, 2,2);
		world.setBlock(i + 11, j + 0, k + 17, Block.stoneSingleSlab.blockID, 2,2);
		world.setBlock(i + 11, j + 1, k + 2, MysticModBlocks.Elevator.blockID);
		world.setBlock(i + 11, j + 1, k + 3, Block.waterStill.blockID);
		world.setBlock(i + 11, j + 1, k + 4, Block.waterStill.blockID);
		world.setBlock(i + 11, j + 1, k + 5, MysticModBlocks.Elevator.blockID);
		world.setBlock(i + 11, j + 1, k + 12, MysticModBlocks.Elevator.blockID);
		world.setBlock(i + 11, j + 1, k + 13, Block.waterStill.blockID);
		world.setBlock(i + 11, j + 1, k + 14, Block.waterStill.blockID);
		world.setBlock(i + 11, j + 1, k + 15, MysticModBlocks.Elevator.blockID);
		world.setBlock(i + 11, j + 2, k + 2, MysticModBlocks.Dropper.blockID);
		world.setBlock(i + 11, j + 2, k + 3, Block.waterStill.blockID);
		world.setBlock(i + 11, j + 2, k + 4, Block.waterStill.blockID);
		world.setBlock(i + 11, j + 2, k + 5, MysticModBlocks.Dropper.blockID);
		world.setBlock(i + 11, j + 2, k + 12, MysticModBlocks.Dropper.blockID);
		world.setBlock(i + 11, j + 2, k + 13, Block.waterStill.blockID);
		world.setBlock(i + 11, j + 2, k + 14, Block.waterStill.blockID);
		world.setBlock(i + 11, j + 2, k + 15, MysticModBlocks.Dropper.blockID);
		world.setBlock(i + 11, j + 3, k + 3, MysticModBlocks.Dropper.blockID);
		world.setBlock(i + 11, j + 3, k + 4, MysticModBlocks.Dropper.blockID);
		world.setBlock(i + 11, j + 3, k + 13, MysticModBlocks.Dropper.blockID);
		world.setBlock(i + 11, j + 3, k + 14, MysticModBlocks.Dropper.blockID);
		world.setBlock(i + 11, j + 18, k + 0, MysticModBlocks.mysticBricks.blockID);
		world.setBlock(i + 11, j + 18, k + 2, MysticModBlocks.mysticBricks.blockID);
		world.setBlock(i + 11, j + 18, k + 15, MysticModBlocks.mysticBricks.blockID);
		world.setBlock(i + 11, j + 18, k + 17, MysticModBlocks.mysticBricks.blockID);
		world.setBlock(i + 11, j + 19, k + 1, Block.stoneSingleSlab.blockID, 2,2);
		world.setBlock(i + 11, j + 19, k + 3, Block.stoneSingleSlab.blockID, 2,2);
		world.setBlock(i + 11, j + 19, k + 4, Block.stoneSingleSlab.blockID, 2,2);
		world.setBlock(i + 11, j + 19, k + 5, MysticModBlocks.mysticGlass.blockID);
		world.setBlock(i + 11, j + 19, k + 6, MysticModBlocks.mysticGlass.blockID);
		world.setBlock(i + 11, j + 19, k + 7, MysticModBlocks.mysticGlass.blockID);
		world.setBlock(i + 11, j + 19, k + 8, MysticModBlocks.mysticGlass.blockID);
		world.setBlock(i + 11, j + 19, k + 9, MysticModBlocks.mysticGlass.blockID);
		world.setBlock(i + 11, j + 19, k + 10, MysticModBlocks.mysticGlass.blockID);
		world.setBlock(i + 11, j + 19, k + 11, MysticModBlocks.mysticGlass.blockID);
		world.setBlock(i + 11, j + 19, k + 12, MysticModBlocks.mysticGlass.blockID);
		world.setBlock(i + 11, j + 19, k + 13, Block.stoneSingleSlab.blockID, 2,2);
		world.setBlock(i + 11, j + 19, k + 14, Block.stoneSingleSlab.blockID, 2,2);
		world.setBlock(i + 11, j + 19, k + 16, Block.stoneSingleSlab.blockID, 2,2);
		world.setBlock(i + 11, j + 20, k + 4, Block.stoneSingleSlab.blockID, 2,2);
		world.setBlock(i + 11, j + 20, k + 13, Block.stoneSingleSlab.blockID, 2,2);
		world.setBlock(i + 12, j + 0, k + 0, Block.stoneSingleSlab.blockID, 2,2);
		world.setBlock(i + 12, j + 0, k + 2, Block.stoneSingleSlab.blockID, 2,2);
		world.setBlock(i + 12, j + 0, k + 3, MysticModBlocks.Elevator.blockID);
		world.setBlock(i + 12, j + 0, k + 4, MysticModBlocks.Elevator.blockID);
		world.setBlock(i + 12, j + 0, k + 13, MysticModBlocks.Elevator.blockID);
		world.setBlock(i + 12, j + 0, k + 14, MysticModBlocks.Elevator.blockID);
		world.setBlock(i + 12, j + 0, k + 15, Block.stoneSingleSlab.blockID, 2,2);
		world.setBlock(i + 12, j + 0, k + 17, Block.stoneSingleSlab.blockID, 2,2);
		world.setBlock(i + 12, j + 1, k + 2, MysticModBlocks.Elevator.blockID);
		world.setBlock(i + 12, j + 1, k + 3, Block.waterStill.blockID);
		world.setBlock(i + 12, j + 1, k + 4, Block.waterStill.blockID);
		world.setBlock(i + 12, j + 1, k + 5, MysticModBlocks.Elevator.blockID);
		world.setBlock(i + 12, j + 1, k + 6, MysticModBlocks.Elevator.blockID);
		world.setBlock(i + 12, j + 1, k + 7, MysticModBlocks.Elevator.blockID);
		world.setBlock(i + 12, j + 1, k + 8, MysticModBlocks.Elevator.blockID);
		world.setBlock(i + 12, j + 1, k + 9, MysticModBlocks.Elevator.blockID);
		world.setBlock(i + 12, j + 1, k + 10, MysticModBlocks.Elevator.blockID);
		world.setBlock(i + 12, j + 1, k + 11, MysticModBlocks.Elevator.blockID);
		world.setBlock(i + 12, j + 1, k + 12, MysticModBlocks.Elevator.blockID);
		world.setBlock(i + 12, j + 1, k + 13, Block.waterStill.blockID);
		world.setBlock(i + 12, j + 1, k + 14, Block.waterStill.blockID);
		world.setBlock(i + 12, j + 1, k + 15, MysticModBlocks.Elevator.blockID);
		world.setBlock(i + 12, j + 2, k + 2, MysticModBlocks.Dropper.blockID);
		world.setBlock(i + 12, j + 2, k + 3, Block.waterStill.blockID);
		world.setBlock(i + 12, j + 2, k + 4, Block.waterStill.blockID);
		world.setBlock(i + 12, j + 2, k + 5, MysticModBlocks.Dropper.blockID);
		world.setBlock(i + 12, j + 2, k + 6, MysticModBlocks.Dropper.blockID);
		world.setBlock(i + 12, j + 2, k + 7, MysticModBlocks.Dropper.blockID);
		world.setBlock(i + 12, j + 2, k + 8, MysticModBlocks.Dropper.blockID);
		world.setBlock(i + 12, j + 2, k + 9, MysticModBlocks.Dropper.blockID);
		world.setBlock(i + 12, j + 2, k + 10, MysticModBlocks.Dropper.blockID);
		world.setBlock(i + 12, j + 2, k + 11, MysticModBlocks.Dropper.blockID);
		world.setBlock(i + 12, j + 2, k + 12, MysticModBlocks.Dropper.blockID);
		world.setBlock(i + 12, j + 2, k + 13, Block.waterStill.blockID);
		world.setBlock(i + 12, j + 2, k + 14, Block.waterStill.blockID);
		world.setBlock(i + 12, j + 2, k + 15, MysticModBlocks.Dropper.blockID);
		world.setBlock(i + 12, j + 3, k + 3, MysticModBlocks.Dropper.blockID);
		world.setBlock(i + 12, j + 3, k + 4, MysticModBlocks.Dropper.blockID);
		world.setBlock(i + 12, j + 3, k + 13, MysticModBlocks.Dropper.blockID);
		world.setBlock(i + 12, j + 3, k + 14, MysticModBlocks.Dropper.blockID);
		world.setBlock(i + 12, j + 18, k + 0, MysticModBlocks.mysticBricks.blockID);
		world.setBlock(i + 12, j + 18, k + 2, MysticModBlocks.mysticBricks.blockID);
		world.setBlock(i + 12, j + 18, k + 15, MysticModBlocks.mysticBricks.blockID);
		world.setBlock(i + 12, j + 18, k + 17, MysticModBlocks.mysticBricks.blockID);
		world.setBlock(i + 12, j + 19, k + 1, Block.stoneSingleSlab.blockID, 2,2);
		world.setBlock(i + 12, j + 19, k + 3, Block.stoneSingleSlab.blockID, 2,2);
		world.setBlock(i + 12, j + 19, k + 4, Block.stoneSingleSlab.blockID, 2,2);
		world.setBlock(i + 12, j + 19, k + 5, MysticModBlocks.mysticGlass.blockID);
		world.setBlock(i + 12, j + 19, k + 6, MysticModBlocks.mysticGlass.blockID);
		world.setBlock(i + 12, j + 19, k + 7, MysticModBlocks.mysticGlass.blockID);
		world.setBlock(i + 12, j + 19, k + 8, MysticModBlocks.mysticGlass.blockID);
		world.setBlock(i + 12, j + 19, k + 9, MysticModBlocks.mysticGlass.blockID);
		world.setBlock(i + 12, j + 19, k + 10, MysticModBlocks.mysticGlass.blockID);
		world.setBlock(i + 12, j + 19, k + 11, MysticModBlocks.mysticGlass.blockID);
		world.setBlock(i + 12, j + 19, k + 12, MysticModBlocks.mysticGlass.blockID);
		world.setBlock(i + 12, j + 19, k + 13, Block.stoneSingleSlab.blockID, 2,2);
		world.setBlock(i + 12, j + 19, k + 14, Block.stoneSingleSlab.blockID, 2,2);
		world.setBlock(i + 12, j + 19, k + 16, Block.stoneSingleSlab.blockID, 2,2);
		world.setBlock(i + 12, j + 20, k + 4, Block.stoneSingleSlab.blockID, 2,2);
		world.setBlock(i + 12, j + 20, k + 13, Block.stoneSingleSlab.blockID, 2,2);
		world.setBlock(i + 13, j + 0, k + 0, Block.stoneSingleSlab.blockID, 2,2);
		world.setBlock(i + 13, j + 0, k + 2, Block.stoneSingleSlab.blockID, 2,2);
		world.setBlock(i + 13, j + 0, k + 3, MysticModBlocks.Elevator.blockID);
		world.setBlock(i + 13, j + 0, k + 4, MysticModBlocks.Elevator.blockID);
		world.setBlock(i + 13, j + 0, k + 5, MysticModBlocks.Elevator.blockID);
		world.setBlock(i + 13, j + 0, k + 6, MysticModBlocks.Elevator.blockID);
		world.setBlock(i + 13, j + 0, k + 7, MysticModBlocks.Elevator.blockID);
		world.setBlock(i + 13, j + 0, k + 8, MysticModBlocks.Elevator.blockID);
		world.setBlock(i + 13, j + 0, k + 9, MysticModBlocks.Elevator.blockID);
		world.setBlock(i + 13, j + 0, k + 10, MysticModBlocks.Elevator.blockID);
		world.setBlock(i + 13, j + 0, k + 11, MysticModBlocks.Elevator.blockID);
		world.setBlock(i + 13, j + 0, k + 12, MysticModBlocks.Elevator.blockID);
		world.setBlock(i + 13, j + 0, k + 13, MysticModBlocks.Elevator.blockID);
		world.setBlock(i + 13, j + 0, k + 14, MysticModBlocks.Elevator.blockID);
		world.setBlock(i + 13, j + 0, k + 15, Block.stoneSingleSlab.blockID, 2,2);
		world.setBlock(i + 13, j + 0, k + 17, Block.stoneSingleSlab.blockID, 2,2);
		world.setBlock(i + 13, j + 1, k + 2, MysticModBlocks.Elevator.blockID);
		world.setBlock(i + 13, j + 1, k + 3, Block.waterStill.blockID);
		world.setBlock(i + 13, j + 1, k + 4, Block.waterStill.blockID);
		world.setBlock(i + 13, j + 1, k + 5, Block.waterStill.blockID);
		world.setBlock(i + 13, j + 1, k + 6, Block.waterStill.blockID);
		world.setBlock(i + 13, j + 1, k + 7, Block.waterStill.blockID);
		world.setBlock(i + 13, j + 1, k + 8, Block.waterStill.blockID);
		world.setBlock(i + 13, j + 1, k + 9, Block.waterStill.blockID);
		world.setBlock(i + 13, j + 1, k + 10, Block.waterStill.blockID);
		world.setBlock(i + 13, j + 1, k + 11, Block.waterStill.blockID);
		world.setBlock(i + 13, j + 1, k + 12, Block.waterStill.blockID);
		world.setBlock(i + 13, j + 1, k + 13, Block.waterStill.blockID);
		world.setBlock(i + 13, j + 1, k + 14, Block.waterStill.blockID);
		world.setBlock(i + 13, j + 1, k + 15, MysticModBlocks.Elevator.blockID);
		world.setBlock(i + 13, j + 2, k + 2, MysticModBlocks.Dropper.blockID);
		world.setBlock(i + 13, j + 2, k + 3, Block.waterStill.blockID);
		world.setBlock(i + 13, j + 2, k + 4, Block.waterStill.blockID);
		world.setBlock(i + 13, j + 2, k + 5, Block.waterStill.blockID);
		world.setBlock(i + 13, j + 2, k + 6, Block.waterStill.blockID);
		world.setBlock(i + 13, j + 2, k + 7, Block.waterStill.blockID);
		world.setBlock(i + 13, j + 2, k + 8, Block.waterStill.blockID);
		world.setBlock(i + 13, j + 2, k + 9, Block.waterStill.blockID);
		world.setBlock(i + 13, j + 2, k + 10, Block.waterStill.blockID);
		world.setBlock(i + 13, j + 2, k + 11, Block.waterStill.blockID);
		world.setBlock(i + 13, j + 2, k + 12, Block.waterStill.blockID);
		world.setBlock(i + 13, j + 2, k + 13, Block.waterStill.blockID);
		world.setBlock(i + 13, j + 2, k + 14, Block.waterStill.blockID);
		world.setBlock(i + 13, j + 2, k + 15, MysticModBlocks.Dropper.blockID);
		world.setBlock(i + 13, j + 3, k + 3, MysticModBlocks.Dropper.blockID);
		world.setBlock(i + 13, j + 3, k + 4, MysticModBlocks.Dropper.blockID);
		world.setBlock(i + 13, j + 3, k + 5, MysticModBlocks.Dropper.blockID);
		world.setBlock(i + 13, j + 3, k + 6, MysticModBlocks.Dropper.blockID);
		world.setBlock(i + 13, j + 3, k + 7, MysticModBlocks.Dropper.blockID);
		world.setBlock(i + 13, j + 3, k + 8, MysticModBlocks.Dropper.blockID);
		world.setBlock(i + 13, j + 3, k + 9, MysticModBlocks.Dropper.blockID);
		world.setBlock(i + 13, j + 3, k + 10, MysticModBlocks.Dropper.blockID);
		world.setBlock(i + 13, j + 3, k + 11, MysticModBlocks.Dropper.blockID);
		world.setBlock(i + 13, j + 3, k + 12, MysticModBlocks.Dropper.blockID);
		world.setBlock(i + 13, j + 3, k + 13, MysticModBlocks.Dropper.blockID);
		world.setBlock(i + 13, j + 3, k + 14, MysticModBlocks.Dropper.blockID);
		world.setBlock(i + 13, j + 18, k + 0, MysticModBlocks.mysticBricks.blockID);
		world.setBlock(i + 13, j + 18, k + 2, MysticModBlocks.mysticBricks.blockID);
		world.setBlock(i + 13, j + 18, k + 15, MysticModBlocks.mysticBricks.blockID);
		world.setBlock(i + 13, j + 18, k + 17, MysticModBlocks.mysticBricks.blockID);
		world.setBlock(i + 13, j + 19, k + 1, Block.stoneSingleSlab.blockID, 2,2);
		world.setBlock(i + 13, j + 19, k + 3, Block.stoneSingleSlab.blockID, 2,2);
		world.setBlock(i + 13, j + 19, k + 4, Block.stoneSingleSlab.blockID, 2,2);
		world.setBlock(i + 13, j + 19, k + 5, MysticModBlocks.mysticGlass.blockID);
		world.setBlock(i + 13, j + 19, k + 6, MysticModBlocks.mysticGlass.blockID);
		world.setBlock(i + 13, j + 19, k + 7, MysticModBlocks.mysticGlass.blockID);
		world.setBlock(i + 13, j + 19, k + 8, MysticModBlocks.mysticGlass.blockID);
		world.setBlock(i + 13, j + 19, k + 9, MysticModBlocks.mysticGlass.blockID);
		world.setBlock(i + 13, j + 19, k + 10, MysticModBlocks.mysticGlass.blockID);
		world.setBlock(i + 13, j + 19, k + 11, MysticModBlocks.mysticGlass.blockID);
		world.setBlock(i + 13, j + 19, k + 12, MysticModBlocks.mysticGlass.blockID);
		world.setBlock(i + 13, j + 19, k + 13, Block.stoneSingleSlab.blockID, 2,2);
		world.setBlock(i + 13, j + 19, k + 14, Block.stoneSingleSlab.blockID, 2,2);
		world.setBlock(i + 13, j + 19, k + 16, Block.stoneSingleSlab.blockID, 2,2);
		world.setBlock(i + 13, j + 20, k + 4, Block.stoneSingleSlab.blockID, 2,2);
		world.setBlock(i + 13, j + 20, k + 13, Block.stoneSingleSlab.blockID, 2,2);
		world.setBlock(i + 14, j + 0, k + 0, Block.stoneSingleSlab.blockID, 2,2);
		world.setBlock(i + 14, j + 0, k + 2, Block.stoneSingleSlab.blockID, 2,2);
		world.setBlock(i + 14, j + 0, k + 3, MysticModBlocks.Elevator.blockID);
		world.setBlock(i + 14, j + 0, k + 4, MysticModBlocks.Elevator.blockID);
		world.setBlock(i + 14, j + 0, k + 5, MysticModBlocks.Elevator.blockID);
		world.setBlock(i + 14, j + 0, k + 6, MysticModBlocks.Elevator.blockID);
		world.setBlock(i + 14, j + 0, k + 7, MysticModBlocks.Elevator.blockID);
		world.setBlock(i + 14, j + 0, k + 8, MysticModBlocks.Elevator.blockID);
		world.setBlock(i + 14, j + 0, k + 9, MysticModBlocks.Elevator.blockID);
		world.setBlock(i + 14, j + 0, k + 10, MysticModBlocks.Elevator.blockID);
		world.setBlock(i + 14, j + 0, k + 11, MysticModBlocks.Elevator.blockID);
		world.setBlock(i + 14, j + 0, k + 12, MysticModBlocks.Elevator.blockID);
		world.setBlock(i + 14, j + 0, k + 13, MysticModBlocks.Elevator.blockID);
		world.setBlock(i + 14, j + 0, k + 14, MysticModBlocks.Elevator.blockID);
		world.setBlock(i + 14, j + 0, k + 15, Block.stoneSingleSlab.blockID, 2,2);
		world.setBlock(i + 14, j + 0, k + 17, Block.stoneSingleSlab.blockID, 2,2);
		world.setBlock(i + 14, j + 1, k + 2, MysticModBlocks.Elevator.blockID);
		world.setBlock(i + 14, j + 1, k + 3, Block.waterStill.blockID);
		world.setBlock(i + 14, j + 1, k + 4, Block.waterStill.blockID);
		world.setBlock(i + 14, j + 1, k + 5, Block.waterStill.blockID);
		world.setBlock(i + 14, j + 1, k + 6, Block.waterStill.blockID);
		world.setBlock(i + 14, j + 1, k + 7, Block.waterStill.blockID);
		world.setBlock(i + 14, j + 1, k + 8, Block.waterStill.blockID);
		world.setBlock(i + 14, j + 1, k + 9, Block.waterStill.blockID);
		world.setBlock(i + 14, j + 1, k + 10, Block.waterStill.blockID);
		world.setBlock(i + 14, j + 1, k + 11, Block.waterStill.blockID);
		world.setBlock(i + 14, j + 1, k + 12, Block.waterStill.blockID);
		world.setBlock(i + 14, j + 1, k + 13, Block.waterStill.blockID);
		world.setBlock(i + 14, j + 1, k + 14, Block.waterStill.blockID);
		world.setBlock(i + 14, j + 1, k + 15, MysticModBlocks.Elevator.blockID);
		world.setBlock(i + 14, j + 2, k + 2, MysticModBlocks.Dropper.blockID);
		world.setBlock(i + 14, j + 2, k + 3, Block.waterStill.blockID);
		world.setBlock(i + 14, j + 2, k + 4, Block.waterStill.blockID);
		world.setBlock(i + 14, j + 2, k + 5, Block.waterStill.blockID);
		world.setBlock(i + 14, j + 2, k + 6, Block.waterStill.blockID);
		world.setBlock(i + 14, j + 2, k + 7, Block.waterStill.blockID);
		world.setBlock(i + 14, j + 2, k + 8, Block.waterStill.blockID);
		world.setBlock(i + 14, j + 2, k + 9, Block.waterStill.blockID);
		world.setBlock(i + 14, j + 2, k + 10, Block.waterStill.blockID);
		world.setBlock(i + 14, j + 2, k + 11, Block.waterStill.blockID);
		world.setBlock(i + 14, j + 2, k + 12, Block.waterStill.blockID);
		world.setBlock(i + 14, j + 2, k + 13, Block.waterStill.blockID);
		world.setBlock(i + 14, j + 2, k + 14, Block.waterStill.blockID);
		world.setBlock(i + 14, j + 2, k + 15, MysticModBlocks.Dropper.blockID);
		world.setBlock(i + 14, j + 3, k + 3, MysticModBlocks.Dropper.blockID);
		world.setBlock(i + 14, j + 3, k + 4, MysticModBlocks.Dropper.blockID);
		world.setBlock(i + 14, j + 3, k + 5, MysticModBlocks.Dropper.blockID);
		world.setBlock(i + 14, j + 3, k + 6, MysticModBlocks.Dropper.blockID);
		world.setBlock(i + 14, j + 3, k + 7, MysticModBlocks.Dropper.blockID);
		world.setBlock(i + 14, j + 3, k + 8, MysticModBlocks.Dropper.blockID);
		world.setBlock(i + 14, j + 3, k + 9, MysticModBlocks.Dropper.blockID);
		world.setBlock(i + 14, j + 3, k + 10, MysticModBlocks.Dropper.blockID);
		world.setBlock(i + 14, j + 3, k + 11, MysticModBlocks.Dropper.blockID);
		world.setBlock(i + 14, j + 3, k + 12, MysticModBlocks.Dropper.blockID);
		world.setBlock(i + 14, j + 3, k + 13, MysticModBlocks.Dropper.blockID);
		world.setBlock(i + 14, j + 3, k + 14, MysticModBlocks.Dropper.blockID);
		world.setBlock(i + 14, j + 18, k + 0, MysticModBlocks.mysticBricks.blockID);
		world.setBlock(i + 14, j + 18, k + 2, MysticModBlocks.mysticBricks.blockID);
		world.setBlock(i + 14, j + 18, k + 15, MysticModBlocks.mysticBricks.blockID);
		world.setBlock(i + 14, j + 18, k + 17, MysticModBlocks.mysticBricks.blockID);
		world.setBlock(i + 14, j + 19, k + 1, Block.stoneSingleSlab.blockID, 2,2);
		world.setBlock(i + 14, j + 19, k + 3, Block.stoneSingleSlab.blockID, 2,2);
		world.setBlock(i + 14, j + 19, k + 4, Block.stoneSingleSlab.blockID, 2,2);
		world.setBlock(i + 14, j + 19, k + 5, Block.stoneSingleSlab.blockID, 2,2);
		world.setBlock(i + 14, j + 19, k + 6, Block.stoneSingleSlab.blockID, 2,2);
		world.setBlock(i + 14, j + 19, k + 7, Block.stoneSingleSlab.blockID, 2,2);
		world.setBlock(i + 14, j + 19, k + 8, Block.stoneSingleSlab.blockID, 2,2);
		world.setBlock(i + 14, j + 19, k + 9, Block.stoneSingleSlab.blockID, 2,2);
		world.setBlock(i + 14, j + 19, k + 10, Block.stoneSingleSlab.blockID, 2,2);
		world.setBlock(i + 14, j + 19, k + 11, Block.stoneSingleSlab.blockID, 2,2);
		world.setBlock(i + 14, j + 19, k + 12, Block.stoneSingleSlab.blockID, 2,2);
		world.setBlock(i + 14, j + 19, k + 13, Block.stoneSingleSlab.blockID, 2,2);
		world.setBlock(i + 14, j + 19, k + 14, Block.stoneSingleSlab.blockID, 2,2);
		world.setBlock(i + 14, j + 19, k + 16, Block.stoneSingleSlab.blockID, 2,2);
		world.setBlock(i + 14, j + 20, k + 4, Block.stoneSingleSlab.blockID, 2,2);
		world.setBlock(i + 14, j + 20, k + 5, Block.stoneSingleSlab.blockID, 2,2);
		world.setBlock(i + 14, j + 20, k + 6, Block.stoneSingleSlab.blockID, 2,2);
		world.setBlock(i + 14, j + 20, k + 7, Block.stoneSingleSlab.blockID, 2,2);
		world.setBlock(i + 14, j + 20, k + 8, Block.stoneSingleSlab.blockID, 2,2);
		world.setBlock(i + 14, j + 20, k + 9, Block.stoneSingleSlab.blockID, 2,2);
		world.setBlock(i + 14, j + 20, k + 10, Block.stoneSingleSlab.blockID, 2,2);
		world.setBlock(i + 14, j + 20, k + 11, Block.stoneSingleSlab.blockID, 2,2);
		world.setBlock(i + 14, j + 20, k + 12, Block.stoneSingleSlab.blockID, 2,2);
		world.setBlock(i + 14, j + 20, k + 13, Block.stoneSingleSlab.blockID, 2,2);
		world.setBlock(i + 15, j + 0, k + 0, Block.stoneSingleSlab.blockID, 2,2);
		world.setBlock(i + 15, j + 0, k + 2, Block.stoneSingleSlab.blockID, 2,2);
		world.setBlock(i + 15, j + 0, k + 3, Block.stoneSingleSlab.blockID, 2,2);
		world.setBlock(i + 15, j + 0, k + 4, Block.stoneSingleSlab.blockID, 2,2);
		world.setBlock(i + 15, j + 0, k + 5, Block.stoneSingleSlab.blockID, 2,2);
		world.setBlock(i + 15, j + 0, k + 6, Block.stoneSingleSlab.blockID, 2,2);
		world.setBlock(i + 15, j + 0, k + 7, Block.stoneSingleSlab.blockID, 2,2);
		world.setBlock(i + 15, j + 0, k + 8, Block.stoneSingleSlab.blockID, 2,2);
		world.setBlock(i + 15, j + 0, k + 9, Block.stoneSingleSlab.blockID, 2,2);
		world.setBlock(i + 15, j + 0, k + 10, Block.stoneSingleSlab.blockID, 2,2);
		world.setBlock(i + 15, j + 0, k + 11, Block.stoneSingleSlab.blockID, 2,2);
		world.setBlock(i + 15, j + 0, k + 12, Block.stoneSingleSlab.blockID, 2,2);
		world.setBlock(i + 15, j + 0, k + 13, Block.stoneSingleSlab.blockID, 2,2);
		world.setBlock(i + 15, j + 0, k + 14, Block.stoneSingleSlab.blockID, 2,2);
		world.setBlock(i + 15, j + 0, k + 15, Block.stoneSingleSlab.blockID, 2,2);
		world.setBlock(i + 15, j + 0, k + 17, Block.stoneSingleSlab.blockID, 2,2);
		world.setBlock(i + 15, j + 1, k + 2, MysticModBlocks.Elevator.blockID);
		world.setBlock(i + 15, j + 1, k + 3, MysticModBlocks.Elevator.blockID);
		world.setBlock(i + 15, j + 1, k + 4, MysticModBlocks.Elevator.blockID);
		world.setBlock(i + 15, j + 1, k + 5, MysticModBlocks.Elevator.blockID);
		world.setBlock(i + 15, j + 1, k + 6, MysticModBlocks.Elevator.blockID);
		world.setBlock(i + 15, j + 1, k + 7, MysticModBlocks.Elevator.blockID);
		world.setBlock(i + 15, j + 1, k + 8, MysticModBlocks.Elevator.blockID);
		world.setBlock(i + 15, j + 1, k + 9, MysticModBlocks.Elevator.blockID);
		world.setBlock(i + 15, j + 1, k + 10, MysticModBlocks.Elevator.blockID);
		world.setBlock(i + 15, j + 1, k + 11, MysticModBlocks.Elevator.blockID);
		world.setBlock(i + 15, j + 1, k + 12, MysticModBlocks.Elevator.blockID);
		world.setBlock(i + 15, j + 1, k + 13, MysticModBlocks.Elevator.blockID);
		world.setBlock(i + 15, j + 1, k + 14, MysticModBlocks.Elevator.blockID);
		world.setBlock(i + 15, j + 1, k + 15, MysticModBlocks.Elevator.blockID);
		world.setBlock(i + 15, j + 2, k + 2, MysticModBlocks.Dropper.blockID);
		world.setBlock(i + 15, j + 2, k + 3, MysticModBlocks.Dropper.blockID);
		world.setBlock(i + 15, j + 2, k + 4, MysticModBlocks.Dropper.blockID);
		world.setBlock(i + 15, j + 2, k + 5, MysticModBlocks.Dropper.blockID);
		world.setBlock(i + 15, j + 2, k + 6, MysticModBlocks.Dropper.blockID);
		world.setBlock(i + 15, j + 2, k + 7, MysticModBlocks.Dropper.blockID);
		world.setBlock(i + 15, j + 2, k + 8, MysticModBlocks.Dropper.blockID);
		world.setBlock(i + 15, j + 2, k + 9, MysticModBlocks.Dropper.blockID);
		world.setBlock(i + 15, j + 2, k + 10, MysticModBlocks.Dropper.blockID);
		world.setBlock(i + 15, j + 2, k + 11, MysticModBlocks.Dropper.blockID);
		world.setBlock(i + 15, j + 2, k + 12, MysticModBlocks.Dropper.blockID);
		world.setBlock(i + 15, j + 2, k + 13, MysticModBlocks.Dropper.blockID);
		world.setBlock(i + 15, j + 2, k + 14, MysticModBlocks.Dropper.blockID);
		world.setBlock(i + 15, j + 2, k + 15, MysticModBlocks.Dropper.blockID);
		world.setBlock(i + 15, j + 18, k + 0, MysticModBlocks.mysticBricks.blockID);
		world.setBlock(i + 15, j + 18, k + 2, MysticModBlocks.mysticBricks.blockID);
		world.setBlock(i + 15, j + 18, k + 3, MysticModBlocks.mysticBricks.blockID);
		world.setBlock(i + 15, j + 18, k + 4, MysticModBlocks.mysticBricks.blockID);
		world.setBlock(i + 15, j + 18, k + 5, MysticModBlocks.mysticBricks.blockID);
		world.setBlock(i + 15, j + 18, k + 6, MysticModBlocks.mysticBricks.blockID);
		world.setBlock(i + 15, j + 18, k + 7, MysticModBlocks.mysticBricks.blockID);
		world.setBlock(i + 15, j + 18, k + 8, MysticModBlocks.mysticBricks.blockID);
		world.setBlock(i + 15, j + 18, k + 9, MysticModBlocks.mysticBricks.blockID);
		world.setBlock(i + 15, j + 18, k + 10, MysticModBlocks.mysticBricks.blockID);
		world.setBlock(i + 15, j + 18, k + 11, MysticModBlocks.mysticBricks.blockID);
		world.setBlock(i + 15, j + 18, k + 12, MysticModBlocks.mysticBricks.blockID);
		world.setBlock(i + 15, j + 18, k + 13, MysticModBlocks.mysticBricks.blockID);
		world.setBlock(i + 15, j + 18, k + 14, MysticModBlocks.mysticBricks.blockID);
		world.setBlock(i + 15, j + 18, k + 15, MysticModBlocks.mysticBricks.blockID);
		world.setBlock(i + 15, j + 18, k + 17, MysticModBlocks.mysticBricks.blockID);
		world.setBlock(i + 15, j + 19, k + 1, Block.stoneSingleSlab.blockID, 2,2);
		world.setBlock(i + 15, j + 19, k + 16, Block.stoneSingleSlab.blockID, 2,2);
		world.setBlock(i + 16, j + 0, k + 0, Block.stoneSingleSlab.blockID, 2,2);
		world.setBlock(i + 16, j + 0, k + 17, Block.stoneSingleSlab.blockID, 2,2);
		world.setBlock(i + 16, j + 18, k + 0, MysticModBlocks.mysticBricks.blockID);
		world.setBlock(i + 16, j + 18, k + 17, MysticModBlocks.mysticBricks.blockID);
		world.setBlock(i + 16, j + 19, k + 1, Block.stoneSingleSlab.blockID, 2,2);
		world.setBlock(i + 16, j + 19, k + 2, Block.stoneSingleSlab.blockID, 2,2);
		world.setBlock(i + 16, j + 19, k + 3, Block.stoneSingleSlab.blockID, 2,2);
		world.setBlock(i + 16, j + 19, k + 4, Block.stoneSingleSlab.blockID, 2,2);
		world.setBlock(i + 16, j + 19, k + 5, Block.stoneSingleSlab.blockID, 2,2);
		world.setBlock(i + 16, j + 19, k + 6, Block.stoneSingleSlab.blockID, 2,2);
		world.setBlock(i + 16, j + 19, k + 7, Block.stoneSingleSlab.blockID, 2,2);
		world.setBlock(i + 16, j + 19, k + 8, Block.stoneSingleSlab.blockID, 2,2);
		world.setBlock(i + 16, j + 19, k + 9, Block.stoneSingleSlab.blockID, 2,2);
		world.setBlock(i + 16, j + 19, k + 10, Block.stoneSingleSlab.blockID, 2,2);
		world.setBlock(i + 16, j + 19, k + 11, Block.stoneSingleSlab.blockID, 2,2);
		world.setBlock(i + 16, j + 19, k + 12, Block.stoneSingleSlab.blockID, 2,2);
		world.setBlock(i + 16, j + 19, k + 13, Block.stoneSingleSlab.blockID, 2,2);
		world.setBlock(i + 16, j + 19, k + 14, Block.stoneSingleSlab.blockID, 2,2);
		world.setBlock(i + 16, j + 19, k + 15, Block.stoneSingleSlab.blockID, 2,2);
		world.setBlock(i + 16, j + 19, k + 16, Block.stoneSingleSlab.blockID, 2,2);
		world.setBlock(i + 17, j + 0, k + 0, Block.stoneSingleSlab.blockID, 2,2);
		world.setBlock(i + 17, j + 0, k + 1, Block.stoneSingleSlab.blockID, 2,2);
		world.setBlock(i + 17, j + 0, k + 2, Block.stoneSingleSlab.blockID, 2,2);
		world.setBlock(i + 17, j + 0, k + 3, Block.stoneSingleSlab.blockID, 2,2);
		world.setBlock(i + 17, j + 0, k + 4, Block.stoneSingleSlab.blockID, 2,2);
		world.setBlock(i + 17, j + 0, k + 5, Block.stoneSingleSlab.blockID, 2,2);
		world.setBlock(i + 17, j + 0, k + 6, Block.stoneSingleSlab.blockID, 2,2);
		world.setBlock(i + 17, j + 0, k + 7, Block.stoneSingleSlab.blockID, 2,2);
		world.setBlock(i + 17, j + 0, k + 8, Block.stoneSingleSlab.blockID, 2,2);
		world.setBlock(i + 17, j + 0, k + 9, Block.stoneSingleSlab.blockID, 2,2);
		world.setBlock(i + 17, j + 0, k + 10, Block.stoneSingleSlab.blockID, 2,2);
		world.setBlock(i + 17, j + 0, k + 11, Block.stoneSingleSlab.blockID, 2,2);
		world.setBlock(i + 17, j + 0, k + 12, Block.stoneSingleSlab.blockID, 2,2);
		world.setBlock(i + 17, j + 0, k + 13, Block.stoneSingleSlab.blockID, 2,2);
		world.setBlock(i + 17, j + 0, k + 14, Block.stoneSingleSlab.blockID, 2,2);
		world.setBlock(i + 17, j + 0, k + 15, Block.stoneSingleSlab.blockID, 2,2);
		world.setBlock(i + 17, j + 0, k + 16, Block.stoneSingleSlab.blockID, 2,2);
		world.setBlock(i + 17, j + 0, k + 17, Block.stoneSingleSlab.blockID, 2,2);
		world.setBlock(i + 17, j + 18, k + 0, MysticModBlocks.mysticBricks.blockID);
		world.setBlock(i + 17, j + 18, k + 1, MysticModBlocks.mysticBricks.blockID);
		world.setBlock(i + 17, j + 18, k + 2, MysticModBlocks.mysticBricks.blockID);
		world.setBlock(i + 17, j + 18, k + 3, MysticModBlocks.mysticBricks.blockID);
		world.setBlock(i + 17, j + 18, k + 4, MysticModBlocks.mysticBricks.blockID);
		world.setBlock(i + 17, j + 18, k + 5, MysticModBlocks.mysticBricks.blockID);
		world.setBlock(i + 17, j + 18, k + 6, MysticModBlocks.mysticBricks.blockID);
		world.setBlock(i + 17, j + 18, k + 7, MysticModBlocks.mysticBricks.blockID);
		world.setBlock(i + 17, j + 18, k + 8, MysticModBlocks.mysticBricks.blockID);
		world.setBlock(i + 17, j + 18, k + 9, MysticModBlocks.mysticBricks.blockID);
		world.setBlock(i + 17, j + 18, k + 10, MysticModBlocks.mysticBricks.blockID);
		world.setBlock(i + 17, j + 18, k + 11, MysticModBlocks.mysticBricks.blockID);
		world.setBlock(i + 17, j + 18, k + 12, MysticModBlocks.mysticBricks.blockID);
		world.setBlock(i + 17, j + 18, k + 13, MysticModBlocks.mysticBricks.blockID);
		world.setBlock(i + 17, j + 18, k + 14, MysticModBlocks.mysticBricks.blockID);
		world.setBlock(i + 17, j + 18, k + 15, MysticModBlocks.mysticBricks.blockID);
		world.setBlock(i + 17, j + 18, k + 16, MysticModBlocks.mysticBricks.blockID);
		world.setBlock(i + 17, j + 18, k + 17, MysticModBlocks.mysticBricks.blockID);
		world.setBlock(i + 1, j + 0, k + 1, Block.waterStill.blockID, 8,2);
		world.setBlock(i + 1, j + 0, k + 2, Block.waterStill.blockID, 8,2);
		world.setBlock(i + 1, j + 0, k + 3, Block.waterStill.blockID, 8,2);
		world.setBlock(i + 1, j + 0, k + 4, Block.waterStill.blockID, 8,2);
		world.setBlock(i + 1, j + 0, k + 5, Block.waterStill.blockID, 8,2);
		world.setBlock(i + 1, j + 0, k + 6, Block.waterStill.blockID, 8,2);
		world.setBlock(i + 1, j + 0, k + 7, Block.waterStill.blockID, 8,2);
		world.setBlock(i + 1, j + 0, k + 8, Block.waterStill.blockID, 8,2);
		world.setBlock(i + 1, j + 0, k + 9, Block.waterStill.blockID, 8,2);
		world.setBlock(i + 1, j + 0, k + 10, Block.waterStill.blockID, 8,2);
		world.setBlock(i + 1, j + 0, k + 11, Block.waterStill.blockID, 8,2);
		world.setBlock(i + 1, j + 0, k + 12, Block.waterStill.blockID, 8,2);
		world.setBlock(i + 1, j + 0, k + 13, Block.waterStill.blockID, 8,2);
		world.setBlock(i + 1, j + 0, k + 14, Block.waterStill.blockID, 8,2);
		world.setBlock(i + 1, j + 0, k + 15, Block.waterStill.blockID, 8,2);
		world.setBlock(i + 1, j + 0, k + 16, Block.waterStill.blockID, 8,2);
		world.setBlock(i + 1, j + 1, k + 1, Block.waterStill.blockID, 8,2);
		world.setBlock(i + 1, j + 1, k + 2, Block.waterStill.blockID, 8,2);
		world.setBlock(i + 1, j + 1, k + 3, Block.waterStill.blockID, 8,2);
		world.setBlock(i + 1, j + 1, k + 4, Block.waterStill.blockID, 8,2);
		world.setBlock(i + 1, j + 1, k + 5, Block.waterStill.blockID, 8,2);
		world.setBlock(i + 1, j + 1, k + 6, Block.waterStill.blockID, 8,2);
		world.setBlock(i + 1, j + 1, k + 7, Block.waterStill.blockID, 8,2);
		world.setBlock(i + 1, j + 1, k + 8, Block.waterStill.blockID, 8,2);
		world.setBlock(i + 1, j + 1, k + 9, Block.waterStill.blockID, 8,2);
		world.setBlock(i + 1, j + 1, k + 10, Block.waterStill.blockID, 8,2);
		world.setBlock(i + 1, j + 1, k + 11, Block.waterStill.blockID, 8,2);
		world.setBlock(i + 1, j + 1, k + 12, Block.waterStill.blockID, 8,2);
		world.setBlock(i + 1, j + 1, k + 13, Block.waterStill.blockID, 8,2);
		world.setBlock(i + 1, j + 1, k + 14, Block.waterStill.blockID, 8,2);
		world.setBlock(i + 1, j + 1, k + 15, Block.waterStill.blockID, 8,2);
		world.setBlock(i + 1, j + 1, k + 16, Block.waterStill.blockID, 8,2);
		world.setBlock(i + 1, j + 2, k + 1, Block.waterStill.blockID, 8,2);
		world.setBlock(i + 1, j + 2, k + 2, Block.waterStill.blockID, 8,2);
		world.setBlock(i + 1, j + 2, k + 3, Block.waterStill.blockID, 8,2);
		world.setBlock(i + 1, j + 2, k + 4, Block.waterStill.blockID, 8,2);
		world.setBlock(i + 1, j + 2, k + 5, Block.waterStill.blockID, 8,2);
		world.setBlock(i + 1, j + 2, k + 6, Block.waterStill.blockID, 8,2);
		world.setBlock(i + 1, j + 2, k + 7, Block.waterStill.blockID, 8,2);
		world.setBlock(i + 1, j + 2, k + 8, Block.waterStill.blockID, 8,2);
		world.setBlock(i + 1, j + 2, k + 9, Block.waterStill.blockID, 8,2);
		world.setBlock(i + 1, j + 2, k + 10, Block.waterStill.blockID, 8,2);
		world.setBlock(i + 1, j + 2, k + 11, Block.waterStill.blockID, 8,2);
		world.setBlock(i + 1, j + 2, k + 12, Block.waterStill.blockID, 8,2);
		world.setBlock(i + 1, j + 2, k + 13, Block.waterStill.blockID, 8,2);
		world.setBlock(i + 1, j + 2, k + 14, Block.waterStill.blockID, 8,2);
		world.setBlock(i + 1, j + 2, k + 15, Block.waterStill.blockID, 8,2);
		world.setBlock(i + 1, j + 2, k + 16, Block.waterStill.blockID, 8,2);
		world.setBlock(i + 1, j + 3, k + 1, Block.waterStill.blockID, 8,2);
		world.setBlock(i + 1, j + 3, k + 2, Block.waterStill.blockID, 8,2);
		world.setBlock(i + 1, j + 3, k + 3, Block.waterStill.blockID, 8,2);
		world.setBlock(i + 1, j + 3, k + 4, Block.waterStill.blockID, 8,2);
		world.setBlock(i + 1, j + 3, k + 5, Block.waterStill.blockID, 8,2);
		world.setBlock(i + 1, j + 3, k + 6, Block.waterStill.blockID, 8,2);
		world.setBlock(i + 1, j + 3, k + 7, Block.waterStill.blockID, 8,2);
		world.setBlock(i + 1, j + 3, k + 8, Block.waterStill.blockID, 8,2);
		world.setBlock(i + 1, j + 3, k + 9, Block.waterStill.blockID, 8,2);
		world.setBlock(i + 1, j + 3, k + 10, Block.waterStill.blockID, 8,2);
		world.setBlock(i + 1, j + 3, k + 11, Block.waterStill.blockID, 8,2);
		world.setBlock(i + 1, j + 3, k + 12, Block.waterStill.blockID, 8,2);
		world.setBlock(i + 1, j + 3, k + 13, Block.waterStill.blockID, 8,2);
		world.setBlock(i + 1, j + 3, k + 14, Block.waterStill.blockID, 8,2);
		world.setBlock(i + 1, j + 3, k + 15, Block.waterStill.blockID, 8,2);
		world.setBlock(i + 1, j + 3, k + 16, Block.waterStill.blockID, 8,2);
		world.setBlock(i + 1, j + 4, k + 1, Block.waterStill.blockID, 8,2);
		world.setBlock(i + 1, j + 4, k + 2, Block.waterStill.blockID, 8,2);
		world.setBlock(i + 1, j + 4, k + 3, Block.waterStill.blockID, 8,2);
		world.setBlock(i + 1, j + 4, k + 4, Block.waterStill.blockID, 8,2);
		world.setBlock(i + 1, j + 4, k + 5, Block.waterStill.blockID, 8,2);
		world.setBlock(i + 1, j + 4, k + 6, Block.waterStill.blockID, 8,2);
		world.setBlock(i + 1, j + 4, k + 7, Block.waterStill.blockID, 8,2);
		world.setBlock(i + 1, j + 4, k + 8, Block.waterStill.blockID, 8,2);
		world.setBlock(i + 1, j + 4, k + 9, Block.waterStill.blockID, 8,2);
		world.setBlock(i + 1, j + 4, k + 10, Block.waterStill.blockID, 8,2);
		world.setBlock(i + 1, j + 4, k + 11, Block.waterStill.blockID, 8,2);
		world.setBlock(i + 1, j + 4, k + 12, Block.waterStill.blockID, 8,2);
		world.setBlock(i + 1, j + 4, k + 13, Block.waterStill.blockID, 8,2);
		world.setBlock(i + 1, j + 4, k + 14, Block.waterStill.blockID, 8,2);
		world.setBlock(i + 1, j + 4, k + 15, Block.waterStill.blockID, 8,2);
		world.setBlock(i + 1, j + 4, k + 16, Block.waterStill.blockID, 8,2);
		world.setBlock(i + 1, j + 5, k + 1, Block.waterStill.blockID, 8,2);
		world.setBlock(i + 1, j + 5, k + 2, Block.waterStill.blockID, 8,2);
		world.setBlock(i + 1, j + 5, k + 3, Block.waterStill.blockID, 8,2);
		world.setBlock(i + 1, j + 5, k + 4, Block.waterStill.blockID, 8,2);
		world.setBlock(i + 1, j + 5, k + 5, Block.waterStill.blockID, 8,2);
		world.setBlock(i + 1, j + 5, k + 6, Block.waterStill.blockID, 8,2);
		world.setBlock(i + 1, j + 5, k + 7, Block.waterStill.blockID, 8,2);
		world.setBlock(i + 1, j + 5, k + 8, Block.waterStill.blockID, 8,2);
		world.setBlock(i + 1, j + 5, k + 9, Block.waterStill.blockID, 8,2);
		world.setBlock(i + 1, j + 5, k + 10, Block.waterStill.blockID, 8,2);
		world.setBlock(i + 1, j + 5, k + 11, Block.waterStill.blockID, 8,2);
		world.setBlock(i + 1, j + 5, k + 12, Block.waterStill.blockID, 8,2);
		world.setBlock(i + 1, j + 5, k + 13, Block.waterStill.blockID, 8,2);
		world.setBlock(i + 1, j + 5, k + 14, Block.waterStill.blockID, 8,2);
		world.setBlock(i + 1, j + 5, k + 15, Block.waterStill.blockID, 8,2);
		world.setBlock(i + 1, j + 5, k + 16, Block.waterStill.blockID, 8,2);
		world.setBlock(i + 1, j + 6, k + 1, Block.waterStill.blockID, 8,2);
		world.setBlock(i + 1, j + 6, k + 2, Block.waterStill.blockID, 8,2);
		world.setBlock(i + 1, j + 6, k + 3, Block.waterStill.blockID, 8,2);
		world.setBlock(i + 1, j + 6, k + 4, Block.waterStill.blockID, 8,2);
		world.setBlock(i + 1, j + 6, k + 5, Block.waterStill.blockID, 8,2);
		world.setBlock(i + 1, j + 6, k + 6, Block.waterStill.blockID, 8,2);
		world.setBlock(i + 1, j + 6, k + 7, Block.waterStill.blockID, 8,2);
		world.setBlock(i + 1, j + 6, k + 8, Block.waterStill.blockID, 8,2);
		world.setBlock(i + 1, j + 6, k + 9, Block.waterStill.blockID, 8,2);
		world.setBlock(i + 1, j + 6, k + 10, Block.waterStill.blockID, 8,2);
		world.setBlock(i + 1, j + 6, k + 11, Block.waterStill.blockID, 8,2);
		world.setBlock(i + 1, j + 6, k + 12, Block.waterStill.blockID, 8,2);
		world.setBlock(i + 1, j + 6, k + 13, Block.waterStill.blockID, 8,2);
		world.setBlock(i + 1, j + 6, k + 14, Block.waterStill.blockID, 8,2);
		world.setBlock(i + 1, j + 6, k + 15, Block.waterStill.blockID, 8,2);
		world.setBlock(i + 1, j + 6, k + 16, Block.waterStill.blockID, 8,2);
		world.setBlock(i + 1, j + 7, k + 1, Block.waterStill.blockID, 8,2);
		world.setBlock(i + 1, j + 7, k + 2, Block.waterStill.blockID, 8,2);
		world.setBlock(i + 1, j + 7, k + 3, Block.waterStill.blockID, 8,2);
		world.setBlock(i + 1, j + 7, k + 4, Block.waterStill.blockID, 8,2);
		world.setBlock(i + 1, j + 7, k + 5, Block.waterStill.blockID, 8,2);
		world.setBlock(i + 1, j + 7, k + 6, Block.waterStill.blockID, 8,2);
		world.setBlock(i + 1, j + 7, k + 7, Block.waterStill.blockID, 8,2);
		world.setBlock(i + 1, j + 7, k + 8, Block.waterStill.blockID, 8,2);
		world.setBlock(i + 1, j + 7, k + 9, Block.waterStill.blockID, 8,2);
		world.setBlock(i + 1, j + 7, k + 10, Block.waterStill.blockID, 8,2);
		world.setBlock(i + 1, j + 7, k + 11, Block.waterStill.blockID, 8,2);
		world.setBlock(i + 1, j + 7, k + 12, Block.waterStill.blockID, 8,2);
		world.setBlock(i + 1, j + 7, k + 13, Block.waterStill.blockID, 8,2);
		world.setBlock(i + 1, j + 7, k + 14, Block.waterStill.blockID, 8,2);
		world.setBlock(i + 1, j + 7, k + 15, Block.waterStill.blockID, 8,2);
		world.setBlock(i + 1, j + 7, k + 16, Block.waterStill.blockID, 8,2);
		world.setBlock(i + 1, j + 8, k + 1, Block.waterStill.blockID, 8,2);
		world.setBlock(i + 1, j + 8, k + 2, Block.waterStill.blockID, 8,2);
		world.setBlock(i + 1, j + 8, k + 3, Block.waterStill.blockID, 8,2);
		world.setBlock(i + 1, j + 8, k + 4, Block.waterStill.blockID, 8,2);
		world.setBlock(i + 1, j + 8, k + 5, Block.waterStill.blockID, 8,2);
		world.setBlock(i + 1, j + 8, k + 6, Block.waterStill.blockID, 8,2);
		world.setBlock(i + 1, j + 8, k + 7, Block.waterStill.blockID, 8,2);
		world.setBlock(i + 1, j + 8, k + 8, Block.waterStill.blockID, 8,2);
		world.setBlock(i + 1, j + 8, k + 9, Block.waterStill.blockID, 8,2);
		world.setBlock(i + 1, j + 8, k + 10, Block.waterStill.blockID, 8,2);
		world.setBlock(i + 1, j + 8, k + 11, Block.waterStill.blockID, 8,2);
		world.setBlock(i + 1, j + 8, k + 12, Block.waterStill.blockID, 8,2);
		world.setBlock(i + 1, j + 8, k + 13, Block.waterStill.blockID, 8,2);
		world.setBlock(i + 1, j + 8, k + 14, Block.waterStill.blockID, 8,2);
		world.setBlock(i + 1, j + 8, k + 15, Block.waterStill.blockID, 8,2);
		world.setBlock(i + 1, j + 8, k + 16, Block.waterStill.blockID, 8,2);
		world.setBlock(i + 1, j + 9, k + 1, Block.waterStill.blockID, 8,2);
		world.setBlock(i + 1, j + 9, k + 2, Block.waterStill.blockID, 8,2);
		world.setBlock(i + 1, j + 9, k + 3, Block.waterStill.blockID, 8,2);
		world.setBlock(i + 1, j + 9, k + 4, Block.waterStill.blockID, 8,2);
		world.setBlock(i + 1, j + 9, k + 5, Block.waterStill.blockID, 8,2);
		world.setBlock(i + 1, j + 9, k + 6, Block.waterStill.blockID, 8,2);
		world.setBlock(i + 1, j + 9, k + 7, Block.waterStill.blockID, 8,2);
		world.setBlock(i + 1, j + 9, k + 8, Block.waterStill.blockID, 8,2);
		world.setBlock(i + 1, j + 9, k + 9, Block.waterStill.blockID, 8,2);
		world.setBlock(i + 1, j + 9, k + 10, Block.waterStill.blockID, 8,2);
		world.setBlock(i + 1, j + 9, k + 11, Block.waterStill.blockID, 8,2);
		world.setBlock(i + 1, j + 9, k + 12, Block.waterStill.blockID, 8,2);
		world.setBlock(i + 1, j + 9, k + 13, Block.waterStill.blockID, 8,2);
		world.setBlock(i + 1, j + 9, k + 14, Block.waterStill.blockID, 8,2);
		world.setBlock(i + 1, j + 9, k + 15, Block.waterStill.blockID, 8,2);
		world.setBlock(i + 1, j + 9, k + 16, Block.waterStill.blockID, 8,2);
		world.setBlock(i + 1, j + 10, k + 1, Block.waterStill.blockID, 8,2);
		world.setBlock(i + 1, j + 10, k + 2, Block.waterStill.blockID, 8,2);
		world.setBlock(i + 1, j + 10, k + 3, Block.waterStill.blockID, 8,2);
		world.setBlock(i + 1, j + 10, k + 4, Block.waterStill.blockID, 8,2);
		world.setBlock(i + 1, j + 10, k + 5, Block.waterStill.blockID, 8,2);
		world.setBlock(i + 1, j + 10, k + 6, Block.waterStill.blockID, 8,2);
		world.setBlock(i + 1, j + 10, k + 7, Block.waterStill.blockID, 8,2);
		world.setBlock(i + 1, j + 10, k + 8, Block.waterStill.blockID, 8,2);
		world.setBlock(i + 1, j + 10, k + 9, Block.waterStill.blockID, 8,2);
		world.setBlock(i + 1, j + 10, k + 10, Block.waterStill.blockID, 8,2);
		world.setBlock(i + 1, j + 10, k + 11, Block.waterStill.blockID, 8,2);
		world.setBlock(i + 1, j + 10, k + 12, Block.waterStill.blockID, 8,2);
		world.setBlock(i + 1, j + 10, k + 13, Block.waterStill.blockID, 8,2);
		world.setBlock(i + 1, j + 10, k + 14, Block.waterStill.blockID, 8,2);
		world.setBlock(i + 1, j + 10, k + 15, Block.waterStill.blockID, 8,2);
		world.setBlock(i + 1, j + 10, k + 16, Block.waterStill.blockID, 8,2);
		world.setBlock(i + 1, j + 11, k + 1, Block.waterStill.blockID, 8,2);
		world.setBlock(i + 1, j + 11, k + 2, Block.waterStill.blockID, 8,2);
		world.setBlock(i + 1, j + 11, k + 3, Block.waterStill.blockID, 8,2);
		world.setBlock(i + 1, j + 11, k + 4, Block.waterStill.blockID, 8,2);
		world.setBlock(i + 1, j + 11, k + 5, Block.waterStill.blockID, 8,2);
		world.setBlock(i + 1, j + 11, k + 6, Block.waterStill.blockID, 8,2);
		world.setBlock(i + 1, j + 11, k + 7, Block.waterStill.blockID, 8,2);
		world.setBlock(i + 1, j + 11, k + 8, Block.waterStill.blockID, 8,2);
		world.setBlock(i + 1, j + 11, k + 9, Block.waterStill.blockID, 8,2);
		world.setBlock(i + 1, j + 11, k + 10, Block.waterStill.blockID, 8,2);
		world.setBlock(i + 1, j + 11, k + 11, Block.waterStill.blockID, 8,2);
		world.setBlock(i + 1, j + 11, k + 12, Block.waterStill.blockID, 8,2);
		world.setBlock(i + 1, j + 11, k + 13, Block.waterStill.blockID, 8,2);
		world.setBlock(i + 1, j + 11, k + 14, Block.waterStill.blockID, 8,2);
		world.setBlock(i + 1, j + 11, k + 15, Block.waterStill.blockID, 8,2);
		world.setBlock(i + 1, j + 11, k + 16, Block.waterStill.blockID, 8,2);
		world.setBlock(i + 1, j + 12, k + 1, Block.waterStill.blockID, 8,2);
		world.setBlock(i + 1, j + 12, k + 2, Block.waterStill.blockID, 8,2);
		world.setBlock(i + 1, j + 12, k + 3, Block.waterStill.blockID, 8,2);
		world.setBlock(i + 1, j + 12, k + 4, Block.waterStill.blockID, 8,2);
		world.setBlock(i + 1, j + 12, k + 5, Block.waterStill.blockID, 8,2);
		world.setBlock(i + 1, j + 12, k + 6, Block.waterStill.blockID, 8,2);
		world.setBlock(i + 1, j + 12, k + 7, Block.waterStill.blockID, 8,2);
		world.setBlock(i + 1, j + 12, k + 8, Block.waterStill.blockID, 8,2);
		world.setBlock(i + 1, j + 12, k + 9, Block.waterStill.blockID, 8,2);
		world.setBlock(i + 1, j + 12, k + 10, Block.waterStill.blockID, 8,2);
		world.setBlock(i + 1, j + 12, k + 11, Block.waterStill.blockID, 8,2);
		world.setBlock(i + 1, j + 12, k + 12, Block.waterStill.blockID, 8,2);
		world.setBlock(i + 1, j + 12, k + 13, Block.waterStill.blockID, 8,2);
		world.setBlock(i + 1, j + 12, k + 14, Block.waterStill.blockID, 8,2);
		world.setBlock(i + 1, j + 12, k + 15, Block.waterStill.blockID, 8,2);
		world.setBlock(i + 1, j + 12, k + 16, Block.waterStill.blockID, 8,2);
		world.setBlock(i + 1, j + 13, k + 1, Block.waterStill.blockID, 8,2);
		world.setBlock(i + 1, j + 13, k + 2, Block.waterStill.blockID, 8,2);
		world.setBlock(i + 1, j + 13, k + 3, Block.waterStill.blockID, 8,2);
		world.setBlock(i + 1, j + 13, k + 4, Block.waterStill.blockID, 8,2);
		world.setBlock(i + 1, j + 13, k + 5, Block.waterStill.blockID, 8,2);
		world.setBlock(i + 1, j + 13, k + 6, Block.waterStill.blockID, 8,2);
		world.setBlock(i + 1, j + 13, k + 7, Block.waterStill.blockID, 8,2);
		world.setBlock(i + 1, j + 13, k + 8, Block.waterStill.blockID, 8,2);
		world.setBlock(i + 1, j + 13, k + 9, Block.waterStill.blockID, 8,2);
		world.setBlock(i + 1, j + 13, k + 10, Block.waterStill.blockID, 8,2);
		world.setBlock(i + 1, j + 13, k + 11, Block.waterStill.blockID, 8,2);
		world.setBlock(i + 1, j + 13, k + 12, Block.waterStill.blockID, 8,2);
		world.setBlock(i + 1, j + 13, k + 13, Block.waterStill.blockID, 8,2);
		world.setBlock(i + 1, j + 13, k + 14, Block.waterStill.blockID, 8,2);
		world.setBlock(i + 1, j + 13, k + 15, Block.waterStill.blockID, 8,2);
		world.setBlock(i + 1, j + 13, k + 16, Block.waterStill.blockID, 8,2);
		world.setBlock(i + 1, j + 14, k + 1, Block.waterStill.blockID, 8,2);
		world.setBlock(i + 1, j + 14, k + 2, Block.waterStill.blockID, 8,2);
		world.setBlock(i + 1, j + 14, k + 3, Block.waterStill.blockID, 8,2);
		world.setBlock(i + 1, j + 14, k + 4, Block.waterStill.blockID, 8,2);
		world.setBlock(i + 1, j + 14, k + 5, Block.waterStill.blockID, 8,2);
		world.setBlock(i + 1, j + 14, k + 6, Block.waterStill.blockID, 8,2);
		world.setBlock(i + 1, j + 14, k + 7, Block.waterStill.blockID, 8,2);
		world.setBlock(i + 1, j + 14, k + 8, Block.waterStill.blockID, 8,2);
		world.setBlock(i + 1, j + 14, k + 9, Block.waterStill.blockID, 8,2);
		world.setBlock(i + 1, j + 14, k + 10, Block.waterStill.blockID, 8,2);
		world.setBlock(i + 1, j + 14, k + 11, Block.waterStill.blockID, 8,2);
		world.setBlock(i + 1, j + 14, k + 12, Block.waterStill.blockID, 8,2);
		world.setBlock(i + 1, j + 14, k + 13, Block.waterStill.blockID, 8,2);
		world.setBlock(i + 1, j + 14, k + 14, Block.waterStill.blockID, 8,2);
		world.setBlock(i + 1, j + 14, k + 15, Block.waterStill.blockID, 8,2);
		world.setBlock(i + 1, j + 14, k + 16, Block.waterStill.blockID, 8,2);
		world.setBlock(i + 1, j + 15, k + 1, Block.waterStill.blockID, 8,2);
		world.setBlock(i + 1, j + 15, k + 2, Block.waterStill.blockID, 8,2);
		world.setBlock(i + 1, j + 15, k + 3, Block.waterStill.blockID, 8,2);
		world.setBlock(i + 1, j + 15, k + 4, Block.waterStill.blockID, 8,2);
		world.setBlock(i + 1, j + 15, k + 5, Block.waterStill.blockID, 8,2);
		world.setBlock(i + 1, j + 15, k + 6, Block.waterStill.blockID, 8,2);
		world.setBlock(i + 1, j + 15, k + 7, Block.waterStill.blockID, 8,2);
		world.setBlock(i + 1, j + 15, k + 8, Block.waterStill.blockID, 8,2);
		world.setBlock(i + 1, j + 15, k + 9, Block.waterStill.blockID, 8,2);
		world.setBlock(i + 1, j + 15, k + 10, Block.waterStill.blockID, 8,2);
		world.setBlock(i + 1, j + 15, k + 11, Block.waterStill.blockID, 8,2);
		world.setBlock(i + 1, j + 15, k + 12, Block.waterStill.blockID, 8,2);
		world.setBlock(i + 1, j + 15, k + 13, Block.waterStill.blockID, 8,2);
		world.setBlock(i + 1, j + 15, k + 14, Block.waterStill.blockID, 8,2);
		world.setBlock(i + 1, j + 15, k + 15, Block.waterStill.blockID, 8,2);
		world.setBlock(i + 1, j + 15, k + 16, Block.waterStill.blockID, 8,2);
		world.setBlock(i + 1, j + 16, k + 1, Block.waterStill.blockID, 8,2);
		world.setBlock(i + 1, j + 16, k + 2, Block.waterStill.blockID, 8,2);
		world.setBlock(i + 1, j + 16, k + 3, Block.waterStill.blockID, 8,2);
		world.setBlock(i + 1, j + 16, k + 4, Block.waterStill.blockID, 8,2);
		world.setBlock(i + 1, j + 16, k + 5, Block.waterStill.blockID, 8,2);
		world.setBlock(i + 1, j + 16, k + 6, Block.waterStill.blockID, 8,2);
		world.setBlock(i + 1, j + 16, k + 7, Block.waterStill.blockID, 8,2);
		world.setBlock(i + 1, j + 16, k + 8, Block.waterStill.blockID, 8,2);
		world.setBlock(i + 1, j + 16, k + 9, Block.waterStill.blockID, 8,2);
		world.setBlock(i + 1, j + 16, k + 10, Block.waterStill.blockID, 8,2);
		world.setBlock(i + 1, j + 16, k + 11, Block.waterStill.blockID, 8,2);
		world.setBlock(i + 1, j + 16, k + 12, Block.waterStill.blockID, 8,2);
		world.setBlock(i + 1, j + 16, k + 13, Block.waterStill.blockID, 8,2);
		world.setBlock(i + 1, j + 16, k + 14, Block.waterStill.blockID, 8,2);
		world.setBlock(i + 1, j + 16, k + 15, Block.waterStill.blockID, 8,2);
		world.setBlock(i + 1, j + 16, k + 16, Block.waterStill.blockID, 8,2);
		world.setBlock(i + 1, j + 17, k + 1, Block.waterStill.blockID, 8,2);
		world.setBlock(i + 1, j + 17, k + 2, Block.waterStill.blockID, 8,2);
		world.setBlock(i + 1, j + 17, k + 3, Block.waterStill.blockID, 8,2);
		world.setBlock(i + 1, j + 17, k + 4, Block.waterStill.blockID, 8,2);
		world.setBlock(i + 1, j + 17, k + 5, Block.waterStill.blockID, 8,2);
		world.setBlock(i + 1, j + 17, k + 6, Block.waterStill.blockID, 8,2);
		world.setBlock(i + 1, j + 17, k + 7, Block.waterStill.blockID, 8,2);
		world.setBlock(i + 1, j + 17, k + 8, Block.waterStill.blockID, 8,2);
		world.setBlock(i + 1, j + 17, k + 9, Block.waterStill.blockID, 8,2);
		world.setBlock(i + 1, j + 17, k + 10, Block.waterStill.blockID, 8,2);
		world.setBlock(i + 1, j + 17, k + 11, Block.waterStill.blockID, 8,2);
		world.setBlock(i + 1, j + 17, k + 12, Block.waterStill.blockID, 8,2);
		world.setBlock(i + 1, j + 17, k + 13, Block.waterStill.blockID, 8,2);
		world.setBlock(i + 1, j + 17, k + 14, Block.waterStill.blockID, 8,2);
		world.setBlock(i + 1, j + 17, k + 15, Block.waterStill.blockID, 8,2);
		world.setBlock(i + 1, j + 17, k + 16, Block.waterStill.blockID, 8,2);
		world.setBlock(i + 1, j + 18, k + 1, Block.waterStill.blockID);
		world.setBlock(i + 1, j + 18, k + 2, Block.waterStill.blockID);
		world.setBlock(i + 1, j + 18, k + 3, Block.waterStill.blockID);
		world.setBlock(i + 1, j + 18, k + 4, Block.waterStill.blockID);
		world.setBlock(i + 1, j + 18, k + 5, Block.waterStill.blockID);
		world.setBlock(i + 1, j + 18, k + 6, Block.waterStill.blockID);
		world.setBlock(i + 1, j + 18, k + 7, Block.waterStill.blockID);
		world.setBlock(i + 1, j + 18, k + 8, Block.waterStill.blockID);
		world.setBlock(i + 1, j + 18, k + 9, Block.waterStill.blockID);
		world.setBlock(i + 1, j + 18, k + 10, Block.waterStill.blockID);
		world.setBlock(i + 1, j + 18, k + 11, Block.waterStill.blockID);
		world.setBlock(i + 1, j + 18, k + 12, Block.waterStill.blockID);
		world.setBlock(i + 1, j + 18, k + 13, Block.waterStill.blockID);
		world.setBlock(i + 1, j + 18, k + 14, Block.waterStill.blockID);
		world.setBlock(i + 1, j + 18, k + 15, Block.waterStill.blockID);
		world.setBlock(i + 1, j + 18, k + 16, Block.waterStill.blockID);
		world.setBlock(i + 2, j + 0, k + 1, Block.waterStill.blockID, 8,2);
		world.setBlock(i + 2, j + 0, k + 16, Block.waterStill.blockID, 8,2);
		world.setBlock(i + 2, j + 1, k + 1, Block.waterStill.blockID, 8,2);
		world.setBlock(i + 2, j + 1, k + 16, Block.waterStill.blockID, 8,2);
		world.setBlock(i + 2, j + 2, k + 1, Block.waterStill.blockID, 8,2);
		world.setBlock(i + 2, j + 2, k + 16, Block.waterStill.blockID, 8,2);
		world.setBlock(i + 2, j + 3, k + 1, Block.waterStill.blockID, 8,2);
		world.setBlock(i + 2, j + 3, k + 16, Block.waterStill.blockID, 8,2);
		world.setBlock(i + 2, j + 4, k + 1, Block.waterStill.blockID, 8,2);
		world.setBlock(i + 2, j + 4, k + 16, Block.waterStill.blockID, 8,2);
		world.setBlock(i + 2, j + 5, k + 1, Block.waterStill.blockID, 8,2);
		world.setBlock(i + 2, j + 5, k + 16, Block.waterStill.blockID, 8,2);
		world.setBlock(i + 2, j + 6, k + 1, Block.waterStill.blockID, 8,2);
		world.setBlock(i + 2, j + 6, k + 16, Block.waterStill.blockID, 8,2);
		world.setBlock(i + 2, j + 7, k + 1, Block.waterStill.blockID, 8,2);
		world.setBlock(i + 2, j + 7, k + 16, Block.waterStill.blockID, 8,2);
		world.setBlock(i + 2, j + 8, k + 1, Block.waterStill.blockID, 8,2);
		world.setBlock(i + 2, j + 8, k + 16, Block.waterStill.blockID, 8,2);
		world.setBlock(i + 2, j + 9, k + 1, Block.waterStill.blockID, 8,2);
		world.setBlock(i + 2, j + 9, k + 16, Block.waterStill.blockID, 8,2);
		world.setBlock(i + 2, j + 10, k + 1, Block.waterStill.blockID, 8,2);
		world.setBlock(i + 2, j + 10, k + 16, Block.waterStill.blockID, 8,2);
		world.setBlock(i + 2, j + 11, k + 1, Block.waterStill.blockID, 8,2);
		world.setBlock(i + 2, j + 11, k + 16, Block.waterStill.blockID, 8,2);
		world.setBlock(i + 2, j + 12, k + 1, Block.waterStill.blockID, 8,2);
		world.setBlock(i + 2, j + 12, k + 16, Block.waterStill.blockID, 8,2);
		world.setBlock(i + 2, j + 13, k + 1, Block.waterStill.blockID, 8,2);
		world.setBlock(i + 2, j + 13, k + 16, Block.waterStill.blockID, 8,2);
		world.setBlock(i + 2, j + 14, k + 1, Block.waterStill.blockID, 8,2);
		world.setBlock(i + 2, j + 14, k + 16, Block.waterStill.blockID, 8,2);
		world.setBlock(i + 2, j + 15, k + 1, Block.waterStill.blockID, 8,2);
		world.setBlock(i + 2, j + 15, k + 16, Block.waterStill.blockID, 8,2);
		world.setBlock(i + 2, j + 16, k + 1, Block.waterStill.blockID, 8,2);
		world.setBlock(i + 2, j + 16, k + 16, Block.waterStill.blockID, 8,2);
		world.setBlock(i + 2, j + 17, k + 1, Block.waterStill.blockID, 8,2);
		world.setBlock(i + 2, j + 17, k + 16, Block.waterStill.blockID, 8,2);
		world.setBlock(i + 2, j + 18, k + 1, Block.waterStill.blockID);
		world.setBlock(i + 2, j + 18, k + 16, Block.waterStill.blockID);
		world.setBlock(i + 2, j + 19, k + 2, Block.waterStill.blockID);
		world.setBlock(i + 2, j + 19, k + 3, Block.waterStill.blockID);
		world.setBlock(i + 2, j + 19, k + 4, Block.waterStill.blockID);
		world.setBlock(i + 2, j + 19, k + 5, Block.waterStill.blockID);
		world.setBlock(i + 2, j + 19, k + 6, Block.waterStill.blockID);
		world.setBlock(i + 2, j + 19, k + 7, Block.waterStill.blockID);
		world.setBlock(i + 2, j + 19, k + 8, Block.waterStill.blockID);
		world.setBlock(i + 2, j + 19, k + 9, Block.waterStill.blockID);
		world.setBlock(i + 2, j + 19, k + 10, Block.waterStill.blockID);
		world.setBlock(i + 2, j + 19, k + 11, Block.waterStill.blockID);
		world.setBlock(i + 2, j + 19, k + 12, Block.waterStill.blockID);
		world.setBlock(i + 2, j + 19, k + 13, Block.waterStill.blockID);
		world.setBlock(i + 2, j + 19, k + 14, Block.waterStill.blockID);
		world.setBlock(i + 2, j + 19, k + 15, Block.waterStill.blockID);
		world.setBlock(i + 3, j + 0, k + 1, Block.waterStill.blockID, 9,2);
		world.setBlock(i + 3, j + 0, k + 16, Block.waterStill.blockID, 8,2);
		world.setBlock(i + 3, j + 1, k + 1, Block.waterStill.blockID, 9,2);
		world.setBlock(i + 3, j + 1, k + 16, Block.waterStill.blockID, 8,2);
		world.setBlock(i + 3, j + 2, k + 1, Block.waterStill.blockID, 9,2);
