/*
*** MADE BY MITHION'S .SCHEMATIC TO JAVA CONVERTING TOOL v1.6 ***
*/

package com.sudwood.mysticadditions.worldgen;
import java.util.Random;

import net.minecraft.block.Block;
import net.minecraft.item.ItemStack;
import net.minecraft.tileentity.TileEntityChest;
import net.minecraft.tileentity.TileEntityMobSpawner;
import net.minecraft.world.World;
import net.minecraft.world.gen.feature.WorldGenerator;

import com.sudwood.mysticadditions.blocks.MysticModBlocks;
import com.sudwood.mysticadditions.items.MysticModItems;

public class WorldGenWarpedFireShrine extends WorldGenerator
{
	protected int[] GetValidSpawnBlocks() {
		return new int[] {
			MysticModBlocks.inertGrass.blockID
		};
	}

	public boolean LocationIsValidSpawn(World world, int i, int j, int k){
		if(!world.isRemote)
		{
		int distanceToAir = 0;
		int checkID = world.getBlockId(i, j, k);

		while (checkID != 0){
			distanceToAir++;
			checkID = world.getBlockId(i, j + distanceToAir, k);
		}

		if (distanceToAir > 3){
			return false;
		}
		j += distanceToAir - 1;

		int blockID = world.getBlockId(i, j, k);
		int blockIDAbove = world.getBlockId(i, j+1, k);
		int blockIDBelow = world.getBlockId(i, j-1, k);
		for (int x : GetValidSpawnBlocks()){
			if (blockIDAbove != 0){
				return false;
			}
			if (blockID == x){
				return true;
			}else if (blockID == Block.snow.blockID && blockIDBelow == x){
				return true;
			}
		}
		}
		return false;
	}

	public WorldGenWarpedFireShrine() { }

	public boolean generate(World world, Random rand, int i, int j, int k) {
		//check that each corner is one of the valid spawn blocks
		if(world.getBlockId(i, j, k)!=MysticModBlocks.inertGrass.blockID)
		{
			return false;
		}

		
		world.setBlock(i + 2, j + 1, k + 4, Block.stoneSingleSlab.blockID, 2,2);
		world.setBlock(i + 2, j + 1, k + 5, Block.stoneSingleSlab.blockID, 2,2);
		world.setBlock(i + 2, j + 1, k + 6, Block.stoneSingleSlab.blockID, 2,2);
		world.setBlock(i + 2, j + 1, k + 7, Block.stoneSingleSlab.blockID, 2,2);
		world.setBlock(i + 2, j + 1, k + 8, Block.stoneSingleSlab.blockID, 2,2);
		world.setBlock(i + 2, j + 1, k + 9, Block.stoneSingleSlab.blockID, 2,2);
		world.setBlock(i + 2, j + 1, k + 10, Block.stoneSingleSlab.blockID, 2,2);
		world.setBlock(i + 2, j + 1, k + 11, Block.stoneSingleSlab.blockID, 2,2);
		world.setBlock(i + 2, j + 1, k + 12, Block.stoneSingleSlab.blockID, 2,2);
		
		world.setBlock(i + 3, j + 1, k + 4, Block.stoneSingleSlab.blockID, 2,2);
		world.setBlock(i + 3, j + 1, k + 5, MysticModBlocks.mysticBricks.blockID);
		world.setBlock(i + 3, j + 1, k + 6, MysticModBlocks.mysticBricks.blockID);
		world.setBlock(i + 3, j + 1, k + 7, MysticModBlocks.mysticBricks.blockID);
		world.setBlock(i + 3, j + 1, k + 8, MysticModBlocks.mysticBricks.blockID);
		world.setBlock(i + 3, j + 1, k + 9, MysticModBlocks.mysticBricks.blockID);
		world.setBlock(i + 3, j + 1, k + 10, MysticModBlocks.mysticBricks.blockID);
		world.setBlock(i + 3, j + 1, k + 11, MysticModBlocks.mysticBricks.blockID);
		world.setBlock(i + 3, j + 1, k + 12, Block.stoneSingleSlab.blockID, 2,2);
		
		world.setBlock(i + 4, j + 1, k + 4, Block.stoneSingleSlab.blockID, 2,2);
		world.setBlock(i + 4, j + 1, k + 5, MysticModBlocks.mysticBricks.blockID);
		world.setBlock(i + 4, j + 1, k + 6, MysticModBlocks.mysticBricks.blockID);
		world.setBlock(i + 4, j + 1, k + 7, MysticModBlocks.mysticBricks.blockID);
		world.setBlock(i + 4, j + 1, k + 8, MysticModBlocks.mysticBricks.blockID);
		world.setBlock(i + 4, j + 1, k + 9, MysticModBlocks.mysticBricks.blockID);
		world.setBlock(i + 4, j + 1, k + 10, MysticModBlocks.mysticBricks.blockID);
		world.setBlock(i + 4, j + 1, k + 11, MysticModBlocks.mysticBricks.blockID);
		world.setBlock(i + 4, j + 1, k + 12, Block.stoneSingleSlab.blockID, 2,2);
		world.setBlock(i + 4, j + 2, k + 6, Block.stoneSingleSlab.blockID, 2,2);
		world.setBlock(i + 4, j + 2, k + 7, Block.stoneSingleSlab.blockID, 2,2);
		world.setBlock(i + 4, j + 2, k + 8, Block.stoneSingleSlab.blockID, 2,2);
		world.setBlock(i + 4, j + 2, k + 9, Block.stoneSingleSlab.blockID, 2,2);
		world.setBlock(i + 4, j + 2, k + 10, Block.stoneSingleSlab.blockID, 2,2);
		
		world.setBlock(i + 5, j + 1, k + 4, Block.stoneSingleSlab.blockID, 2,2);
		world.setBlock(i + 5, j + 1, k + 5, MysticModBlocks.mysticBricks.blockID);
		world.setBlock(i + 5, j + 1, k + 6, MysticModBlocks.mysticBricks.blockID);
		world.setBlock(i + 5, j + 1, k + 7, MysticModBlocks.mysticBricks.blockID);
		world.setBlock(i + 5, j + 1, k + 8, MysticModBlocks.mysticBricks.blockID);
		world.setBlock(i + 5, j + 1, k + 9, MysticModBlocks.mysticBricks.blockID);
		world.setBlock(i + 5, j + 1, k + 10, MysticModBlocks.mysticBricks.blockID);
		world.setBlock(i + 5, j + 1, k + 11, MysticModBlocks.mysticBricks.blockID);
		world.setBlock(i + 5, j + 1, k + 12, Block.stoneSingleSlab.blockID, 2,2);
		world.setBlock(i + 5, j + 2, k + 6, Block.stoneSingleSlab.blockID, 2,2);
		world.setBlock(i + 5, j + 2, k + 7, MysticModBlocks.mysticBricks.blockID);
		world.setBlock(i + 5, j + 2, k + 8, MysticModBlocks.mysticBricks.blockID);
		world.setBlock(i + 5, j + 2, k + 9, MysticModBlocks.mysticBricks.blockID);
		world.setBlock(i + 5, j + 2, k + 10, Block.stoneSingleSlab.blockID, 2,2);
		
		world.setBlock(i + 6, j + 1, k + 4, Block.stoneSingleSlab.blockID, 2,2);
		world.setBlock(i + 6, j + 1, k + 5, MysticModBlocks.mysticBricks.blockID);
		world.setBlock(i + 6, j + 1, k + 6, MysticModBlocks.mysticBricks.blockID);
		world.setBlock(i + 6, j + 1, k + 7, MysticModBlocks.mysticBricks.blockID);
		world.setBlock(i + 6, j + 1, k + 8, MysticModBlocks.mysticBricks.blockID);
		world.setBlock(i + 6, j + 1, k + 9, MysticModBlocks.mysticBricks.blockID);
		world.setBlock(i + 6, j + 1, k + 10, MysticModBlocks.mysticBricks.blockID);
		world.setBlock(i + 6, j + 1, k + 11, MysticModBlocks.mysticBricks.blockID);
		world.setBlock(i + 6, j + 1, k + 12, Block.stoneSingleSlab.blockID, 2,2);
		world.setBlock(i + 6, j + 2, k + 6, Block.stoneSingleSlab.blockID, 2,2);
		world.setBlock(i + 6, j + 2, k + 7, MysticModBlocks.mysticBricks.blockID);
		world.setBlock(i + 6, j + 2, k + 8, MysticModBlocks.mysticBricks.blockID);
		world.setBlock(i + 6, j + 2, k + 9, MysticModBlocks.mysticBricks.blockID);
		world.setBlock(i + 6, j + 2, k + 10, Block.stoneSingleSlab.blockID, 2,2);
		
		world.setBlock(i + 7, j + 1, k + 3, Block.stoneSingleSlab.blockID, 2,2);
		world.setBlock(i + 7, j + 1, k + 11, Block.stoneSingleSlab.blockID, 2,2);
		world.setBlock(i + 7, j + 1, k + 13, Block.stoneSingleSlab.blockID, 2,2);
		world.setBlock(i + 7, j + 2, k + 2, MysticModBlocks.mysticBricks.blockID);
		world.setBlock(i + 7, j + 2, k + 3, MysticModBlocks.mysticBricks.blockID);
		world.setBlock(i + 7, j + 2, k + 4, MysticModBlocks.mysticBricks.blockID);
		world.setBlock(i + 7, j + 2, k + 5, MysticModBlocks.mysticBricks.blockID);
		world.setBlock(i + 7, j + 2, k + 6, MysticModBlocks.mysticBricks.blockID);
		world.setBlock(i + 7, j + 2, k + 7, MysticModBlocks.mysticBricks.blockID);
		world.setBlock(i + 7, j + 2, k + 8, MysticModBlocks.mysticBricks.blockID);
		world.setBlock(i + 7, j + 2, k + 9, MysticModBlocks.mysticBricks.blockID);
		world.setBlock(i + 7, j + 2, k + 10, MysticModBlocks.mysticBricks.blockID);
		world.setBlock(i + 7, j + 2, k + 11, MysticModBlocks.mysticBricks.blockID);
		world.setBlock(i + 7, j + 2, k + 12, MysticModBlocks.mysticBricks.blockID);
		world.setBlock(i + 7, j + 2, k + 13, MysticModBlocks.mysticBricks.blockID);
		world.setBlock(i + 7, j + 2, k + 14, MysticModBlocks.mysticBricks.blockID);
		world.setBlock(i + 7, j + 3, k + 2, MysticModBlocks.mysticBricks.blockID);
		world.setBlock(i + 7, j + 3, k + 3, MysticModBlocks.mysticBricks.blockID);
		world.setBlock(i + 7, j + 3, k + 4, MysticModBlocks.mysticBricks.blockID);
		world.setBlock(i + 7, j + 3, k + 5, MysticModBlocks.mysticBricks.blockID);
		world.setBlock(i + 7, j + 3, k + 6, MysticModBlocks.mysticBricks.blockID);
		world.setBlock(i + 7, j + 3, k + 10, MysticModBlocks.mysticBricks.blockID);
		world.setBlock(i + 7, j + 3, k + 11, MysticModBlocks.mysticBricks.blockID);
		world.setBlock(i + 7, j + 3, k + 12, MysticModBlocks.mysticBricks.blockID);
		world.setBlock(i + 7, j + 3, k + 13, MysticModBlocks.mysticBricks.blockID);
		world.setBlock(i + 7, j + 3, k + 14, MysticModBlocks.mysticBricks.blockID);
		world.setBlock(i + 7, j + 4, k + 2, MysticModBlocks.mysticBricks.blockID);
		world.setBlock(i + 7, j + 4, k + 3, MysticModBlocks.mysticBricks.blockID);
		world.setBlock(i + 7, j + 4, k + 4, MysticModBlocks.mysticBricks.blockID);
		world.setBlock(i + 7, j + 4, k + 5, MysticModBlocks.mysticBricks.blockID);
		world.setBlock(i + 7, j + 4, k + 6, MysticModBlocks.mysticBricks.blockID);
		world.setBlock(i + 7, j + 4, k + 10, MysticModBlocks.mysticBricks.blockID);
		world.setBlock(i + 7, j + 4, k + 11, MysticModBlocks.mysticBricks.blockID);
		world.setBlock(i + 7, j + 4, k + 12, MysticModBlocks.mysticBricks.blockID);
		world.setBlock(i + 7, j + 4, k + 13, MysticModBlocks.mysticBricks.blockID);
		world.setBlock(i + 7, j + 4, k + 14, MysticModBlocks.mysticBricks.blockID);
		world.setBlock(i + 7, j + 5, k + 2, MysticModBlocks.mysticBricks.blockID);
		world.setBlock(i + 7, j + 5, k + 3, MysticModBlocks.mysticBricks.blockID);
		world.setBlock(i + 7, j + 5, k + 4, MysticModBlocks.mysticBricks.blockID);
		world.setBlock(i + 7, j + 5, k + 5, MysticModBlocks.mysticBricks.blockID);
		world.setBlock(i + 7, j + 5, k + 6, MysticModBlocks.mysticBricks.blockID);
		world.setBlock(i + 7, j + 5, k + 10, MysticModBlocks.mysticBricks.blockID);
		world.setBlock(i + 7, j + 5, k + 11, MysticModBlocks.mysticBricks.blockID);
		world.setBlock(i + 7, j + 5, k + 12, MysticModBlocks.mysticBricks.blockID);
		world.setBlock(i + 7, j + 5, k + 13, MysticModBlocks.mysticBricks.blockID);
		world.setBlock(i + 7, j + 5, k + 14, MysticModBlocks.mysticBricks.blockID);
		world.setBlock(i + 7, j + 6, k + 2, MysticModBlocks.mysticBricks.blockID);
		world.setBlock(i + 7, j + 6, k + 3, MysticModBlocks.mysticBricks.blockID);
		world.setBlock(i + 7, j + 6, k + 4, MysticModBlocks.mysticBricks.blockID);
		world.setBlock(i + 7, j + 6, k + 5, MysticModBlocks.mysticGlass.blockID);
		world.setBlock(i + 7, j + 6, k + 6, MysticModBlocks.mysticGlass.blockID);
		world.setBlock(i + 7, j + 6, k + 7, MysticModBlocks.mysticBricks.blockID);
		world.setBlock(i + 7, j + 6, k + 8, MysticModBlocks.mysticGlass.blockID);
		world.setBlock(i + 7, j + 6, k + 9, MysticModBlocks.mysticBricks.blockID);
		world.setBlock(i + 7, j + 6, k + 10, MysticModBlocks.mysticGlass.blockID);
		world.setBlock(i + 7, j + 6, k + 11, MysticModBlocks.mysticGlass.blockID);
		world.setBlock(i + 7, j + 6, k + 12, MysticModBlocks.mysticBricks.blockID);
		world.setBlock(i + 7, j + 6, k + 13, MysticModBlocks.mysticBricks.blockID);
		world.setBlock(i + 7, j + 6, k + 14, MysticModBlocks.mysticBricks.blockID);
		world.setBlock(i + 7, j + 7, k + 2, MysticModBlocks.mysticBricks.blockID);
		world.setBlock(i + 7, j + 7, k + 3, MysticModBlocks.mysticBricks.blockID);
		world.setBlock(i + 7, j + 7, k + 4, MysticModBlocks.mysticBricks.blockID);
		world.setBlock(i + 7, j + 7, k + 5, MysticModBlocks.mysticGlass.blockID);
		world.setBlock(i + 7, j + 7, k + 6, MysticModBlocks.mysticGlass.blockID);
		world.setBlock(i + 7, j + 7, k + 7, MysticModBlocks.mysticBricks.blockID);
		world.setBlock(i + 7, j + 7, k + 8, MysticModBlocks.mysticBricks.blockID);
		world.setBlock(i + 7, j + 7, k + 9, MysticModBlocks.mysticBricks.blockID);
		world.setBlock(i + 7, j + 7, k + 10, MysticModBlocks.mysticGlass.blockID);
		world.setBlock(i + 7, j + 7, k + 11, MysticModBlocks.mysticGlass.blockID);
		world.setBlock(i + 7, j + 7, k + 12, MysticModBlocks.mysticBricks.blockID);
		world.setBlock(i + 7, j + 7, k + 13, MysticModBlocks.mysticBricks.blockID);
		world.setBlock(i + 7, j + 7, k + 14, MysticModBlocks.mysticBricks.blockID);
		world.setBlock(i + 7, j + 8, k + 2, MysticModBlocks.mysticBricks.blockID);
		world.setBlock(i + 7, j + 8, k + 3, MysticModBlocks.mysticBricks.blockID);
		world.setBlock(i + 7, j + 8, k + 4, MysticModBlocks.mysticBricks.blockID);
		world.setBlock(i + 7, j + 8, k + 5, MysticModBlocks.mysticBricks.blockID);
		world.setBlock(i + 7, j + 8, k + 6, MysticModBlocks.mysticBricks.blockID);
		world.setBlock(i + 7, j + 8, k + 7, MysticModBlocks.mysticBricks.blockID);
		world.setBlock(i + 7, j + 8, k + 8, MysticModBlocks.mysticBricks.blockID);
		world.setBlock(i + 7, j + 8, k + 9, MysticModBlocks.mysticBricks.blockID);
		world.setBlock(i + 7, j + 8, k + 10, MysticModBlocks.mysticBricks.blockID);
		world.setBlock(i + 7, j + 8, k + 11, MysticModBlocks.mysticBricks.blockID);
		world.setBlock(i + 7, j + 8, k + 12, MysticModBlocks.mysticBricks.blockID);
		world.setBlock(i + 7, j + 8, k + 13, MysticModBlocks.mysticBricks.blockID);
		world.setBlock(i + 7, j + 8, k + 14, MysticModBlocks.mysticBricks.blockID);
		world.setBlock(i + 7, j + 9, k + 2, Block.stoneSingleSlab.blockID, 2,2);
		world.setBlock(i + 7, j + 9, k + 3, MysticModBlocks.mysticBricks.blockID);
		world.setBlock(i + 7, j + 9, k + 4, MysticModBlocks.mysticBricks.blockID);
		world.setBlock(i + 7, j + 9, k + 5, MysticModBlocks.mysticBricks.blockID);
		world.setBlock(i + 7, j + 9, k + 6, MysticModBlocks.mysticBricks.blockID);
		world.setBlock(i + 7, j + 9, k + 7, MysticModBlocks.mysticBricks.blockID);
		world.setBlock(i + 7, j + 9, k + 8, MysticModBlocks.mysticBricks.blockID);
		world.setBlock(i + 7, j + 9, k + 9, MysticModBlocks.mysticBricks.blockID);
		world.setBlock(i + 7, j + 9, k + 10, MysticModBlocks.mysticBricks.blockID);
		world.setBlock(i + 7, j + 9, k + 11, MysticModBlocks.mysticBricks.blockID);
		world.setBlock(i + 7, j + 9, k + 12, MysticModBlocks.mysticBricks.blockID);
		world.setBlock(i + 7, j + 9, k + 13, MysticModBlocks.mysticBricks.blockID);
		world.setBlock(i + 7, j + 9, k + 14, Block.stoneSingleSlab.blockID, 2,2);
	
		world.setBlock(i + 8, j + 1, k + 2, Block.stoneSingleSlab.blockID, 2,2);
		world.setBlock(i + 8, j + 1, k + 4, Block.stoneSingleSlab.blockID, 2,2);
		world.setBlock(i + 8, j + 1, k + 12, Block.stoneSingleSlab.blockID, 2,2);
		world.setBlock(i + 8, j + 1, k + 14, Block.stoneSingleSlab.blockID, 2,2);
		world.setBlock(i + 8, j + 2, k + 2, MysticModBlocks.mysticBricks.blockID);
		world.setBlock(i + 8, j + 2, k + 4, MysticModBlocks.mysticBricks.blockID);
		world.setBlock(i + 8, j + 2, k + 5, MysticModBlocks.mysticBricks.blockID);
		world.setBlock(i + 8, j + 2, k + 6, MysticModBlocks.mysticBricks.blockID);
		world.setBlock(i + 8, j + 2, k + 7, MysticModBlocks.mysticBricks.blockID);
		world.setBlock(i + 8, j + 2, k + 8, MysticModBlocks.mysticBricks.blockID);
		world.setBlock(i + 8, j + 2, k + 9, MysticModBlocks.mysticBricks.blockID);
		world.setBlock(i + 8, j + 2, k + 10, MysticModBlocks.mysticBricks.blockID);
		world.setBlock(i + 8, j + 2, k + 11, MysticModBlocks.mysticBricks.blockID);
		world.setBlock(i + 8, j + 2, k + 12, MysticModBlocks.mysticBricks.blockID);
		world.setBlock(i + 8, j + 2, k + 14, MysticModBlocks.mysticBricks.blockID);
		world.setBlock(i + 8, j + 3, k + 2, MysticModBlocks.mysticBricks.blockID);
		world.setBlock(i + 8, j + 3, k + 14, MysticModBlocks.mysticBricks.blockID);
		world.setBlock(i + 8, j + 4, k + 2, MysticModBlocks.mysticBricks.blockID);
		world.setBlock(i + 8, j + 4, k + 14, MysticModBlocks.mysticBricks.blockID);
		world.setBlock(i + 8, j + 5, k + 2, MysticModBlocks.mysticBricks.blockID);
		world.setBlock(i + 8, j + 5, k + 14, MysticModBlocks.mysticBricks.blockID);
		world.setBlock(i + 8, j + 6, k + 2, MysticModBlocks.mysticBricks.blockID);
		world.setBlock(i + 8, j + 6, k + 14, MysticModBlocks.mysticBricks.blockID);
		world.setBlock(i + 8, j + 7, k + 2, MysticModBlocks.mysticBricks.blockID);
		world.setBlock(i + 8, j + 7, k + 14, MysticModBlocks.mysticBricks.blockID);
		world.setBlock(i + 8, j + 8, k + 2, MysticModBlocks.mysticBricks.blockID);
		world.setBlock(i + 8, j + 8, k + 14, MysticModBlocks.mysticBricks.blockID);
		world.setBlock(i + 8, j + 9, k + 2, MysticModBlocks.mysticBricks.blockID);
		world.setBlock(i + 8, j + 9, k + 4, MysticModBlocks.mysticBricks.blockID);
		world.setBlock(i + 8, j + 9, k + 5, MysticModBlocks.mysticBricks.blockID);
		world.setBlock(i + 8, j + 9, k + 6, MysticModBlocks.mysticBricks.blockID);
		world.setBlock(i + 8, j + 9, k + 7, MysticModBlocks.mysticBricks.blockID);
		world.setBlock(i + 8, j + 9, k + 8, MysticModBlocks.mysticBricks.blockID);
		world.setBlock(i + 8, j + 9, k + 9, MysticModBlocks.mysticBricks.blockID);
		world.setBlock(i + 8, j + 9, k + 10, MysticModBlocks.mysticBricks.blockID);
		world.setBlock(i + 8, j + 9, k + 11, MysticModBlocks.mysticBricks.blockID);
		world.setBlock(i + 8, j + 9, k + 12, MysticModBlocks.mysticBricks.blockID);
		world.setBlock(i + 8, j + 9, k + 14, MysticModBlocks.mysticBricks.blockID);
		world.setBlock(i + 8, j + 10, k + 3, Block.stoneSingleSlab.blockID, 2,2);
		world.setBlock(i + 8, j + 10, k + 4, Block.stoneSingleSlab.blockID, 2,2);
		world.setBlock(i + 8, j + 10, k + 5, Block.stoneSingleSlab.blockID, 2,2);
		world.setBlock(i + 8, j + 10, k + 6, Block.stoneSingleSlab.blockID, 2,2);
		world.setBlock(i + 8, j + 10, k + 7, Block.stoneSingleSlab.blockID, 2,2);
		world.setBlock(i + 8, j + 10, k + 8, Block.stoneSingleSlab.blockID, 2,2);
		world.setBlock(i + 8, j + 10, k + 9, Block.stoneSingleSlab.blockID, 2,2);
		world.setBlock(i + 8, j + 10, k + 10, Block.stoneSingleSlab.blockID, 2,2);
		world.setBlock(i + 8, j + 10, k + 11, Block.stoneSingleSlab.blockID, 2,2);
		world.setBlock(i + 8, j + 10, k + 12, Block.stoneSingleSlab.blockID, 2,2);
		world.setBlock(i + 8, j + 10, k + 13, Block.stoneSingleSlab.blockID, 2,2);
	
		world.setBlock(i + 9, j + 1, k + 3, Block.stoneSingleSlab.blockID, 2,2);
		world.setBlock(i + 9, j + 1, k + 13, Block.stoneSingleSlab.blockID, 2,2);
		world.setBlock(i + 9, j + 1, k + 14, MysticModBlocks.mysticBricks.blockID);
		world.setBlock(i + 9, j + 2, k + 2, MysticModBlocks.mysticBricks.blockID);
		world.setBlock(i + 9, j + 2, k + 3, MysticModBlocks.mysticBricks.blockID);
		world.setBlock(i + 9, j + 2, k + 4, MysticModBlocks.mysticBricks.blockID);
		world.setBlock(i + 9, j + 2, k + 5, MysticModBlocks.mysticBricks.blockID);
		world.setBlock(i + 9, j + 2, k + 6, MysticModBlocks.mysticBricks.blockID);
		world.setBlock(i + 9, j + 2, k + 7, MysticModBlocks.mysticBricks.blockID);
		world.setBlock(i + 9, j + 2, k + 8, MysticModBlocks.mysticBricks.blockID);
		world.setBlock(i + 9, j + 2, k + 9, MysticModBlocks.mysticBricks.blockID);
		world.setBlock(i + 9, j + 2, k + 10, MysticModBlocks.mysticBricks.blockID);
		world.setBlock(i + 9, j + 2, k + 11, MysticModBlocks.mysticBricks.blockID);
		world.setBlock(i + 9, j + 2, k + 12, MysticModBlocks.mysticBricks.blockID);
		world.setBlock(i + 9, j + 2, k + 13, MysticModBlocks.mysticBricks.blockID);
		world.setBlock(i + 9, j + 2, k + 14, MysticModBlocks.mysticBricks.blockID);
		world.setBlock(i + 9, j + 3, k + 2, MysticModBlocks.mysticBricks.blockID);
		world.setBlock(i + 9, j + 3, k + 14, MysticModBlocks.mysticBricks.blockID);
		world.setBlock(i + 9, j + 4, k + 2, MysticModBlocks.mysticBricks.blockID);
		world.setBlock(i + 9, j + 4, k + 14, MysticModBlocks.mysticBricks.blockID);
		world.setBlock(i + 9, j + 5, k + 2, MysticModBlocks.mysticBricks.blockID);
		world.setBlock(i + 9, j + 5, k + 14, MysticModBlocks.mysticBricks.blockID);
		world.setBlock(i + 9, j + 6, k + 2, MysticModBlocks.mysticBricks.blockID);
		world.setBlock(i + 9, j + 6, k + 14, MysticModBlocks.mysticBricks.blockID);
		world.setBlock(i + 9, j + 7, k + 2, MysticModBlocks.mysticBricks.blockID);
		world.setBlock(i + 9, j + 7, k + 14, MysticModBlocks.mysticBricks.blockID);
		world.setBlock(i + 9, j + 8, k + 2, MysticModBlocks.mysticBricks.blockID);
		world.setBlock(i + 9, j + 8, k + 14, MysticModBlocks.mysticBricks.blockID);
		world.setBlock(i + 9, j + 9, k + 2, MysticModBlocks.mysticBricks.blockID);
		world.setBlock(i + 9, j + 9, k + 3, MysticModBlocks.mysticBricks.blockID);
		world.setBlock(i + 9, j + 9, k + 4, MysticModBlocks.mysticGlass.blockID);
		world.setBlock(i + 9, j + 9, k + 5, MysticModBlocks.mysticGlass.blockID);
		world.setBlock(i + 9, j + 9, k + 6, MysticModBlocks.mysticGlass.blockID);
		world.setBlock(i + 9, j + 9, k + 7, MysticModBlocks.mysticGlass.blockID);
		world.setBlock(i + 9, j + 9, k + 8, MysticModBlocks.mysticGlass.blockID);
		world.setBlock(i + 9, j + 9, k + 9, MysticModBlocks.mysticGlass.blockID);
		world.setBlock(i + 9, j + 9, k + 10, MysticModBlocks.mysticGlass.blockID);
		world.setBlock(i + 9, j + 9, k + 11, MysticModBlocks.mysticGlass.blockID);
		world.setBlock(i + 9, j + 9, k + 12, MysticModBlocks.mysticGlass.blockID);
		world.setBlock(i + 9, j + 9, k + 13, MysticModBlocks.mysticBricks.blockID);
		world.setBlock(i + 9, j + 9, k + 14, MysticModBlocks.mysticBricks.blockID);
		world.setBlock(i + 9, j + 10, k + 3, Block.stoneSingleSlab.blockID, 2,2);
		world.setBlock(i + 9, j + 10, k + 13, Block.stoneSingleSlab.blockID, 2,2);
		
		world.setBlock(i + 10, j + 2, k + 2, MysticModBlocks.mysticBricks.blockID);
		world.setBlock(i + 10, j + 2, k + 3, MysticModBlocks.mysticBricks.blockID);
		world.setBlock(i + 10, j + 2, k + 4, MysticModBlocks.mysticBricks.blockID);
		world.setBlock(i + 10, j + 2, k + 5, MysticModBlocks.mysticfireGlass.blockID);
		world.setBlock(i + 10, j + 2, k + 6, MysticModBlocks.mysticfireGlass.blockID);
		world.setBlock(i + 10, j + 2, k + 7, MysticModBlocks.mysticfireGlass.blockID);
		world.setBlock(i + 10, j + 2, k + 8, MysticModBlocks.mysticfireGlass.blockID);
		world.setBlock(i + 10, j + 2, k + 9, MysticModBlocks.mysticfireGlass.blockID);
		world.setBlock(i + 10, j + 2, k + 10, MysticModBlocks.mysticfireGlass.blockID);
		world.setBlock(i + 10, j + 2, k + 11, MysticModBlocks.mysticfireGlass.blockID);
		world.setBlock(i + 10, j + 2, k + 12, MysticModBlocks.mysticBricks.blockID);
		world.setBlock(i + 10, j + 2, k + 13, MysticModBlocks.mysticBricks.blockID);
		world.setBlock(i + 10, j + 2, k + 14, MysticModBlocks.mysticBricks.blockID);
		world.setBlock(i + 10, j + 3, k + 2, MysticModBlocks.mysticBricks.blockID);
		world.setBlock(i + 10, j + 3, k + 14, MysticModBlocks.mysticBricks.blockID);
		world.setBlock(i + 10, j + 4, k + 2, MysticModBlocks.mysticBricks.blockID);
		world.setBlock(i + 10, j + 4, k + 14, MysticModBlocks.mysticBricks.blockID);
		world.setBlock(i + 10, j + 5, k + 2, MysticModBlocks.mysticBricks.blockID);
		world.setBlock(i + 10, j + 5, k + 14, MysticModBlocks.mysticBricks.blockID);
		world.setBlock(i + 10, j + 6, k + 2, MysticModBlocks.mysticBricks.blockID);
		world.setBlock(i + 10, j + 6, k + 14, MysticModBlocks.mysticBricks.blockID);
		world.setBlock(i + 10, j + 7, k + 2, MysticModBlocks.mysticBricks.blockID);
		world.setBlock(i + 10, j + 7, k + 14, MysticModBlocks.mysticBricks.blockID);
		world.setBlock(i + 10, j + 8, k + 2, MysticModBlocks.mysticBricks.blockID);
		world.setBlock(i + 10, j + 8, k + 14, MysticModBlocks.mysticBricks.blockID);
		world.setBlock(i + 10, j + 9, k + 2, MysticModBlocks.mysticBricks.blockID);
		world.setBlock(i + 10, j + 9, k + 3, MysticModBlocks.mysticBricks.blockID);
		world.setBlock(i + 10, j + 9, k + 4, MysticModBlocks.mysticGlass.blockID);
		world.setBlock(i + 10, j + 9, k + 5, MysticModBlocks.mysticGlass.blockID);
		world.setBlock(i + 10, j + 9, k + 6, MysticModBlocks.mysticGlass.blockID);
		world.setBlock(i + 10, j + 9, k + 7, MysticModBlocks.mysticGlass.blockID);
		world.setBlock(i + 10, j + 9, k + 8, MysticModBlocks.mysticGlass.blockID);
		world.setBlock(i + 10, j + 9, k + 9, MysticModBlocks.mysticGlass.blockID);
		world.setBlock(i + 10, j + 9, k + 10, MysticModBlocks.mysticGlass.blockID);
		world.setBlock(i + 10, j + 9, k + 11, MysticModBlocks.mysticGlass.blockID);
		world.setBlock(i + 10, j + 9, k + 12, MysticModBlocks.mysticGlass.blockID);
		world.setBlock(i + 10, j + 9, k + 13, MysticModBlocks.mysticBricks.blockID);
		world.setBlock(i + 10, j + 9, k + 14, MysticModBlocks.mysticBricks.blockID);
		world.setBlock(i + 10, j + 10, k + 3, Block.stoneSingleSlab.blockID, 2,2);
		world.setBlock(i + 10, j + 10, k + 13, Block.stoneSingleSlab.blockID, 2,2);
		
		world.setBlock(i + 11, j + 2, k + 2, MysticModBlocks.mysticBricks.blockID);
		world.setBlock(i + 11, j + 2, k + 3, MysticModBlocks.mysticBricks.blockID);
		world.setBlock(i + 11, j + 2, k + 4, MysticModBlocks.mysticBricks.blockID);
		world.setBlock(i + 11, j + 2, k + 5, MysticModBlocks.mysticfireGlass.blockID);
		world.setBlock(i + 11, j + 2, k + 6, MysticModBlocks.mysticfireGlass.blockID);
		world.setBlock(i + 11, j + 2, k + 7, MysticModBlocks.mysticfireGlass.blockID);
		world.setBlock(i + 11, j + 2, k + 8, MysticModBlocks.mysticfireGlass.blockID);
		world.setBlock(i + 11, j + 2, k + 9, MysticModBlocks.mysticfireGlass.blockID);
		world.setBlock(i + 11, j + 2, k + 10, MysticModBlocks.mysticfireGlass.blockID);
		world.setBlock(i + 11, j + 2, k + 11, MysticModBlocks.mysticfireGlass.blockID);
		world.setBlock(i + 11, j + 2, k + 12, MysticModBlocks.mysticBricks.blockID);
		world.setBlock(i + 11, j + 2, k + 13, MysticModBlocks.mysticBricks.blockID);
		world.setBlock(i + 11, j + 2, k + 14, MysticModBlocks.mysticBricks.blockID);
		world.setBlock(i + 11, j + 3, k + 2, MysticModBlocks.mysticBricks.blockID);
		world.setBlock(i + 11, j + 3, k + 14, MysticModBlocks.mysticBricks.blockID);
		world.setBlock(i + 11, j + 4, k + 2, MysticModBlocks.mysticBricks.blockID);
		world.setBlock(i + 11, j + 4, k + 14, MysticModBlocks.mysticBricks.blockID);
		world.setBlock(i + 11, j + 5, k + 2, MysticModBlocks.mysticBricks.blockID);
		world.setBlock(i + 11, j + 5, k + 14, MysticModBlocks.mysticBricks.blockID);
		world.setBlock(i + 11, j + 6, k + 2, MysticModBlocks.mysticBricks.blockID);
		world.setBlock(i + 11, j + 6, k + 14, MysticModBlocks.mysticBricks.blockID);
		world.setBlock(i + 11, j + 7, k + 2, MysticModBlocks.mysticBricks.blockID);
		world.setBlock(i + 11, j + 7, k + 14, MysticModBlocks.mysticBricks.blockID);
		world.setBlock(i + 11, j + 8, k + 2, MysticModBlocks.mysticBricks.blockID);
		world.setBlock(i + 11, j + 8, k + 14, MysticModBlocks.mysticBricks.blockID);
		world.setBlock(i + 11, j + 9, k + 2, MysticModBlocks.mysticBricks.blockID);
		world.setBlock(i + 11, j + 9, k + 3, MysticModBlocks.mysticBricks.blockID);
		world.setBlock(i + 11, j + 9, k + 4, MysticModBlocks.mysticGlass.blockID);
		world.setBlock(i + 11, j + 9, k + 5, MysticModBlocks.mysticGlass.blockID);
		world.setBlock(i + 11, j + 9, k + 6, MysticModBlocks.mysticGlass.blockID);
		world.setBlock(i + 11, j + 9, k + 7, MysticModBlocks.mysticGlass.blockID);
		world.setBlock(i + 11, j + 9, k + 8, MysticModBlocks.mysticGlass.blockID);
		world.setBlock(i + 11, j + 9, k + 9, MysticModBlocks.mysticGlass.blockID);
		world.setBlock(i + 11, j + 9, k + 10, MysticModBlocks.mysticGlass.blockID);
		world.setBlock(i + 11, j + 9, k + 11, MysticModBlocks.mysticGlass.blockID);
		world.setBlock(i + 11, j + 9, k + 12, MysticModBlocks.mysticGlass.blockID);
		world.setBlock(i + 11, j + 9, k + 13, MysticModBlocks.mysticBricks.blockID);
		world.setBlock(i + 11, j + 9, k + 14, MysticModBlocks.mysticBricks.blockID);
		world.setBlock(i + 11, j + 10, k + 3, Block.stoneSingleSlab.blockID, 2,2);
		world.setBlock(i + 11, j + 10, k + 13, Block.stoneSingleSlab.blockID, 2,2);
		
		world.setBlock(i + 12, j + 2, k + 2, MysticModBlocks.mysticBricks.blockID);
		world.setBlock(i + 12, j + 2, k + 3, MysticModBlocks.mysticBricks.blockID);
		world.setBlock(i + 12, j + 2, k + 4, MysticModBlocks.mysticBricks.blockID);
		world.setBlock(i + 12, j + 2, k + 5, MysticModBlocks.mysticfireGlass.blockID);
		world.setBlock(i + 12, j + 2, k + 6, MysticModBlocks.mysticfireGlass.blockID);
		world.setBlock(i + 12, j + 2, k + 7, MysticModBlocks.mysticfireGlass.blockID);
		world.setBlock(i + 12, j + 2, k + 8, MysticModBlocks.mysticfireGlass.blockID);
		world.setBlock(i + 12, j + 2, k + 9, MysticModBlocks.mysticfireGlass.blockID);
		world.setBlock(i + 12, j + 2, k + 10, MysticModBlocks.mysticfireGlass.blockID);
		world.setBlock(i + 12, j + 2, k + 11, MysticModBlocks.mysticfireGlass.blockID);
		world.setBlock(i + 12, j + 2, k + 12, MysticModBlocks.mysticBricks.blockID);
		world.setBlock(i + 12, j + 2, k + 13, MysticModBlocks.mysticBricks.blockID);
		world.setBlock(i + 12, j + 2, k + 14, MysticModBlocks.mysticBricks.blockID);
		world.setBlock(i + 12, j + 3, k + 2, MysticModBlocks.mysticBricks.blockID);
		world.setBlock(i + 12, j + 3, k + 14, MysticModBlocks.mysticBricks.blockID);
		world.setBlock(i + 12, j + 4, k + 2, MysticModBlocks.mysticBricks.blockID);
		world.setBlock(i + 12, j + 4, k + 14, MysticModBlocks.mysticBricks.blockID);
		world.setBlock(i + 12, j + 5, k + 2, MysticModBlocks.mysticBricks.blockID);
		world.setBlock(i + 12, j + 5, k + 14, MysticModBlocks.mysticBricks.blockID);
		world.setBlock(i + 12, j + 6, k + 2, MysticModBlocks.mysticBricks.blockID);
		world.setBlock(i + 12, j + 6, k + 14, MysticModBlocks.mysticBricks.blockID);
		world.setBlock(i + 12, j + 7, k + 2, MysticModBlocks.mysticBricks.blockID);
		world.setBlock(i + 12, j + 7, k + 14, MysticModBlocks.mysticBricks.blockID);
		world.setBlock(i + 12, j + 8, k + 2, MysticModBlocks.mysticBricks.blockID);
		world.setBlock(i + 12, j + 8, k + 14, MysticModBlocks.mysticBricks.blockID);
		world.setBlock(i + 12, j + 9, k + 2, MysticModBlocks.mysticBricks.blockID);
		world.setBlock(i + 12, j + 9, k + 3, MysticModBlocks.mysticBricks.blockID);
		world.setBlock(i + 12, j + 9, k + 4, MysticModBlocks.mysticGlass.blockID);
		world.setBlock(i + 12, j + 9, k + 5, MysticModBlocks.mysticGlass.blockID);
		world.setBlock(i + 12, j + 9, k + 6, MysticModBlocks.mysticGlass.blockID);
		world.setBlock(i + 12, j + 9, k + 7, MysticModBlocks.mysticGlass.blockID);
		world.setBlock(i + 12, j + 9, k + 8, MysticModBlocks.mysticGlass.blockID);
		world.setBlock(i + 12, j + 9, k + 9, MysticModBlocks.mysticGlass.blockID);
		world.setBlock(i + 12, j + 9, k + 10, MysticModBlocks.mysticGlass.blockID);
		world.setBlock(i + 12, j + 9, k + 11, MysticModBlocks.mysticGlass.blockID);
		world.setBlock(i + 12, j + 9, k + 12, MysticModBlocks.mysticGlass.blockID);
		world.setBlock(i + 12, j + 9, k + 13, MysticModBlocks.mysticBricks.blockID);
		world.setBlock(i + 12, j + 9, k + 14, MysticModBlocks.mysticBricks.blockID);
		world.setBlock(i + 12, j + 10, k + 3, Block.stoneSingleSlab.blockID, 2,2);
		world.setBlock(i + 12, j + 10, k + 13, Block.stoneSingleSlab.blockID, 2,2);
		
		world.setBlock(i + 13, j + 2, k + 2, MysticModBlocks.mysticBricks.blockID);
		world.setBlock(i + 13, j + 2, k + 3, MysticModBlocks.mysticBricks.blockID);
		world.setBlock(i + 13, j + 2, k + 4, MysticModBlocks.mysticBricks.blockID);
		world.setBlock(i + 13, j + 2, k + 5, MysticModBlocks.mysticfireGlass.blockID);
		world.setBlock(i + 13, j + 2, k + 6, MysticModBlocks.mysticfireGlass.blockID);
		world.setBlock(i + 13, j + 2, k + 7, MysticModBlocks.mysticfireGlass.blockID);
		world.setBlock(i + 13, j + 2, k + 8, MysticModBlocks.mysticBricks.blockID);
		world.setBlock(i + 13, j + 2, k + 9, MysticModBlocks.mysticfireGlass.blockID);
		world.setBlock(i + 13, j + 2, k + 10, MysticModBlocks.mysticfireGlass.blockID);
		world.setBlock(i + 13, j + 2, k + 11, MysticModBlocks.mysticfireGlass.blockID);
		world.setBlock(i + 13, j + 2, k + 12, MysticModBlocks.mysticBricks.blockID);
		world.setBlock(i + 13, j + 2, k + 13, MysticModBlocks.mysticBricks.blockID);
		world.setBlock(i + 13, j + 2, k + 14, MysticModBlocks.mysticBricks.blockID);
		world.setBlock(i + 13, j + 3, k + 2, MysticModBlocks.mysticBricks.blockID);
		world.setBlock(i + 13, j + 3, k + 8, Block.chest.blockID);
		TileEntityChest tile = (TileEntityChest) world.getBlockTileEntity(i+13, j+3, k+8);
		tile.setInventorySlotContents(0, new ItemStack(MysticModItems.fireToken, 1));
		world.setBlock(i + 13, j + 3, k + 14, MysticModBlocks.mysticBricks.blockID);
		world.setBlock(i + 13, j + 4, k + 2, MysticModBlocks.mysticBricks.blockID);
		world.setBlock(i + 13, j + 4, k + 8, Block.mobSpawner.blockID);
		TileEntityMobSpawner tile2 = (TileEntityMobSpawner) world.getBlockTileEntity(i+13, j+4, k+8);
		tile2.getSpawnerLogic().setMobID("MysticAdditions.FireMiniBoss");
		world.setBlock(i + 13, j + 4, k + 14, MysticModBlocks.mysticBricks.blockID);
		world.setBlock(i + 13, j + 5, k + 2, MysticModBlocks.mysticBricks.blockID);
		world.setBlock(i + 13, j + 5, k + 14, MysticModBlocks.mysticBricks.blockID);
		world.setBlock(i + 13, j + 6, k + 2, MysticModBlocks.mysticBricks.blockID);
		world.setBlock(i + 13, j + 6, k + 14, MysticModBlocks.mysticBricks.blockID);
		world.setBlock(i + 13, j + 7, k + 2, MysticModBlocks.mysticBricks.blockID);
		world.setBlock(i + 13, j + 7, k + 14, MysticModBlocks.mysticBricks.blockID);
		world.setBlock(i + 13, j + 8, k + 2, MysticModBlocks.mysticBricks.blockID);
		world.setBlock(i + 13, j + 8, k + 14, MysticModBlocks.mysticBricks.blockID);
		world.setBlock(i + 13, j + 9, k + 2, MysticModBlocks.mysticBricks.blockID);
		world.setBlock(i + 13, j + 9, k + 3, MysticModBlocks.mysticBricks.blockID);
		world.setBlock(i + 13, j + 9, k + 4, MysticModBlocks.mysticGlass.blockID);
		world.setBlock(i + 13, j + 9, k + 5, MysticModBlocks.mysticGlass.blockID);
		world.setBlock(i + 13, j + 9, k + 6, MysticModBlocks.mysticGlass.blockID);
		world.setBlock(i + 13, j + 9, k + 7, MysticModBlocks.mysticGlass.blockID);
		world.setBlock(i + 13, j + 9, k + 8, MysticModBlocks.mysticGlass.blockID);
		world.setBlock(i + 13, j + 9, k + 9, MysticModBlocks.mysticGlass.blockID);
		world.setBlock(i + 13, j + 9, k + 10, MysticModBlocks.mysticGlass.blockID);
		world.setBlock(i + 13, j + 9, k + 11, MysticModBlocks.mysticGlass.blockID);
		world.setBlock(i + 13, j + 9, k + 12, MysticModBlocks.mysticGlass.blockID);
		world.setBlock(i + 13, j + 9, k + 13, MysticModBlocks.mysticBricks.blockID);
		world.setBlock(i + 13, j + 9, k + 14, MysticModBlocks.mysticBricks.blockID);
		world.setBlock(i + 13, j + 10, k + 3, Block.stoneSingleSlab.blockID, 2,2);
		world.setBlock(i + 13, j + 10, k + 13, Block.stoneSingleSlab.blockID, 2,2);

		world.setBlock(i + 14, j + 1, k + 3, Block.stoneSingleSlab.blockID, 2,2);
		world.setBlock(i + 14, j + 1, k + 13, Block.stoneSingleSlab.blockID, 2,2);
		world.setBlock(i + 14, j + 1, k + 14, MysticModBlocks.mysticBricks.blockID);
		world.setBlock(i + 14, j + 2, k + 2, MysticModBlocks.mysticBricks.blockID);
		world.setBlock(i + 14, j + 2, k + 3, MysticModBlocks.mysticBricks.blockID);
		world.setBlock(i + 14, j + 2, k + 4, MysticModBlocks.mysticBricks.blockID);
		world.setBlock(i + 14, j + 2, k + 5, MysticModBlocks.mysticfireGlass.blockID);
		world.setBlock(i + 14, j + 2, k + 6, MysticModBlocks.mysticfireGlass.blockID);
		world.setBlock(i + 14, j + 2, k + 7, MysticModBlocks.mysticfireGlass.blockID);
		world.setBlock(i + 14, j + 2, k + 8, MysticModBlocks.mysticfireGlass.blockID);
		world.setBlock(i + 14, j + 2, k + 9, MysticModBlocks.mysticfireGlass.blockID);
		world.setBlock(i + 14, j + 2, k + 10, MysticModBlocks.mysticfireGlass.blockID);
		world.setBlock(i + 14, j + 2, k + 11, MysticModBlocks.mysticfireGlass.blockID);
		world.setBlock(i + 14, j + 2, k + 12, MysticModBlocks.mysticBricks.blockID);
		world.setBlock(i + 14, j + 2, k + 13, MysticModBlocks.mysticBricks.blockID);
		world.setBlock(i + 14, j + 2, k + 14, MysticModBlocks.mysticBricks.blockID);
		world.setBlock(i + 14, j + 3, k + 2, MysticModBlocks.mysticBricks.blockID);
		world.setBlock(i + 14, j + 3, k + 14, MysticModBlocks.mysticBricks.blockID);
		world.setBlock(i + 14, j + 4, k + 2, MysticModBlocks.mysticBricks.blockID);
		world.setBlock(i + 14, j + 4, k + 14, MysticModBlocks.mysticBricks.blockID);
		world.setBlock(i + 14, j + 5, k + 2, MysticModBlocks.mysticBricks.blockID);
		world.setBlock(i + 14, j + 5, k + 14, MysticModBlocks.mysticBricks.blockID);
		world.setBlock(i + 14, j + 6, k + 2, MysticModBlocks.mysticBricks.blockID);
		world.setBlock(i + 14, j + 6, k + 14, MysticModBlocks.mysticBricks.blockID);
		world.setBlock(i + 14, j + 7, k + 2, MysticModBlocks.mysticBricks.blockID);
		world.setBlock(i + 14, j + 7, k + 14, MysticModBlocks.mysticBricks.blockID);
		world.setBlock(i + 14, j + 8, k + 2, MysticModBlocks.mysticBricks.blockID);
		world.setBlock(i + 14, j + 8, k + 14, MysticModBlocks.mysticBricks.blockID);
		world.setBlock(i + 14, j + 9, k + 2, MysticModBlocks.mysticBricks.blockID);
		world.setBlock(i + 14, j + 9, k + 3, MysticModBlocks.mysticBricks.blockID);
		world.setBlock(i + 14, j + 9, k + 4, MysticModBlocks.mysticGlass.blockID);
		world.setBlock(i + 14, j + 9, k + 5, MysticModBlocks.mysticGlass.blockID);
		world.setBlock(i + 14, j + 9, k + 6, MysticModBlocks.mysticGlass.blockID);
		world.setBlock(i + 14, j + 9, k + 7, MysticModBlocks.mysticGlass.blockID);
		world.setBlock(i + 14, j + 9, k + 8, MysticModBlocks.mysticGlass.blockID);
		world.setBlock(i + 14, j + 9, k + 9, MysticModBlocks.mysticGlass.blockID);
		world.setBlock(i + 14, j + 9, k + 10, MysticModBlocks.mysticGlass.blockID);
		world.setBlock(i + 14, j + 9, k + 11, MysticModBlocks.mysticGlass.blockID);
		world.setBlock(i + 14, j + 9, k + 12, MysticModBlocks.mysticGlass.blockID);
		world.setBlock(i + 14, j + 9, k + 13, MysticModBlocks.mysticBricks.blockID);
		world.setBlock(i + 14, j + 9, k + 14, MysticModBlocks.mysticBricks.blockID);
		world.setBlock(i + 14, j + 10, k + 3, Block.stoneSingleSlab.blockID, 2,2);
		world.setBlock(i + 14, j + 10, k + 13, Block.stoneSingleSlab.blockID, 2,2);

		world.setBlock(i + 15, j + 1, k + 2, Block.stoneSingleSlab.blockID, 2,2);
		world.setBlock(i + 15, j + 1, k + 4, Block.stoneSingleSlab.blockID, 2,2);
		world.setBlock(i + 15, j + 1, k + 12, Block.stoneSingleSlab.blockID, 2,2);
		world.setBlock(i + 15, j + 1, k + 14, Block.stoneSingleSlab.blockID, 2,2);
		world.setBlock(i + 15, j + 2, k + 2, MysticModBlocks.mysticBricks.blockID);
		world.setBlock(i + 15, j + 2, k + 4, MysticModBlocks.mysticBricks.blockID);
		world.setBlock(i + 15, j + 2, k + 5, MysticModBlocks.mysticfireGlass.blockID);
		world.setBlock(i + 15, j + 2, k + 6, MysticModBlocks.mysticfireGlass.blockID);
		world.setBlock(i + 15, j + 2, k + 7, MysticModBlocks.mysticfireGlass.blockID);
		world.setBlock(i + 15, j + 2, k + 8, MysticModBlocks.mysticfireGlass.blockID);
		world.setBlock(i + 15, j + 2, k + 9, MysticModBlocks.mysticfireGlass.blockID);
		world.setBlock(i + 15, j + 2, k + 10, MysticModBlocks.mysticfireGlass.blockID);
		world.setBlock(i + 15, j + 2, k + 11, MysticModBlocks.mysticfireGlass.blockID);
		world.setBlock(i + 15, j + 2, k + 12, MysticModBlocks.mysticBricks.blockID);
		world.setBlock(i + 15, j + 2, k + 14, MysticModBlocks.mysticBricks.blockID);
		world.setBlock(i + 15, j + 3, k + 2, MysticModBlocks.mysticBricks.blockID);
		world.setBlock(i + 15, j + 3, k + 14, MysticModBlocks.mysticBricks.blockID);
		world.setBlock(i + 15, j + 4, k + 2, MysticModBlocks.mysticBricks.blockID);
		world.setBlock(i + 15, j + 4, k + 14, MysticModBlocks.mysticBricks.blockID);
		world.setBlock(i + 15, j + 5, k + 2, MysticModBlocks.mysticBricks.blockID);
		world.setBlock(i + 15, j + 5, k + 14, MysticModBlocks.mysticBricks.blockID);
		world.setBlock(i + 15, j + 6, k + 2, MysticModBlocks.mysticBricks.blockID);
		world.setBlock(i + 15, j + 6, k + 14, MysticModBlocks.mysticBricks.blockID);
		world.setBlock(i + 15, j + 7, k + 2, MysticModBlocks.mysticBricks.blockID);
		world.setBlock(i + 15, j + 7, k + 14, MysticModBlocks.mysticBricks.blockID);
		world.setBlock(i + 15, j + 8, k + 2, MysticModBlocks.mysticBricks.blockID);
		world.setBlock(i + 15, j + 8, k + 14, MysticModBlocks.mysticBricks.blockID);
		world.setBlock(i + 15, j + 9, k + 2, MysticModBlocks.mysticBricks.blockID);
		world.setBlock(i + 15, j + 9, k + 4, MysticModBlocks.mysticBricks.blockID);
		world.setBlock(i + 15, j + 9, k + 5, MysticModBlocks.mysticGlass.blockID);
		world.setBlock(i + 15, j + 9, k + 6, MysticModBlocks.mysticGlass.blockID);
		world.setBlock(i + 15, j + 9, k + 7, MysticModBlocks.mysticGlass.blockID);
		world.setBlock(i + 15, j + 9, k + 8, MysticModBlocks.mysticGlass.blockID);
		world.setBlock(i + 15, j + 9, k + 9, MysticModBlocks.mysticGlass.blockID);
		world.setBlock(i + 15, j + 9, k + 10, MysticModBlocks.mysticGlass.blockID);
		world.setBlock(i + 15, j + 9, k + 11, MysticModBlocks.mysticGlass.blockID);
		world.setBlock(i + 15, j + 9, k + 12, MysticModBlocks.mysticBricks.blockID);
		world.setBlock(i + 15, j + 9, k + 14, MysticModBlocks.mysticBricks.blockID);
		world.setBlock(i + 15, j + 10, k + 3, Block.stoneSingleSlab.blockID, 2,2);
		world.setBlock(i + 15, j + 10, k + 4, Block.stoneSingleSlab.blockID, 2,2);
		world.setBlock(i + 15, j + 10, k + 12, Block.stoneSingleSlab.blockID, 2,2);
		world.setBlock(i + 15, j + 10, k + 13, Block.stoneSingleSlab.blockID, 2,2);

		world.setBlock(i + 16, j + 1, k + 3, Block.stoneSingleSlab.blockID, 2,2);
		world.setBlock(i + 16, j + 1, k + 13, Block.stoneSingleSlab.blockID, 2,2);
		world.setBlock(i + 16, j + 2, k + 2, MysticModBlocks.mysticBricks.blockID);
		world.setBlock(i + 16, j + 2, k + 3, MysticModBlocks.mysticBricks.blockID);
		world.setBlock(i + 16, j + 2, k + 4, MysticModBlocks.mysticBricks.blockID);
		world.setBlock(i + 16, j + 2, k + 5, MysticModBlocks.mysticfireGlass.blockID);
		world.setBlock(i + 16, j + 2, k + 6, MysticModBlocks.mysticfireGlass.blockID);
		world.setBlock(i + 16, j + 2, k + 7, MysticModBlocks.mysticfireGlass.blockID);
		world.setBlock(i + 16, j + 2, k + 8, MysticModBlocks.mysticfireGlass.blockID);
		world.setBlock(i + 16, j + 2, k + 9, MysticModBlocks.mysticfireGlass.blockID);
		world.setBlock(i + 16, j + 2, k + 10, MysticModBlocks.mysticfireGlass.blockID);
		world.setBlock(i + 16, j + 2, k + 11, MysticModBlocks.mysticfireGlass.blockID);
		world.setBlock(i + 16, j + 2, k + 12, MysticModBlocks.mysticBricks.blockID);
		world.setBlock(i + 16, j + 2, k + 13, MysticModBlocks.mysticBricks.blockID);
		world.setBlock(i + 16, j + 2, k + 14, MysticModBlocks.mysticBricks.blockID);
		world.setBlock(i + 16, j + 3, k + 2, MysticModBlocks.mysticBricks.blockID);
		world.setBlock(i + 16, j + 3, k + 3, MysticModBlocks.mysticBricks.blockID);
		world.setBlock(i + 16, j + 3, k + 13, MysticModBlocks.mysticBricks.blockID);
		world.setBlock(i + 16, j + 3, k + 14, MysticModBlocks.mysticBricks.blockID);
		world.setBlock(i + 16, j + 4, k + 2, MysticModBlocks.mysticBricks.blockID);
		world.setBlock(i + 16, j + 4, k + 3, MysticModBlocks.mysticBricks.blockID);
		world.setBlock(i + 16, j + 4, k + 13, MysticModBlocks.mysticBricks.blockID);
		world.setBlock(i + 16, j + 4, k + 14, MysticModBlocks.mysticBricks.blockID);
		world.setBlock(i + 16, j + 5, k + 2, MysticModBlocks.mysticBricks.blockID);
		world.setBlock(i + 16, j + 5, k + 3, MysticModBlocks.mysticBricks.blockID);
		world.setBlock(i + 16, j + 5, k + 13, MysticModBlocks.mysticBricks.blockID);
		world.setBlock(i + 16, j + 5, k + 14, MysticModBlocks.mysticBricks.blockID);
		world.setBlock(i + 16, j + 6, k + 2, MysticModBlocks.mysticBricks.blockID);
		world.setBlock(i + 16, j + 6, k + 3, MysticModBlocks.mysticBricks.blockID);
		world.setBlock(i + 16, j + 6, k + 13, MysticModBlocks.mysticBricks.blockID);
		world.setBlock(i + 16, j + 6, k + 14, MysticModBlocks.mysticBricks.blockID);
		world.setBlock(i + 16, j + 7, k + 2, MysticModBlocks.mysticBricks.blockID);
		world.setBlock(i + 16, j + 7, k + 3, MysticModBlocks.mysticBricks.blockID);
		world.setBlock(i + 16, j + 7, k + 13, MysticModBlocks.mysticBricks.blockID);
		world.setBlock(i + 16, j + 7, k + 14, MysticModBlocks.mysticBricks.blockID);
		world.setBlock(i + 16, j + 8, k + 2, MysticModBlocks.mysticBricks.blockID);
		world.setBlock(i + 16, j + 8, k + 3, MysticModBlocks.mysticBricks.blockID);
		world.setBlock(i + 16, j + 8, k + 13, MysticModBlocks.mysticBricks.blockID);
		world.setBlock(i + 16, j + 8, k + 14, MysticModBlocks.mysticBricks.blockID);
		world.setBlock(i + 16, j + 9, k + 2, Block.stoneSingleSlab.blockID, 2,2);
		world.setBlock(i + 16, j + 9, k + 3, MysticModBlocks.mysticBricks.blockID);
		world.setBlock(i + 16, j + 9, k + 4, MysticModBlocks.mysticBricks.blockID);
		world.setBlock(i + 16, j + 9, k + 5, MysticModBlocks.mysticBricks.blockID);
		world.setBlock(i + 16, j + 9, k + 6, MysticModBlocks.mysticGlass.blockID);
		world.setBlock(i + 16, j + 9, k + 7, MysticModBlocks.mysticGlass.blockID);
		world.setBlock(i + 16, j + 9, k + 8, MysticModBlocks.mysticGlass.blockID);
		world.setBlock(i + 16, j + 9, k + 9, MysticModBlocks.mysticGlass.blockID);
		world.setBlock(i + 16, j + 9, k + 10, MysticModBlocks.mysticGlass.blockID);
		world.setBlock(i + 16, j + 9, k + 11, MysticModBlocks.mysticBricks.blockID);
		world.setBlock(i + 16, j + 9, k + 12, MysticModBlocks.mysticBricks.blockID);
		world.setBlock(i + 16, j + 9, k + 13, MysticModBlocks.mysticBricks.blockID);
		world.setBlock(i + 16, j + 9, k + 14, Block.stoneSingleSlab.blockID, 2,2);
		world.setBlock(i + 16, j + 10, k + 4, Block.stoneSingleSlab.blockID, 2,2);
		world.setBlock(i + 16, j + 10, k + 5, Block.stoneSingleSlab.blockID, 2,2);
		world.setBlock(i + 16, j + 10, k + 11, Block.stoneSingleSlab.blockID, 2,2);
		world.setBlock(i + 16, j + 10, k + 12, Block.stoneSingleSlab.blockID, 2,2);

		world.setBlock(i + 17, j + 2, k + 4, MysticModBlocks.mysticBricks.blockID);
		world.setBlock(i + 17, j + 2, k + 5, MysticModBlocks.mysticBricks.blockID);
		world.setBlock(i + 17, j + 2, k + 6, MysticModBlocks.mysticBricks.blockID);
		world.setBlock(i + 17, j + 2, k + 7, MysticModBlocks.mysticBricks.blockID);
		world.setBlock(i + 17, j + 2, k + 8, MysticModBlocks.mysticBricks.blockID);
		world.setBlock(i + 17, j + 2, k + 9, MysticModBlocks.mysticBricks.blockID);
		world.setBlock(i + 17, j + 2, k + 10, MysticModBlocks.mysticBricks.blockID);
		world.setBlock(i + 17, j + 2, k + 11, MysticModBlocks.mysticBricks.blockID);
		world.setBlock(i + 17, j + 2, k + 12, MysticModBlocks.mysticBricks.blockID);
		world.setBlock(i + 17, j + 3, k + 4, MysticModBlocks.mysticBricks.blockID);
		world.setBlock(i + 17, j + 3, k + 12, MysticModBlocks.mysticBricks.blockID);
		world.setBlock(i + 17, j + 4, k + 4, MysticModBlocks.mysticBricks.blockID);
		world.setBlock(i + 17, j + 4, k + 12, MysticModBlocks.mysticBricks.blockID);
		world.setBlock(i + 17, j + 5, k + 4, MysticModBlocks.mysticBricks.blockID);
		world.setBlock(i + 17, j + 5, k + 12, MysticModBlocks.mysticBricks.blockID);
		world.setBlock(i + 17, j + 6, k + 4, MysticModBlocks.mysticBricks.blockID);
		world.setBlock(i + 17, j + 6, k + 12, MysticModBlocks.mysticBricks.blockID);
		world.setBlock(i + 17, j + 7, k + 4, MysticModBlocks.mysticBricks.blockID);
		world.setBlock(i + 17, j + 7, k + 12, MysticModBlocks.mysticBricks.blockID);
		world.setBlock(i + 17, j + 8, k + 4, MysticModBlocks.mysticBricks.blockID);
		world.setBlock(i + 17, j + 8, k + 12, MysticModBlocks.mysticBricks.blockID);
		world.setBlock(i + 17, j + 9, k + 4, MysticModBlocks.mysticBricks.blockID);
		world.setBlock(i + 17, j + 9, k + 5, MysticModBlocks.mysticBricks.blockID);
		world.setBlock(i + 17, j + 9, k + 6, MysticModBlocks.mysticBricks.blockID);
		world.setBlock(i + 17, j + 9, k + 7, MysticModBlocks.mysticGlass.blockID);
		world.setBlock(i + 17, j + 9, k + 8, MysticModBlocks.mysticGlass.blockID);
		world.setBlock(i + 17, j + 9, k + 9, MysticModBlocks.mysticGlass.blockID);
		world.setBlock(i + 17, j + 9, k + 10, MysticModBlocks.mysticBricks.blockID);
		world.setBlock(i + 17, j + 9, k + 11, MysticModBlocks.mysticBricks.blockID);
		world.setBlock(i + 17, j + 9, k + 12, MysticModBlocks.mysticBricks.blockID);
		world.setBlock(i + 17, j + 10, k + 5, Block.stoneSingleSlab.blockID, 2,2);
		world.setBlock(i + 17, j + 10, k + 6, Block.stoneSingleSlab.blockID, 2,2);
		world.setBlock(i + 17, j + 10, k + 10, Block.stoneSingleSlab.blockID, 2,2);
		world.setBlock(i + 17, j + 10, k + 11, Block.stoneSingleSlab.blockID, 2,2);

		world.setBlock(i + 18, j + 2, k + 5, MysticModBlocks.mysticBricks.blockID);
		world.setBlock(i + 18, j + 2, k + 6, MysticModBlocks.mysticBricks.blockID);
		world.setBlock(i + 18, j + 2, k + 7, MysticModBlocks.mysticBricks.blockID);
		world.setBlock(i + 18, j + 2, k + 8, MysticModBlocks.mysticBricks.blockID);
		world.setBlock(i + 18, j + 2, k + 9, MysticModBlocks.mysticBricks.blockID);
		world.setBlock(i + 18, j + 2, k + 10, MysticModBlocks.mysticBricks.blockID);
		world.setBlock(i + 18, j + 2, k + 11, MysticModBlocks.mysticBricks.blockID);
		world.setBlock(i + 18, j + 3, k + 5, MysticModBlocks.mysticBricks.blockID);
		world.setBlock(i + 18, j + 3, k + 11, MysticModBlocks.mysticBricks.blockID);
		world.setBlock(i + 18, j + 4, k + 5, MysticModBlocks.mysticBricks.blockID);
		world.setBlock(i + 18, j + 4, k + 11, MysticModBlocks.mysticBricks.blockID);
		world.setBlock(i + 18, j + 5, k + 5, MysticModBlocks.mysticBricks.blockID);
		world.setBlock(i + 18, j + 5, k + 11, MysticModBlocks.mysticBricks.blockID);
		world.setBlock(i + 18, j + 6, k + 5, MysticModBlocks.mysticBricks.blockID);
		world.setBlock(i + 18, j + 6, k + 11, MysticModBlocks.mysticBricks.blockID);
		world.setBlock(i + 18, j + 7, k + 5, MysticModBlocks.mysticBricks.blockID);
		world.setBlock(i + 18, j + 7, k + 11, MysticModBlocks.mysticBricks.blockID);
		world.setBlock(i + 18, j + 8, k + 5, MysticModBlocks.mysticBricks.blockID);
		world.setBlock(i + 18, j + 8, k + 11, MysticModBlocks.mysticBricks.blockID);
		world.setBlock(i + 18, j + 9, k + 5, MysticModBlocks.mysticBricks.blockID);
		world.setBlock(i + 18, j + 9, k + 6, MysticModBlocks.mysticBricks.blockID);
		world.setBlock(i + 18, j + 9, k + 7, MysticModBlocks.mysticGlass.blockID);
		world.setBlock(i + 18, j + 9, k + 8, MysticModBlocks.mysticGlass.blockID);
		world.setBlock(i + 18, j + 9, k + 9, MysticModBlocks.mysticGlass.blockID);
		world.setBlock(i + 18, j + 9, k + 10, MysticModBlocks.mysticBricks.blockID);
		world.setBlock(i + 18, j + 9, k + 11, MysticModBlocks.mysticBricks.blockID);
		world.setBlock(i + 18, j + 10, k + 6, Block.stoneSingleSlab.blockID, 2,2);
		world.setBlock(i + 18, j + 10, k + 10, Block.stoneSingleSlab.blockID, 2,2);

		world.setBlock(i + 19, j + 2, k + 5, MysticModBlocks.mysticBricks.blockID);
		world.setBlock(i + 19, j + 2, k + 6, MysticModBlocks.mysticBricks.blockID);
		world.setBlock(i + 19, j + 2, k + 7, MysticModBlocks.mysticBricks.blockID);
		world.setBlock(i + 19, j + 2, k + 8, MysticModBlocks.mysticBricks.blockID);
		world.setBlock(i + 19, j + 2, k + 9, MysticModBlocks.mysticBricks.blockID);
		world.setBlock(i + 19, j + 2, k + 10, MysticModBlocks.mysticBricks.blockID);
		world.setBlock(i + 19, j + 2, k + 11, MysticModBlocks.mysticBricks.blockID);
		world.setBlock(i + 19, j + 3, k + 5, MysticModBlocks.mysticBricks.blockID);
		world.setBlock(i + 19, j + 3, k + 11, MysticModBlocks.mysticBricks.blockID);
		world.setBlock(i + 19, j + 4, k + 5, MysticModBlocks.mysticBricks.blockID);
		world.setBlock(i + 19, j + 4, k + 11, MysticModBlocks.mysticBricks.blockID);
		world.setBlock(i + 19, j + 5, k + 5, MysticModBlocks.mysticBricks.blockID);
		world.setBlock(i + 19, j + 5, k + 11, MysticModBlocks.mysticBricks.blockID);
		world.setBlock(i + 19, j + 6, k + 5, MysticModBlocks.mysticBricks.blockID);
		world.setBlock(i + 19, j + 6, k + 11, MysticModBlocks.mysticBricks.blockID);
		world.setBlock(i + 19, j + 7, k + 5, MysticModBlocks.mysticBricks.blockID);
		world.setBlock(i + 19, j + 7, k + 11, MysticModBlocks.mysticBricks.blockID);
		world.setBlock(i + 19, j + 8, k + 5, MysticModBlocks.mysticBricks.blockID);
		world.setBlock(i + 19, j + 8, k + 11, MysticModBlocks.mysticBricks.blockID);
		world.setBlock(i + 19, j + 9, k + 5, MysticModBlocks.mysticBricks.blockID);
		world.setBlock(i + 19, j + 9, k + 6, MysticModBlocks.mysticBricks.blockID);
		world.setBlock(i + 19, j + 9, k + 7, MysticModBlocks.mysticBricks.blockID);
		world.setBlock(i + 19, j + 9, k + 8, MysticModBlocks.mysticGlass.blockID);
		world.setBlock(i + 19, j + 9, k + 9, MysticModBlocks.mysticBricks.blockID);
		world.setBlock(i + 19, j + 9, k + 10, MysticModBlocks.mysticBricks.blockID);
		world.setBlock(i + 19, j + 9, k + 11, MysticModBlocks.mysticBricks.blockID);
		world.setBlock(i + 19, j + 10, k + 6, Block.stoneSingleSlab.blockID, 2,2);
		world.setBlock(i + 19, j + 10, k + 7, Block.stoneSingleSlab.blockID, 2,2);
		world.setBlock(i + 19, j + 10, k + 9, Block.stoneSingleSlab.blockID, 2,2);
		world.setBlock(i + 19, j + 10, k + 10, Block.stoneSingleSlab.blockID, 2,2);

		world.setBlock(i + 20, j + 1, k + 8, Block.stoneSingleSlab.blockID, 2,2);
		world.setBlock(i + 20, j + 2, k + 6, MysticModBlocks.mysticBricks.blockID);
		world.setBlock(i + 20, j + 2, k + 7, MysticModBlocks.mysticBricks.blockID);
		world.setBlock(i + 20, j + 2, k + 8, MysticModBlocks.mysticBricks.blockID);
		world.setBlock(i + 20, j + 2, k + 9, MysticModBlocks.mysticBricks.blockID);
		world.setBlock(i + 20, j + 2, k + 10, MysticModBlocks.mysticBricks.blockID);
		world.setBlock(i + 20, j + 3, k + 6, MysticModBlocks.mysticBricks.blockID);
		world.setBlock(i + 20, j + 3, k + 10, MysticModBlocks.mysticBricks.blockID);
		world.setBlock(i + 20, j + 4, k + 6, MysticModBlocks.mysticBricks.blockID);
		world.setBlock(i + 20, j + 4, k + 10, MysticModBlocks.mysticBricks.blockID);
		world.setBlock(i + 20, j + 5, k + 6, MysticModBlocks.mysticBricks.blockID);
		world.setBlock(i + 20, j + 5, k + 10, MysticModBlocks.mysticBricks.blockID);
		world.setBlock(i + 20, j + 6, k + 6, MysticModBlocks.mysticBricks.blockID);
		world.setBlock(i + 20, j + 6, k + 10, MysticModBlocks.mysticBricks.blockID);
		world.setBlock(i + 20, j + 7, k + 6, MysticModBlocks.mysticBricks.blockID);
		world.setBlock(i + 20, j + 7, k + 10, MysticModBlocks.mysticBricks.blockID);
		world.setBlock(i + 20, j + 8, k + 6, MysticModBlocks.mysticBricks.blockID);
		world.setBlock(i + 20, j + 8, k + 10, MysticModBlocks.mysticBricks.blockID);
		world.setBlock(i + 20, j + 9, k + 6, MysticModBlocks.mysticBricks.blockID);
		world.setBlock(i + 20, j + 9, k + 7, MysticModBlocks.mysticBricks.blockID);
		world.setBlock(i + 20, j + 9, k + 8, MysticModBlocks.mysticBricks.blockID);
		world.setBlock(i + 20, j + 9, k + 9, MysticModBlocks.mysticBricks.blockID);
		world.setBlock(i + 20, j + 9, k + 10, MysticModBlocks.mysticBricks.blockID);
		world.setBlock(i + 20, j + 10, k + 7, Block.stoneSingleSlab.blockID, 2,2);
		world.setBlock(i + 20, j + 10, k + 8, Block.stoneSingleSlab.blockID, 2,2);
		world.setBlock(i + 20, j + 10, k + 9, Block.stoneSingleSlab.blockID, 2,2);

		world.setBlock(i + 21, j + 1, k + 7, Block.stoneSingleSlab.blockID, 2,2);
		world.setBlock(i + 21, j + 1, k + 9, Block.stoneSingleSlab.blockID, 2,2);
		world.setBlock(i + 21, j + 2, k + 7, MysticModBlocks.mysticBricks.blockID);
		world.setBlock(i + 21, j + 2, k + 9, MysticModBlocks.mysticBricks.blockID);
		world.setBlock(i + 21, j + 3, k + 7, MysticModBlocks.mysticBricks.blockID);
		world.setBlock(i + 21, j + 3, k + 9, MysticModBlocks.mysticBricks.blockID);
		world.setBlock(i + 21, j + 4, k + 7, MysticModBlocks.mysticBricks.blockID);
		world.setBlock(i + 21, j + 4, k + 9, MysticModBlocks.mysticBricks.blockID);
		world.setBlock(i + 21, j + 5, k + 7, MysticModBlocks.mysticBricks.blockID);
		world.setBlock(i + 21, j + 5, k + 9, MysticModBlocks.mysticBricks.blockID);
		world.setBlock(i + 21, j + 6, k + 7, MysticModBlocks.mysticBricks.blockID);
		world.setBlock(i + 21, j + 6, k + 9, MysticModBlocks.mysticBricks.blockID);
		world.setBlock(i + 21, j + 7, k + 7, MysticModBlocks.mysticBricks.blockID);
		world.setBlock(i + 21, j + 7, k + 9, MysticModBlocks.mysticBricks.blockID);
		world.setBlock(i + 21, j + 8, k + 7, MysticModBlocks.mysticBricks.blockID);
		world.setBlock(i + 21, j + 8, k + 9, MysticModBlocks.mysticBricks.blockID);
		world.setBlock(i + 21, j + 9, k + 7, MysticModBlocks.mysticBricks.blockID);
		world.setBlock(i + 21, j + 9, k + 9, MysticModBlocks.mysticBricks.blockID);
		world.setBlock(i + 21, j + 10, k + 8, Block.stoneSingleSlab.blockID, 2,2);

		world.setBlock(i + 22, j + 1, k + 8, Block.stoneSingleSlab.blockID, 2,2);
		world.setBlock(i + 22, j + 2, k + 8, MysticModBlocks.mysticBricks.blockID);
		world.setBlock(i + 22, j + 3, k + 8, MysticModBlocks.mysticBricks.blockID);
		world.setBlock(i + 22, j + 4, k + 8, MysticModBlocks.mysticBricks.blockID);
		world.setBlock(i + 22, j + 5, k + 8, MysticModBlocks.mysticBricks.blockID);
		world.setBlock(i + 22, j + 6, k + 8, MysticModBlocks.mysticBricks.blockID);
		world.setBlock(i + 22, j + 7, k + 8, MysticModBlocks.mysticBricks.blockID);
		world.setBlock(i + 22, j + 8, k + 8, MysticModBlocks.mysticBricks.blockID);
		world.setBlock(i + 22, j + 9, k + 8, MysticModBlocks.mysticBricks.blockID);
		world.setBlock(i + 23, j + 0, k + 0, Block.grass.blockID);

		world.setBlock(i + 0, j + 0, k + 2, Block.lavaStill.blockID);
		world.setBlock(i + 0, j + 0, k + 3, Block.lavaStill.blockID);
		world.setBlock(i + 0, j + 0, k + 4, Block.lavaStill.blockID);
		world.setBlock(i + 0, j + 0, k + 5, Block.lavaStill.blockID);
		world.setBlock(i + 0, j + 0, k + 6, Block.lavaStill.blockID);
		world.setBlock(i + 0, j + 0, k + 7, Block.lavaStill.blockID);
		world.setBlock(i + 0, j + 0, k + 8, Block.lavaStill.blockID);
		world.setBlock(i + 0, j + 0, k + 9, Block.lavaStill.blockID);
		world.setBlock(i + 0, j + 0, k + 10, Block.lavaStill.blockID);
		world.setBlock(i + 0, j + 0, k + 11, Block.lavaStill.blockID);
		world.setBlock(i + 0, j + 0, k + 12, Block.lavaStill.blockID);
		world.setBlock(i + 0, j + 0, k + 13, Block.lavaStill.blockID);
		world.setBlock(i + 0, j + 0, k + 14, Block.lavaStill.blockID);
		world.setBlock(i + 1, j + 0, k + 2, Block.lavaStill.blockID);
		world.setBlock(i + 1, j + 0, k + 3, Block.lavaStill.blockID);
		world.setBlock(i + 1, j + 0, k + 4, Block.lavaStill.blockID);
		world.setBlock(i + 1, j + 0, k + 5, Block.lavaStill.blockID);
		world.setBlock(i + 1, j + 0, k + 6, Block.lavaStill.blockID);
		world.setBlock(i + 1, j + 0, k + 7, Block.lavaStill.blockID);
		world.setBlock(i + 1, j + 0, k + 8, Block.lavaStill.blockID);
		world.setBlock(i + 1, j + 0, k + 9, Block.lavaStill.blockID);
		world.setBlock(i + 1, j + 0, k + 10, Block.lavaStill.blockID);
		world.setBlock(i + 1, j + 0, k + 11, Block.lavaStill.blockID);
		world.setBlock(i + 1, j + 0, k + 12, Block.lavaStill.blockID);
		world.setBlock(i + 1, j + 0, k + 13, Block.lavaStill.blockID);
		world.setBlock(i + 1, j + 0, k + 14, Block.lavaStill.blockID);
		world.setBlock(i + 2, j + 0, k + 2, Block.lavaStill.blockID);
		world.setBlock(i + 2, j + 0, k + 3, Block.lavaStill.blockID);
		world.setBlock(i + 2, j + 0, k + 13, Block.lavaStill.blockID);
		world.setBlock(i + 2, j + 0, k + 14, Block.lavaStill.blockID);
		world.setBlock(i + 3, j + 0, k + 2, Block.lavaStill.blockID);
		world.setBlock(i + 3, j + 0, k + 3, Block.lavaStill.blockID);
		world.setBlock(i + 3, j + 0, k + 13, Block.lavaStill.blockID);
		world.setBlock(i + 3, j + 0, k + 14, Block.lavaStill.blockID);
		world.setBlock(i + 4, j + 0, k + 2, Block.lavaStill.blockID);
		world.setBlock(i + 4, j + 0, k + 3, Block.lavaStill.blockID);
		world.setBlock(i + 4, j + 0, k + 13, Block.lavaStill.blockID);
		world.setBlock(i + 4, j + 0, k + 14, Block.lavaStill.blockID);
		world.setBlock(i + 5, j + 0, k + 0, Block.lavaStill.blockID);
		world.setBlock(i + 5, j + 0, k + 1, Block.lavaStill.blockID);
		world.setBlock(i + 5, j + 0, k + 2, Block.lavaStill.blockID);
		world.setBlock(i + 5, j + 0, k + 3, Block.lavaStill.blockID);
		world.setBlock(i + 5, j + 0, k + 13, Block.lavaStill.blockID);
		world.setBlock(i + 5, j + 0, k + 14, Block.lavaStill.blockID);
		world.setBlock(i + 5, j + 0, k + 15, Block.lavaStill.blockID);
		world.setBlock(i + 5, j + 0, k + 16, Block.lavaStill.blockID);
		world.setBlock(i + 6, j + 0, k + 0, Block.lavaStill.blockID);
		world.setBlock(i + 6, j + 0, k + 1, Block.lavaStill.blockID);
		world.setBlock(i + 6, j + 0, k + 2, Block.lavaStill.blockID);
		world.setBlock(i + 6, j + 0, k + 3, Block.lavaStill.blockID);
		world.setBlock(i + 6, j + 0, k + 13, Block.lavaStill.blockID);
		world.setBlock(i + 6, j + 0, k + 14, Block.lavaStill.blockID);
		world.setBlock(i + 6, j + 0, k + 15, Block.lavaStill.blockID);
		world.setBlock(i + 6, j + 0, k + 16, Block.lavaStill.blockID);
		world.setBlock(i + 7, j + 0, k + 0, Block.lavaStill.blockID);
		world.setBlock(i + 7, j + 0, k + 1, Block.lavaStill.blockID);
		world.setBlock(i + 7, j + 0, k + 15, Block.lavaStill.blockID);
		world.setBlock(i + 7, j + 0, k + 16, Block.lavaStill.blockID);
		world.setBlock(i + 8, j + 0, k + 0, Block.lavaStill.blockID);
		world.setBlock(i + 8, j + 0, k + 1, Block.lavaStill.blockID);
		world.setBlock(i + 8, j + 0, k + 15, Block.lavaStill.blockID);
		world.setBlock(i + 8, j + 0, k + 16, Block.lavaStill.blockID);
		world.setBlock(i + 8, j + 1, k + 3, Block.lavaStill.blockID, 8,2);
		world.setBlock(i + 8, j + 1, k + 13, Block.lavaStill.blockID, 8,2);
		world.setBlock(i + 8, j + 2, k + 3, Block.lavaStill.blockID, 8,2);
		world.setBlock(i + 8, j + 2, k + 13, Block.lavaStill.blockID, 8,2);
		world.setBlock(i + 8, j + 3, k + 3, Block.lavaStill.blockID, 8,2);
		world.setBlock(i + 8, j + 3, k + 13, Block.lavaStill.blockID, 8,2);
		world.setBlock(i + 8, j + 4, k + 3, Block.lavaStill.blockID, 8,2);
		world.setBlock(i + 8, j + 4, k + 13, Block.lavaStill.blockID, 8,2);
		world.setBlock(i + 8, j + 5, k + 3, Block.lavaStill.blockID, 8,2);
		world.setBlock(i + 8, j + 5, k + 13, Block.lavaStill.blockID, 8,2);
		world.setBlock(i + 8, j + 6, k + 3, Block.lavaStill.blockID, 8,2);
		world.setBlock(i + 8, j + 6, k + 13, Block.lavaStill.blockID, 8,2);
		world.setBlock(i + 8, j + 7, k + 3, Block.lavaStill.blockID, 8,2);
		world.setBlock(i + 8, j + 7, k + 13, Block.lavaStill.blockID, 8,2);
		world.setBlock(i + 8, j + 8, k + 3, Block.lavaStill.blockID, 8,2);
		world.setBlock(i + 8, j + 8, k + 13, Block.lavaStill.blockID, 8,2);
		world.setBlock(i + 8, j + 9, k + 3, Block.lavaStill.blockID);
		world.setBlock(i + 8, j + 9, k + 13, Block.lavaStill.blockID);
		world.setBlock(i + 9, j + 0, k + 0, Block.lavaStill.blockID);
		world.setBlock(i + 9, j + 0, k + 1, Block.lavaStill.blockID);
		world.setBlock(i + 9, j + 0, k + 15, Block.lavaStill.blockID);
		world.setBlock(i + 9, j + 0, k + 16, Block.lavaStill.blockID);
		world.setBlock(i + 9, j + 10, k + 4, Block.lavaStill.blockID);
		world.setBlock(i + 9, j + 10, k + 5, Block.lavaStill.blockID);
		world.setBlock(i + 9, j + 10, k + 6, Block.lavaStill.blockID);
		world.setBlock(i + 9, j + 10, k + 7, Block.lavaStill.blockID);
		world.setBlock(i + 9, j + 10, k + 8, Block.lavaStill.blockID);
		world.setBlock(i + 9, j + 10, k + 9, Block.lavaStill.blockID);
		world.setBlock(i + 9, j + 10, k + 10, Block.lavaStill.blockID);
		world.setBlock(i + 9, j + 10, k + 11, Block.lavaStill.blockID);
		world.setBlock(i + 9, j + 10, k + 12, Block.lavaStill.blockID);
		world.setBlock(i + 10, j + 0, k + 0, Block.lavaStill.blockID);
		world.setBlock(i + 10, j + 0, k + 1, Block.lavaStill.blockID);
		world.setBlock(i + 10, j + 0, k + 15, Block.lavaStill.blockID);
		world.setBlock(i + 10, j + 0, k + 16, Block.lavaStill.blockID);
		world.setBlock(i + 10, j + 10, k + 4, Block.lavaStill.blockID);
		world.setBlock(i + 10, j + 10, k + 5, Block.lavaStill.blockID);
		world.setBlock(i + 10, j + 10, k + 6, Block.lavaStill.blockID);
		world.setBlock(i + 10, j + 10, k + 7, Block.lavaStill.blockID);
		world.setBlock(i + 10, j + 10, k + 8, Block.lavaStill.blockID);
		world.setBlock(i + 10, j + 10, k + 9, Block.lavaStill.blockID);
		world.setBlock(i + 10, j + 10, k + 10, Block.lavaStill.blockID);
		world.setBlock(i + 10, j + 10, k + 11, Block.lavaStill.blockID);
		world.setBlock(i + 10, j + 10, k + 12, Block.lavaStill.blockID);
		world.setBlock(i + 11, j + 0, k + 0, Block.lavaStill.blockID);
		world.setBlock(i + 11, j + 0, k + 1, Block.lavaStill.blockID);
		world.setBlock(i + 11, j + 0, k + 15, Block.lavaStill.blockID);
		world.setBlock(i + 11, j + 0, k + 16, Block.lavaStill.blockID);
		world.setBlock(i + 11, j + 10, k + 4, Block.lavaStill.blockID);
		world.setBlock(i + 11, j + 10, k + 5, Block.lavaStill.blockID);
		world.setBlock(i + 11, j + 10, k + 6, Block.lavaStill.blockID);
		world.setBlock(i + 11, j + 10, k + 7, Block.lavaStill.blockID);
		world.setBlock(i + 11, j + 10, k + 8, Block.lavaStill.blockID);
		world.setBlock(i + 11, j + 10, k + 9, Block.lavaStill.blockID);
		world.setBlock(i + 11, j + 10, k + 10, Block.lavaStill.blockID);
		world.setBlock(i + 11, j + 10, k + 11, Block.lavaStill.blockID);
		world.setBlock(i + 11, j + 10, k + 12, Block.lavaStill.blockID);
		world.setBlock(i + 12, j + 0, k + 0, Block.lavaStill.blockID);
		world.setBlock(i + 12, j + 0, k + 1, Block.lavaStill.blockID);
		world.setBlock(i + 12, j + 0, k + 15, Block.lavaStill.blockID);
		world.setBlock(i + 12, j + 0, k + 16, Block.lavaStill.blockID);
		world.setBlock(i + 12, j + 10, k + 4, Block.lavaStill.blockID);
		world.setBlock(i + 12, j + 10, k + 5, Block.lavaStill.blockID);
		world.setBlock(i + 12, j + 10, k + 6, Block.lavaStill.blockID);
		world.setBlock(i + 12, j + 10, k + 7, Block.lavaStill.blockID);
		world.setBlock(i + 12, j + 10, k + 8, Block.lavaStill.blockID);
		world.setBlock(i + 12, j + 10, k + 9, Block.lavaStill.blockID);
		world.setBlock(i + 12, j + 10, k + 10, Block.lavaStill.blockID);
		world.setBlock(i + 12, j + 10, k + 11, Block.lavaStill.blockID);
		world.setBlock(i + 12, j + 10, k + 12, Block.lavaStill.blockID);
		world.setBlock(i + 13, j + 0, k + 0, Block.lavaStill.blockID);
		world.setBlock(i + 13, j + 0, k + 1, Block.lavaStill.blockID);
		world.setBlock(i + 13, j + 0, k + 15, Block.lavaStill.blockID);
		world.setBlock(i + 13, j + 0, k + 16, Block.lavaStill.blockID);
		world.setBlock(i + 13, j + 10, k + 4, Block.lavaStill.blockID);
		world.setBlock(i + 13, j + 10, k + 5, Block.lavaStill.blockID);
		world.setBlock(i + 13, j + 10, k + 6, Block.lavaStill.blockID);
		world.setBlock(i + 13, j + 10, k + 7, Block.lavaStill.blockID);
		world.setBlock(i + 13, j + 10, k + 8, Block.lavaStill.blockID);
		world.setBlock(i + 13, j + 10, k + 9, Block.lavaStill.blockID);
		world.setBlock(i + 13, j + 10, k + 10, Block.lavaStill.blockID);
		world.setBlock(i + 13, j + 10, k + 11, Block.lavaStill.blockID);
		world.setBlock(i + 13, j + 10, k + 12, Block.lavaStill.blockID);
		world.setBlock(i + 14, j + 0, k + 0, Block.lavaStill.blockID);
		world.setBlock(i + 14, j + 0, k + 1, Block.lavaStill.blockID);
		world.setBlock(i + 14, j + 0, k + 15, Block.lavaStill.blockID);
		world.setBlock(i + 14, j + 0, k + 16, Block.lavaStill.blockID);
		world.setBlock(i + 14, j + 10, k + 4, Block.lavaStill.blockID);
		world.setBlock(i + 14, j + 10, k + 5, Block.lavaStill.blockID);
		world.setBlock(i + 14, j + 10, k + 6, Block.lavaStill.blockID);
		world.setBlock(i + 14, j + 10, k + 7, Block.lavaStill.blockID);
		world.setBlock(i + 14, j + 10, k + 8, Block.lavaStill.blockID);
		world.setBlock(i + 14, j + 10, k + 9, Block.lavaStill.blockID);
		world.setBlock(i + 14, j + 10, k + 10, Block.lavaStill.blockID);
		world.setBlock(i + 14, j + 10, k + 11, Block.lavaStill.blockID);
		world.setBlock(i + 14, j + 10, k + 12, Block.lavaStill.blockID);
		world.setBlock(i + 15, j + 0, k + 0, Block.lavaStill.blockID);
		world.setBlock(i + 15, j + 0, k + 1, Block.lavaStill.blockID);
		world.setBlock(i + 15, j + 0, k + 15, Block.lavaStill.blockID);
		world.setBlock(i + 15, j + 0, k + 16, Block.lavaStill.blockID);
		world.setBlock(i + 15, j + 1, k + 3, Block.lavaStill.blockID, 8,2);
		world.setBlock(i + 15, j + 1, k + 13, Block.lavaStill.blockID, 8,2);
		world.setBlock(i + 15, j + 2, k + 3, Block.lavaStill.blockID, 8,2);
		world.setBlock(i + 15, j + 2, k + 13, Block.lavaStill.blockID, 8,2);
		world.setBlock(i + 15, j + 3, k + 3, Block.lavaStill.blockID, 8,2);
		world.setBlock(i + 15, j + 3, k + 13, Block.lavaStill.blockID, 8,2);
		world.setBlock(i + 15, j + 4, k + 3, Block.lavaStill.blockID, 8,2);
		world.setBlock(i + 15, j + 4, k + 13, Block.lavaStill.blockID, 8,2);
		world.setBlock(i + 15, j + 5, k + 3, Block.lavaStill.blockID, 8,2);
		world.setBlock(i + 15, j + 5, k + 13, Block.lavaStill.blockID, 8,2);
		world.setBlock(i + 15, j + 6, k + 3, Block.lavaStill.blockID, 8,2);
		world.setBlock(i + 15, j + 6, k + 13, Block.lavaStill.blockID, 8,2);
		world.setBlock(i + 15, j + 7, k + 3, Block.lavaStill.blockID, 8,2);
		world.setBlock(i + 15, j + 7, k + 13, Block.lavaStill.blockID, 8,2);
		world.setBlock(i + 15, j + 8, k + 3, Block.lavaStill.blockID, 8,2);
		world.setBlock(i + 15, j + 8, k + 13, Block.lavaStill.blockID, 8,2);
		world.setBlock(i + 15, j + 9, k + 3, Block.lavaStill.blockID);
		world.setBlock(i + 15, j + 9, k + 13, Block.lavaStill.blockID);
		world.setBlock(i + 15, j + 10, k + 5, Block.lavaStill.blockID);
		world.setBlock(i + 15, j + 10, k + 6, Block.lavaStill.blockID);
		world.setBlock(i + 15, j + 10, k + 7, Block.lavaStill.blockID);
		world.setBlock(i + 15, j + 10, k + 8, Block.lavaStill.blockID);
		world.setBlock(i + 15, j + 10, k + 9, Block.lavaStill.blockID);
		world.setBlock(i + 15, j + 10, k + 10, Block.lavaStill.blockID);
		world.setBlock(i + 15, j + 10, k + 11, Block.lavaStill.blockID);
		world.setBlock(i + 16, j + 0, k + 0, Block.lavaStill.blockID);
		world.setBlock(i + 16, j + 0, k + 1, Block.lavaStill.blockID);
		world.setBlock(i + 16, j + 0, k + 15, Block.lavaStill.blockID);
		world.setBlock(i + 16, j + 0, k + 16, Block.lavaStill.blockID);
		world.setBlock(i + 16, j + 10, k + 6, Block.lavaStill.blockID);
		world.setBlock(i + 16, j + 10, k + 7, Block.lavaStill.blockID);
		world.setBlock(i + 16, j + 10, k + 8, Block.lavaStill.blockID);
		world.setBlock(i + 16, j + 10, k + 9, Block.lavaStill.blockID);
		world.setBlock(i + 16, j + 10, k + 10, Block.lavaStill.blockID);
		world.setBlock(i + 17, j + 0, k + 0, Block.lavaStill.blockID);
		world.setBlock(i + 17, j + 0, k + 1, Block.lavaStill.blockID);
		world.setBlock(i + 17, j + 0, k + 2, Block.lavaStill.blockID);
		world.setBlock(i + 17, j + 0, k + 3, Block.lavaStill.blockID);
		world.setBlock(i + 17, j + 0, k + 14, Block.lavaStill.blockID);
		world.setBlock(i + 17, j + 0, k + 15, Block.lavaStill.blockID);
		world.setBlock(i + 17, j + 0, k + 16, Block.lavaStill.blockID);
		world.setBlock(i + 17, j + 10, k + 7, Block.lavaStill.blockID);
		world.setBlock(i + 17, j + 10, k + 8, Block.lavaStill.blockID);
		world.setBlock(i + 17, j + 10, k + 9, Block.lavaStill.blockID);
		world.setBlock(i + 18, j + 0, k + 0, Block.lavaStill.blockID);
		world.setBlock(i + 18, j + 0, k + 1, Block.lavaStill.blockID);
		world.setBlock(i + 18, j + 0, k + 2, Block.lavaStill.blockID);
		world.setBlock(i + 18, j + 0, k + 3, Block.lavaStill.blockID);
		world.setBlock(i + 18, j + 0, k + 4, Block.lavaStill.blockID);
		world.setBlock(i + 18, j + 0, k + 12, Block.lavaStill.blockID);
		world.setBlock(i + 18, j + 0, k + 13, Block.lavaStill.blockID);
		world.setBlock(i + 18, j + 0, k + 14, Block.lavaStill.blockID);
		world.setBlock(i + 18, j + 0, k + 15, Block.lavaStill.blockID);
		world.setBlock(i + 18, j + 0, k + 16, Block.lavaStill.blockID);
		world.setBlock(i + 18, j + 10, k + 7, Block.lavaStill.blockID);
		world.setBlock(i + 18, j + 10, k + 8, Block.lavaStill.blockID);
		world.setBlock(i + 18, j + 10, k + 9, Block.lavaStill.blockID);
		world.setBlock(i + 19, j + 0, k + 2, Block.lavaStill.blockID);
		world.setBlock(i + 19, j + 0, k + 3, Block.lavaStill.blockID);
		world.setBlock(i + 19, j + 0, k + 4, Block.lavaStill.blockID);
		world.setBlock(i + 19, j + 0, k + 12, Block.lavaStill.blockID);
		world.setBlock(i + 19, j + 0, k + 13, Block.lavaStill.blockID);
		world.setBlock(i + 19, j + 0, k + 14, Block.lavaStill.blockID);
		world.setBlock(i + 19, j + 0, k + 15, Block.lavaStill.blockID);
		world.setBlock(i + 19, j + 10, k + 8, Block.lavaStill.blockID);
		world.setBlock(i + 20, j + 0, k + 3, Block.lavaStill.blockID);
		world.setBlock(i + 20, j + 0, k + 4, Block.lavaStill.blockID);
		world.setBlock(i + 20, j + 0, k + 5, Block.lavaStill.blockID);
		world.setBlock(i + 20, j + 0, k + 11, Block.lavaStill.blockID);
		world.setBlock(i + 20, j + 0, k + 12, Block.lavaStill.blockID);
		world.setBlock(i + 20, j + 0, k + 13, Block.lavaStill.blockID);
		world.setBlock(i + 20, j + 0, k + 14, Block.lavaStill.blockID);
		world.setBlock(i + 21, j + 0, k + 3, Block.lavaStill.blockID);
		world.setBlock(i + 21, j + 0, k + 4, Block.lavaStill.blockID);
		world.setBlock(i + 21, j + 0, k + 5, Block.lavaStill.blockID);
		world.setBlock(i + 21, j + 0, k + 10, Block.lavaStill.blockID);
		world.setBlock(i + 21, j + 0, k + 11, Block.lavaStill.blockID);
		world.setBlock(i + 21, j + 0, k + 12, Block.lavaStill.blockID);
		world.setBlock(i + 21, j + 0, k + 13, Block.lavaStill.blockID);
		world.setBlock(i + 21, j + 1, k + 8, Block.lavaStill.blockID, 8,2);
		world.setBlock(i + 21, j + 2, k + 8, Block.lavaStill.blockID, 8,2);
		world.setBlock(i + 21, j + 3, k + 8, Block.lavaStill.blockID, 8,2);
		world.setBlock(i + 21, j + 4, k + 8, Block.lavaStill.blockID, 8,2);
		world.setBlock(i + 21, j + 5, k + 8, Block.lavaStill.blockID, 8,2);
		world.setBlock(i + 21, j + 6, k + 8, Block.lavaStill.blockID, 8,2);
		world.setBlock(i + 21, j + 7, k + 8, Block.lavaStill.blockID, 8,2);
		world.setBlock(i + 21, j + 8, k + 8, Block.lavaStill.blockID, 8,2);
		world.setBlock(i + 21, j + 9, k + 8, Block.lavaStill.blockID);
		world.setBlock(i + 22, j + 0, k + 4, Block.lavaStill.blockID);
		world.setBlock(i + 22, j + 0, k + 5, Block.lavaStill.blockID);
		world.setBlock(i + 22, j + 0, k + 9, Block.lavaStill.blockID);
		world.setBlock(i + 22, j + 0, k + 10, Block.lavaStill.blockID);
		world.setBlock(i + 22, j + 0, k + 11, Block.lavaStill.blockID);
		world.setBlock(i + 22, j + 0, k + 12, Block.lavaStill.blockID);
		world.setBlock(i + 23, j + 0, k + 4, Block.lavaStill.blockID);
		world.setBlock(i + 23, j + 0, k + 5, Block.lavaStill.blockID);
		world.setBlock(i + 23, j + 0, k + 6, Block.lavaStill.blockID);
		world.setBlock(i + 23, j + 0, k + 7, Block.lavaStill.blockID);
		world.setBlock(i + 23, j + 0, k + 8, Block.lavaStill.blockID);
		world.setBlock(i + 23, j + 0, k + 9, Block.lavaStill.blockID);
		world.setBlock(i + 23, j + 0, k + 10, Block.lavaStill.blockID);
		world.setBlock(i + 23, j + 0, k + 11, Block.lavaStill.blockID);
		world.setBlock(i + 24, j + 0, k + 4, Block.lavaStill.blockID);
		world.setBlock(i + 24, j + 0, k + 5, Block.lavaStill.blockID);
		world.setBlock(i + 24, j + 0, k + 6, Block.lavaStill.blockID);
		world.setBlock(i + 24, j + 0, k + 7, Block.lavaStill.blockID);
		world.setBlock(i + 24, j + 0, k + 8, Block.lavaStill.blockID);
		world.setBlock(i + 24, j + 0, k + 9, Block.lavaStill.blockID);
		world.setBlock(i + 24, j + 0, k + 10, Block.lavaStill.blockID);

		return true;
	}
}